<sdf version='1.10'>
    <model name='sweepee_2'>
      <link name='sweepee_2/base_footprint'>
        <inertial>
          <pose>0 0 0.20519480519480521 0 0 0</pose>
          <mass>154</mass>
          <inertia>
            <ixx>2.161950486734955</ixx>
            <ixy>0</ixy>
            <ixz>0</ixz>
            <iyy>3.861950486734957</iyy>
            <iyz>0</iyz>
            <izz>6.0112500000000004</izz>
          </inertia>
        </inertial>
        <collision name='sweepee_2/base_footprint_fixed_joint_lump__sweepee_2/base_link_sweepee_collision'>
          <pose>0 0 0.20000000000000001 0 0 0</pose>
          <geometry>
            <box>
              <size>0.29999999999999999 0.55000000000000004 0.050000000000000003</size>
            </box>
          </geometry>
          <surface>
            <friction>
              <ode/>
            </friction>
            <bounce/>
            <contact/>
          </surface>
        </collision>
        <collision name='sweepee_2/base_footprint_fixed_joint_lump__sweepee_2/base_link_inertia_collision_1'>
          <pose>0 0 0.40000000000000002 0 0 -2.4492935982947059e-16</pose>
          <geometry>
            <mesh>
              <scale>1 1 1</scale>
              <uri>file:///home/gino/ROS/lampo_ws_ros2_rolling/install/ur_description/share/ur_description/meshes/ur10/collision/base.stl</uri>
            </mesh>
          </geometry>
        </collision>
        <visual name='sweepee_2/base_footprint_fixed_joint_lump__sweepee_2/base_link_sweepee_visual'>
          <pose>0 0 0.032000000000000001 0 0 -1.5707949999999999</pose>
          <geometry>
            <mesh>
              <scale>1 1 1</scale>
              <uri>file:///home/gino/ROS/lampo_ws_ros2_rolling/install/lampo_description/share/lampo_description//meshes/sweepee/visual/sweepee.dae</uri>
            </mesh>
          </geometry>
          <material>
            <diffuse>0.625 0.625 0.625 1</diffuse>
            <ambient>0.625 0.625 0.625 1</ambient>
          </material>
        </visual>
        <visual name='sweepee_2/base_footprint_fixed_joint_lump__sweepee_2/base_link_inertia_visual_1'>
          <pose>0 0 0.40000000000000002 0 0 -2.4492935982947059e-16</pose>
          <geometry>
            <mesh>
              <scale>1 1 1</scale>
              <uri>file:///home/gino/ROS/lampo_ws_ros2_rolling/install/ur_description/share/ur_description/meshes/ur10/visual/base.dae</uri>
            </mesh>
          </geometry>
        </visual>
        <sensor name='gpu_lidar' type='gpu_lidar'>
          <pose>0.35999999999999999 0 0.26000000000000001 0 0 0</pose>
          <topic>sweepee_2/lidar</topic>
          <update_rate>10</update_rate>
          <enable_metrics>false</enable_metrics>
          <gz_frame_id>sweepee_2/front_laser</gz_frame_id>
          <lidar>
            <scan>
              <horizontal>
                <samples>640</samples>
                <resolution>1</resolution>
                <min_angle>-1.396263</min_angle>
                <max_angle>1.396263</max_angle>
              </horizontal>
              <vertical>
                <samples>1</samples>
                <min_angle>0</min_angle>
                <max_angle>0</max_angle>
                <resolution>0.01</resolution>
              </vertical>
            </scan>
            <range>
              <min>0.080000000000000002</min>
              <max>10</max>
              <resolution>0.01</resolution>
            </range>
            <noise>
              <type>gaussian</type>
              <mean>0.0</mean>
              <stddev>0.007</stddev>
            </noise>
            <visibility_mask>4294967295</visibility_mask>
          </lidar>
        </sensor>
        <pose>0 0 0 0 0 0</pose>
        <enable_wind>false</enable_wind>
      </link>
      <joint name='sweepee_2/front_left_wheel_joint' type='revolute'>
        <pose>-5.5511151231257827e-17 -2.7755575615628914e-17 0 0 0 0</pose>
        <parent>sweepee_2/base_footprint</parent>
        <child>sweepee_2/front_left_wheel</child>
        <axis>
          <xyz>0 0 1</xyz>
          <limit>
            <lower>-1.7976900000000001e+308</lower>
            <upper>1.7976900000000001e+308</upper>
            <effort>10000</effort>
            <velocity>5.0999999999999996</velocity>
            <stiffness>100000000</stiffness>
            <dissipation>1</dissipation>
          </limit>
          <dynamics>
            <spring_reference>0</spring_reference>
            <spring_stiffness>0</spring_stiffness>
            <damping>0</damping>
            <friction>0</friction>
          </dynamics>
        </axis>
      </joint>
      <link name='sweepee_2/front_left_wheel'>
        <pose>0.29999999999999982 0.24999999999999956 0.1000000000000001 1.5705441049543432 -1.1789310284554695 -3.1413595505962375</pose>
        <inertial>
          <pose>0 0 0 0 0 0</pose>
          <mass>1</mass>
          <inertia>
            <ixx>0.14499999999999999</ixx>
            <ixy>0</ixy>
            <ixz>0</ixz>
            <iyy>0.14499999999999999</iyy>
            <iyz>0</iyz>
            <izz>0.125</izz>
          </inertia>
        </inertial>
        <collision name='sweepee_2/front_left_wheel_collision'>
          <pose>0 0 0 0 0 0</pose>
          <geometry>
            <sphere>
              <radius>0.10000000000000001</radius>
            </sphere>
          </geometry>
          <surface>
            <contact>
              <ode/>
            </contact>
            <friction>
              <ode>
                <mu>1.0</mu>
                <mu2>0.0</mu2>
                <fdir1 gz:expressed_in="sweepee_2/base_footprint">1 -1 0</fdir1>
              </ode>
            </friction>
            <bounce/>
          </surface>
        </collision>
        <visual name='sweepee_2/front_left_wheel_visual'>
          <pose>0 0 0 0 0 0</pose>
          <geometry>
            <sphere>
              <radius>0.10000000000000001</radius>
            </sphere>
          </geometry>
        </visual>
        <enable_wind>false</enable_wind>
      </link>
      <joint name='sweepee_2/front_right_wheel_joint' type='revolute'>
        <pose>-5.5511151231257827e-17 1.3877787807814457e-17 0 0 0 0</pose>
        <parent>sweepee_2/base_footprint</parent>
        <child>sweepee_2/front_right_wheel</child>
        <axis>
          <xyz>0 0 1</xyz>
          <limit>
            <lower>-1.7976900000000001e+308</lower>
            <upper>1.7976900000000001e+308</upper>
            <effort>10000</effort>
            <velocity>5.0999999999999996</velocity>
            <stiffness>100000000</stiffness>
            <dissipation>1</dissipation>
          </limit>
          <dynamics>
            <spring_reference>0</spring_reference>
            <spring_stiffness>0</spring_stiffness>
            <damping>0</damping>
            <friction>0</friction>
          </dynamics>
        </axis>
      </joint>
      <link name='sweepee_2/front_right_wheel'>
        <pose>0.29999999999999938 -0.25 0.10000000000000005 1.5705506182709605 -1.1679516870566595 -3.1413666141519121</pose>
        <inertial>
          <pose>0 0 0 0 0 0</pose>
          <mass>1</mass>
          <inertia>
            <ixx>0.14499999999999999</ixx>
            <ixy>0</ixy>
            <ixz>0</ixz>
            <iyy>0.14499999999999999</iyy>
            <iyz>0</iyz>
            <izz>0.125</izz>
          </inertia>
        </inertial>
        <collision name='sweepee_2/front_right_wheel_collision'>
          <pose>0 0 0 0 0 0</pose>
          <geometry>
            <sphere>
              <radius>0.10000000000000001</radius>
            </sphere>
          </geometry>
          <surface>
            <contact>
              <ode/>
            </contact>
            <friction>
              <ode>
                <mu>1.0</mu>
                <mu2>0.0</mu2>
                <fdir1 gz:expressed_in="sweepee_2/base_footprint">1 1 0</fdir1>
              </ode>
            </friction>
            <bounce/>
          </surface>
        </collision>
        <visual name='sweepee_2/front_right_wheel_visual'>
          <pose>0 0 0 0 0 0</pose>
          <geometry>
            <sphere>
              <radius>0.10000000000000001</radius>
            </sphere>
          </geometry>
        </visual>
        <enable_wind>false</enable_wind>
      </link>
      <joint name='sweepee_2/rear_left_wheel_joint' type='revolute'>
        <pose>5.5511151231257827e-17 -2.7755575615628914e-17 0 0 0 0</pose>
        <parent>sweepee_2/base_footprint</parent>
        <child>sweepee_2/rear_left_wheel</child>
        <axis>
          <xyz>0 0 1</xyz>
          <limit>
            <lower>-1.7976900000000001e+308</lower>
            <upper>1.7976900000000001e+308</upper>
            <effort>10000</effort>
            <velocity>5.0999999999999996</velocity>
            <stiffness>100000000</stiffness>
            <dissipation>1</dissipation>
          </limit>
          <dynamics>
            <spring_reference>0</spring_reference>
            <spring_stiffness>0</spring_stiffness>
            <damping>0</damping>
            <friction>0</friction>
          </dynamics>
        </axis>
      </joint>
      <link name='sweepee_2/rear_left_wheel'>
        <pose>-0.30000000000000004 0.25 0.10000000000000007 1.5706827322253689 -0.55861936897712472 -3.1415324466564529</pose>
        <inertial>
          <pose>0 0 0 0 0 0</pose>
          <mass>1</mass>
          <inertia>
            <ixx>0.14499999999999999</ixx>
            <ixy>0</ixy>
            <ixz>0</ixz>
            <iyy>0.14499999999999999</iyy>
            <iyz>0</iyz>
            <izz>0.125</izz>
          </inertia>
        </inertial>
        <collision name='sweepee_2/rear_left_wheel_collision'>
          <pose>0 0 0 0 0 0</pose>
          <geometry>
            <sphere>
              <radius>0.10000000000000001</radius>
            </sphere>
          </geometry>
          <surface>
            <contact>
              <ode/>
            </contact>
            <friction>
              <ode>
                <mu>1.0</mu>
                <mu2>0.0</mu2>
                <fdir1 gz:expressed_in="sweepee_2/base_footprint">1 1 0</fdir1>
              </ode>
            </friction>
            <bounce/>
          </surface>
        </collision>
        <visual name='sweepee_2/rear_left_wheel_visual'>
          <pose>0 0 0 0 0 0</pose>
          <geometry>
            <sphere>
              <radius>0.10000000000000001</radius>
            </sphere>
          </geometry>
        </visual>
        <enable_wind>false</enable_wind>
      </link>
      <joint name='sweepee_2/rear_right_wheel_joint' type='revolute'>
        <pose>5.5511151231257827e-17 1.3877787807814457e-17 0 0 0 0</pose>
        <parent>sweepee_2/base_footprint</parent>
        <child>sweepee_2/rear_right_wheel</child>
        <axis>
          <xyz>0 0 1</xyz>
          <limit>
            <lower>-1.7976900000000001e+308</lower>
            <upper>1.7976900000000001e+308</upper>
            <effort>10000</effort>
            <velocity>5.0999999999999996</velocity>
            <stiffness>100000000</stiffness>
            <dissipation>1</dissipation>
          </limit>
          <dynamics>
            <spring_reference>0</spring_reference>
            <spring_stiffness>0</spring_stiffness>
            <damping>0</damping>
            <friction>0</friction>
          </dynamics>
        </axis>
      </joint>
      <link name='sweepee_2/rear_right_wheel'>
        <pose>-0.30000000000000027 -0.24999999999999978 0.099999999999999992 -1.5703498205177389 -1.3533523703942603 -0.0004359919778096245</pose>
        <inertial>
          <pose>0 0 0 0 0 0</pose>
          <mass>1</mass>
          <inertia>
            <ixx>0.14499999999999999</ixx>
            <ixy>0</ixy>
            <ixz>0</ixz>
            <iyy>0.14499999999999999</iyy>
            <iyz>0</iyz>
            <izz>0.125</izz>
          </inertia>
        </inertial>
        <collision name='sweepee_2/rear_right_wheel_collision'>
          <pose>0 0 0 0 0 0</pose>
          <geometry>
            <sphere>
              <radius>0.10000000000000001</radius>
            </sphere>
          </geometry>
          <surface>
            <contact>
              <ode/>
            </contact>
            <friction>
              <ode>
                <mu>1.0</mu>
                <mu2>0.0</mu2>
                <fdir1 gz:expressed_in="sweepee_2/base_footprint">1 -1 0</fdir1>
              </ode>
            </friction>
            <bounce/>
          </surface>
        </collision>
        <visual name='sweepee_2/rear_right_wheel_visual'>
          <pose>0 0 0 0 0 0</pose>
          <geometry>
            <sphere>
              <radius>0.10000000000000001</radius>
            </sphere>
          </geometry>
        </visual>
        <enable_wind>false</enable_wind>
      </link>
      <plugin name='gz::sim::systems::MecanumDrive' filename='gz-sim-mecanum-drive-system'>
        <front_left_joint>sweepee_2/front_left_wheel_joint</front_left_joint>
        <front_right_joint>sweepee_2/front_right_wheel_joint</front_right_joint>
        <back_left_joint>sweepee_2/rear_left_wheel_joint</back_left_joint>
        <back_right_joint>sweepee_2/rear_right_wheel_joint</back_right_joint>
        <wheel_separation>0.5</wheel_separation>
        <wheelbase>0.7</wheelbase>
        <wheel_radius>0.1</wheel_radius>
        <min_acceleration>-5</min_acceleration>
        <max_acceleration>5</max_acceleration>
        <topic>sweepee_2/cmd_vel</topic>
        <frame_id>sweepee_2/odom</frame_id>
        <odom_topic>sweepee_2/odom</odom_topic>
        <tf_topic>sweepee_2/tf</tf_topic>
        <child_frame_id>sweepee_2/base_footprint</child_frame_id>
      </plugin>
      <frame name='sweepee_2/front_laser_joint' attached_to='sweepee_2/base_link_sweepee'>
        <pose>0.35999999999999999 0 0.26000000000000001 0 0 0</pose>
      </frame>
      <frame name='sweepee_2/front_laser' attached_to='sweepee_2/front_laser_joint'>
        <pose>0 0 0 0 0 0</pose>
      </frame>
      <frame name='sweepee_2/rear_laser_joint' attached_to='sweepee_2/base_link_sweepee'>
        <pose>-0.35999999999999999 0 0.26000000000000001 0 0 3.1415899999999999</pose>
      </frame>
      <frame name='sweepee_2/rear_laser' attached_to='sweepee_2/rear_laser_joint'>
        <pose>0 0 0 0 0 0</pose>
      </frame>
      <frame name='sweepee_2/base_footprint_joint' attached_to='sweepee_2/base_footprint'>
        <pose>0 0 0 0 0 0</pose>
      </frame>
      <frame name='sweepee_2/base_link_sweepee' attached_to='sweepee_2/base_footprint_joint'>
        <pose>0 0 0 0 0 0</pose>
      </frame>
      <pose>-0.71226332349694155 1.98948459177051 -7.5037302232010457e-07 1.136839462468235e-07 4.9515905817926549e-07 2.6761841843343928</pose>
      <static>false</static>
      <self_collide>false</self_collide>
    </model>
</sdf>
