<sdf version='1.10'>
    <model name='sweepee_2'>
      <link name='sweepee_2/base_footprint'>
        <inertial>
          <pose>0 0 0.20519480519480521 0 0 0</pose>
          <mass>154</mass>
          <inertia>
            <ixx>2.161950486734955</ixx>
            <ixy>0</ixy>
            <ixz>0</ixz>
            <iyy>3.861950486734957</iyy>
            <iyz>0</iyz>
            <izz>6.0112500000000004</izz>
          </inertia>
        </inertial>
        <collision name='sweepee_2/base_footprint_fixed_joint_lump__sweepee_2/base_link_sweepee_collision'>
          <pose>0 0 0.20000000000000001 0 0 0</pose>
          <geometry>
            <box>
              <size>0.29999999999999999 0.55000000000000004 0.050000000000000003</size>
            </box>
          </geometry>
          <surface>
            <friction>
              <ode/>
            </friction>
            <bounce/>
            <contact/>
          </surface>
        </collision>
        <collision name='sweepee_2/base_footprint_fixed_joint_lump__sweepee_2/base_link_inertia_collision_1'>
          <pose>0 0 0.40000000000000002 0 0 -2.4492935982947059e-16</pose>
          <geometry>
            <mesh>
              <scale>1 1 1</scale>
              <uri>file:///home/stefanomutti/lampo_ws/install/ur_description/share/ur_description/meshes/ur10/collision/base.stl</uri>
            </mesh>
          </geometry>
        </collision>
        <visual name='sweepee_2/base_footprint_fixed_joint_lump__sweepee_2/base_link_sweepee_visual'>
          <pose>0 0 0.032000000000000001 0 0 -1.5707949999999999</pose>
          <geometry>
            <mesh>
              <scale>1 1 1</scale>
              <uri>file:///home/stefanomutti/lampo_ws/install/lampo_description/share/lampo_description//meshes/sweepee/visual/sweepee.dae</uri>
            </mesh>
          </geometry>
          <material>
            <diffuse>0.625 0.625 0.625 1</diffuse>
            <ambient>0.625 0.625 0.625 1</ambient>
          </material>
        </visual>
        <visual name='sweepee_2/base_footprint_fixed_joint_lump__sweepee_2/base_link_inertia_visual_1'>
          <pose>0 0 0.40000000000000002 0 0 -2.4492935982947059e-16</pose>
          <geometry>
            <mesh>
              <scale>1 1 1</scale>
              <uri>file:///home/stefanomutti/lampo_ws/install/ur_description/share/ur_description/meshes/ur10/visual/base.dae</uri>
            </mesh>
          </geometry>
        </visual>
        <sensor name='gpu_lidar' type='gpu_lidar'>
          <pose>0.35999999999999999 0 0.26000000000000001 0 0 0</pose>
          <topic>sweepee_2/lidar</topic>
          <update_rate>10</update_rate>
          <enable_metrics>false</enable_metrics>
          <lidar>
            <scan>
              <horizontal>
                <samples>640</samples>
                <resolution>1</resolution>
                <min_angle>-1.396263</min_angle>
                <max_angle>1.396263</max_angle>
              </horizontal>
              <vertical>
                <samples>1</samples>
                <min_angle>0</min_angle>
                <max_angle>0</max_angle>
                <resolution>0.01</resolution>
              </vertical>
            </scan>
            <range>
              <min>0.080000000000000002</min>
              <max>10</max>
              <resolution>0.01</resolution>
            </range>
            <noise>
              <type>none</type>
              <mean>0</mean>
              <stddev>0</stddev>
            </noise>
            <visibility_mask>4294967295</visibility_mask>
          </lidar>
        </sensor>
        <pose>0 0 0 0 0 0</pose>
        <enable_wind>false</enable_wind>
      </link>
      <joint name='sweepee_2/front_left_wheel_joint' type='revolute'>
        <pose>-5.5511151231257827e-17 -2.7755575615628914e-17 0 0 0 0</pose>
        <parent>sweepee_2/base_footprint</parent>
        <child>sweepee_2/front_left_wheel</child>
        <axis>
          <xyz>0 0 1</xyz>
          <limit>
            <lower>-1.7976900000000001e+308</lower>
            <upper>1.7976900000000001e+308</upper>
            <effort>10000</effort>
            <velocity>5.0999999999999996</velocity>
            <stiffness>100000000</stiffness>
            <dissipation>1</dissipation>
          </limit>
          <dynamics>
            <spring_reference>0</spring_reference>
            <spring_stiffness>0</spring_stiffness>
            <damping>0</damping>
            <friction>0</friction>
          </dynamics>
        </axis>
      </joint>
      <link name='sweepee_2/front_left_wheel'>
        <pose>0.29999999999999982 0.24999999999999956 0.1000000000000001 1.5705441049543432 -1.1789310284554695 -3.1413595505962375</pose>
        <inertial>
          <pose>0 0 0 0 0 0</pose>
          <mass>1</mass>
          <inertia>
            <ixx>0.14499999999999999</ixx>
            <ixy>0</ixy>
            <ixz>0</ixz>
            <iyy>0.14499999999999999</iyy>
            <iyz>0</iyz>
            <izz>0.125</izz>
          </inertia>
        </inertial>
        <collision name='sweepee_2/front_left_wheel_collision'>
          <pose>0 0 0 0 0 0</pose>
          <geometry>
            <sphere>
              <radius>0.10000000000000001</radius>
            </sphere>
          </geometry>
          <surface>
            <contact>
              <ode/>
            </contact>
            <friction>
              <ode>
                <mu>1.0</mu>
                <mu2>0.0</mu2>
                <fdir1 gz:expressed_in="sweepee_2/base_footprint">1 -1 0</fdir1>
              </ode>
            </friction>
            <bounce/>
          </surface>
        </collision>
        <visual name='sweepee_2/front_left_wheel_visual'>
          <pose>0 0 0 0 0 0</pose>
          <geometry>
            <sphere>
              <radius>0.10000000000000001</radius>
            </sphere>
          </geometry>
        </visual>
        <enable_wind>false</enable_wind>
      </link>
      <joint name='sweepee_2/front_right_wheel_joint' type='revolute'>
        <pose>-5.5511151231257827e-17 1.3877787807814457e-17 0 0 0 0</pose>
        <parent>sweepee_2/base_footprint</parent>
        <child>sweepee_2/front_right_wheel</child>
        <axis>
          <xyz>0 0 1</xyz>
          <limit>
            <lower>-1.7976900000000001e+308</lower>
            <upper>1.7976900000000001e+308</upper>
            <effort>10000</effort>
            <velocity>5.0999999999999996</velocity>
            <stiffness>100000000</stiffness>
            <dissipation>1</dissipation>
          </limit>
          <dynamics>
            <spring_reference>0</spring_reference>
            <spring_stiffness>0</spring_stiffness>
            <damping>0</damping>
            <friction>0</friction>
          </dynamics>
        </axis>
      </joint>
      <link name='sweepee_2/front_right_wheel'>
        <pose>0.29999999999999938 -0.25 0.10000000000000005 1.5705506182709605 -1.1679516870566595 -3.1413666141519121</pose>
        <inertial>
          <pose>0 0 0 0 0 0</pose>
          <mass>1</mass>
          <inertia>
            <ixx>0.14499999999999999</ixx>
            <ixy>0</ixy>
            <ixz>0</ixz>
            <iyy>0.14499999999999999</iyy>
            <iyz>0</iyz>
            <izz>0.125</izz>
          </inertia>
        </inertial>
        <collision name='sweepee_2/front_right_wheel_collision'>
          <pose>0 0 0 0 0 0</pose>
          <geometry>
            <sphere>
              <radius>0.10000000000000001</radius>
            </sphere>
          </geometry>
          <surface>
            <contact>
              <ode/>
            </contact>
            <friction>
              <ode>
                <mu>1.0</mu>
                <mu2>0.0</mu2>
                <fdir1 gz:expressed_in="sweepee_2/base_footprint">1 1 0</fdir1>
              </ode>
            </friction>
            <bounce/>
          </surface>
        </collision>
        <visual name='sweepee_2/front_right_wheel_visual'>
          <pose>0 0 0 0 0 0</pose>
          <geometry>
            <sphere>
              <radius>0.10000000000000001</radius>
            </sphere>
          </geometry>
        </visual>
        <enable_wind>false</enable_wind>
      </link>
      <joint name='sweepee_2/rear_left_wheel_joint' type='revolute'>
        <pose>5.5511151231257827e-17 -2.7755575615628914e-17 0 0 0 0</pose>
        <parent>sweepee_2/base_footprint</parent>
        <child>sweepee_2/rear_left_wheel</child>
        <axis>
          <xyz>0 0 1</xyz>
          <limit>
            <lower>-1.7976900000000001e+308</lower>
            <upper>1.7976900000000001e+308</upper>
            <effort>10000</effort>
            <velocity>5.0999999999999996</velocity>
            <stiffness>100000000</stiffness>
            <dissipation>1</dissipation>
          </limit>
          <dynamics>
            <spring_reference>0</spring_reference>
            <spring_stiffness>0</spring_stiffness>
            <damping>0</damping>
            <friction>0</friction>
          </dynamics>
        </axis>
      </joint>
      <link name='sweepee_2/rear_left_wheel'>
        <pose>-0.30000000000000004 0.25 0.10000000000000007 1.5706827322253689 -0.55861936897712472 -3.1415324466564529</pose>
        <inertial>
          <pose>0 0 0 0 0 0</pose>
          <mass>1</mass>
          <inertia>
            <ixx>0.14499999999999999</ixx>
            <ixy>0</ixy>
            <ixz>0</ixz>
            <iyy>0.14499999999999999</iyy>
            <iyz>0</iyz>
            <izz>0.125</izz>
          </inertia>
        </inertial>
        <collision name='sweepee_2/rear_left_wheel_collision'>
          <pose>0 0 0 0 0 0</pose>
          <geometry>
            <sphere>
              <radius>0.10000000000000001</radius>
            </sphere>
          </geometry>
          <surface>
            <contact>
              <ode/>
            </contact>
            <friction>
              <ode>
                <mu>1.0</mu>
                <mu2>0.0</mu2>
                <fdir1 gz:expressed_in="sweepee_2/base_footprint">1 1 0</fdir1>
              </ode>
            </friction>
            <bounce/>
          </surface>
        </collision>
        <visual name='sweepee_2/rear_left_wheel_visual'>
          <pose>0 0 0 0 0 0</pose>
          <geometry>
            <sphere>
              <radius>0.10000000000000001</radius>
            </sphere>
          </geometry>
        </visual>
        <enable_wind>false</enable_wind>
      </link>
      <joint name='sweepee_2/rear_right_wheel_joint' type='revolute'>
        <pose>5.5511151231257827e-17 1.3877787807814457e-17 0 0 0 0</pose>
        <parent>sweepee_2/base_footprint</parent>
        <child>sweepee_2/rear_right_wheel</child>
        <axis>
          <xyz>0 0 1</xyz>
          <limit>
            <lower>-1.7976900000000001e+308</lower>
            <upper>1.7976900000000001e+308</upper>
            <effort>10000</effort>
            <velocity>5.0999999999999996</velocity>
            <stiffness>100000000</stiffness>
            <dissipation>1</dissipation>
          </limit>
          <dynamics>
            <spring_reference>0</spring_reference>
            <spring_stiffness>0</spring_stiffness>
            <damping>0</damping>
            <friction>0</friction>
          </dynamics>
        </axis>
      </joint>
      <link name='sweepee_2/rear_right_wheel'>
        <pose>-0.30000000000000027 -0.24999999999999978 0.099999999999999992 -1.5703498205177389 -1.3533523703942603 -0.0004359919778096245</pose>
        <inertial>
          <pose>0 0 0 0 0 0</pose>
          <mass>1</mass>
          <inertia>
            <ixx>0.14499999999999999</ixx>
            <ixy>0</ixy>
            <ixz>0</ixz>
            <iyy>0.14499999999999999</iyy>
            <iyz>0</iyz>
            <izz>0.125</izz>
          </inertia>
        </inertial>
        <collision name='sweepee_2/rear_right_wheel_collision'>
          <pose>0 0 0 0 0 0</pose>
          <geometry>
            <sphere>
              <radius>0.10000000000000001</radius>
            </sphere>
          </geometry>
          <surface>
            <contact>
              <ode/>
            </contact>
            <friction>
              <ode>
                <mu>1.0</mu>
                <mu2>0.0</mu2>
                <fdir1 gz:expressed_in="sweepee_2/base_footprint">1 -1 0</fdir1>
              </ode>
            </friction>
            <bounce/>
          </surface>
        </collision>
        <visual name='sweepee_2/rear_right_wheel_visual'>
          <pose>0 0 0 0 0 0</pose>
          <geometry>
            <sphere>
              <radius>0.10000000000000001</radius>
            </sphere>
          </geometry>
        </visual>
        <enable_wind>false</enable_wind>
      </link>
      <joint name='sweepee_2/shoulder_pan_joint' type='revolute'>
        <pose>0 0 0 0 0 0</pose>
        <parent>sweepee_2/base_footprint</parent>
        <child>sweepee_2/shoulder_link</child>
        <axis>
          <xyz>0 0 1</xyz>
          <limit>
            <lower>-6.2831853071795862</lower>
            <upper>6.2831853071795862</upper>
            <effort>330</effort>
            <velocity>2.0943951023931948</velocity>
            <stiffness>100000000</stiffness>
            <dissipation>1</dissipation>
          </limit>
          <dynamics>
            <spring_reference>0</spring_reference>
            <spring_stiffness>0</spring_stiffness>
            <damping>0</damping>
            <friction>0</friction>
          </dynamics>
        </axis>
      </joint>
      <link name='sweepee_2/shoulder_link'>
        <pose>-2.2204460492503131e-16 -2.2204460492503131e-16 0.52729999999999999 0 0 3.1407758830697579</pose>
        <inertial>
          <pose>0 0 0 0 0 0</pose>
          <mass>7.7779999999999996</mass>
          <inertia>
            <ixx>0.031474312576936593</ixx>
            <ixy>0</ixy>
            <ixz>0</ixz>
            <iyy>0.031474312576936593</iyy>
            <iyz>0</iyz>
            <izz>0.021875624999999999</izz>
          </inertia>
        </inertial>
        <collision name='sweepee_2/shoulder_link_collision'>
          <pose>0 0 0 0 0 3.1415926535897931</pose>
          <geometry>
            <mesh>
              <scale>1 1 1</scale>
              <uri>file:///home/stefanomutti/lampo_ws/install/ur_description/share/ur_description/meshes/ur10/collision/shoulder.stl</uri>
            </mesh>
          </geometry>
        </collision>
        <visual name='sweepee_2/shoulder_link_visual'>
          <pose>0 0 0 0 0 3.1415926535897931</pose>
          <geometry>
            <mesh>
              <scale>1 1 1</scale>
              <uri>file:///home/stefanomutti/lampo_ws/install/ur_description/share/ur_description/meshes/ur10/visual/shoulder.dae</uri>
            </mesh>
          </geometry>
        </visual>
        <enable_wind>false</enable_wind>
      </link>
      <joint name='sweepee_2/shoulder_lift_joint' type='revolute'>
        <pose>0 0 0 0 0 0</pose>
        <parent>sweepee_2/shoulder_link</parent>
        <child>sweepee_2/upper_arm_link</child>
        <axis>
          <xyz>0 0 1</xyz>
          <limit>
            <lower>-6.2831853071795862</lower>
            <upper>6.2831853071795862</upper>
            <effort>330</effort>
            <velocity>2.0943951023931948</velocity>
            <stiffness>100000000</stiffness>
            <dissipation>1</dissipation>
          </limit>
          <dynamics>
            <spring_reference>0</spring_reference>
            <spring_stiffness>0</spring_stiffness>
            <damping>0</damping>
            <friction>0</friction>
          </dynamics>
        </axis>
      </joint>
      <link name='sweepee_2/upper_arm_link'>
        <pose>-2.2204460492503131e-16 -2.2204460492503131e-16 0.52729999999999999 1.5707963270000005 -0.00039343912719709068 3.140775883069677</pose>
        <inertial>
          <pose>-0.30599999999999999 0 0.17499999999999999 0 1.5707963267948966 0</pose>
          <mass>12.93</mass>
          <inertia>
            <ixx>0.42175380379841088</ixx>
            <ixy>0</ixy>
            <ixz>0</ixz>
            <iyy>0.42175380379841088</iyy>
            <iyz>0</iyz>
            <izz>0.036365624999999992</izz>
          </inertia>
        </inertial>
        <collision name='sweepee_2/upper_arm_link_collision'>
          <pose>0 0 0.220941 1.5707963267948959 5.5511151231257827e-17 -1.5707963267948959</pose>
          <geometry>
            <mesh>
              <scale>1 1 1</scale>
              <uri>file:///home/stefanomutti/lampo_ws/install/ur_description/share/ur_description/meshes/ur10/collision/upperarm.stl</uri>
            </mesh>
          </geometry>
        </collision>
        <visual name='sweepee_2/upper_arm_link_visual'>
          <pose>0 0 0.220941 1.5707963267948959 5.5511151231257827e-17 -1.5707963267948959</pose>
          <geometry>
            <mesh>
              <scale>1 1 1</scale>
              <uri>file:///home/stefanomutti/lampo_ws/install/ur_description/share/ur_description/meshes/ur10/visual/upperarm.dae</uri>
            </mesh>
          </geometry>
        </visual>
        <enable_wind>false</enable_wind>
      </link>
      <joint name='sweepee_2/elbow_joint' type='revolute'>
        <pose>0 1.1102230246251565e-16 1.6653345369377348e-16 0 0 0</pose>
        <parent>sweepee_2/upper_arm_link</parent>
        <child>sweepee_2/forearm_link</child>
        <axis>
          <xyz>0 0 1</xyz>
          <limit>
            <lower>-3.1415926535897931</lower>
            <upper>3.1415926535897931</upper>
            <effort>150</effort>
            <velocity>3.1415926535897931</velocity>
            <stiffness>100000000</stiffness>
            <dissipation>1</dissipation>
          </limit>
          <dynamics>
            <spring_reference>0</spring_reference>
            <spring_stiffness>0</spring_stiffness>
            <damping>0</damping>
            <friction>0</friction>
          </dynamics>
        </axis>
      </joint>
      <link name='sweepee_2/forearm_link'>
        <pose>0.61199974849604777 -0.00049986346404518045 0.52705921526036736 1.5707963270000003 -0.00054055379753565323 3.1407758830696468</pose>
        <inertial>
          <pose>-0.28615000000000002 0 0.049042000000000002 0 1.5707963267948966 0</pose>
          <mass>3.8700000000000001</mass>
          <inertia>
            <ixx>0.1110696940971046</ixx>
            <ixy>0</ixy>
            <ixz>0</ixz>
            <iyy>0.1110696940971046</iyy>
            <iyz>0</iyz>
            <izz>0.010884375</izz>
          </inertia>
        </inertial>
        <collision name='sweepee_2/forearm_link_collision'>
          <pose>0 0 0.049042000000000002 1.5707963267948959 5.5511151231257827e-17 -1.5707963267948959</pose>
          <geometry>
            <mesh>
              <scale>1 1 1</scale>
              <uri>file:///home/stefanomutti/lampo_ws/install/ur_description/share/ur_description/meshes/ur10/collision/forearm.stl</uri>
            </mesh>
          </geometry>
        </collision>
        <visual name='sweepee_2/forearm_link_visual'>
          <pose>0 0 0.049042000000000002 1.5707963267948959 5.5511151231257827e-17 -1.5707963267948959</pose>
          <geometry>
            <mesh>
              <scale>1 1 1</scale>
              <uri>file:///home/stefanomutti/lampo_ws/install/ur_description/share/ur_description/meshes/ur10/visual/forearm.dae</uri>
            </mesh>
          </geometry>
        </visual>
        <enable_wind>false</enable_wind>
      </link>
      <joint name='sweepee_2/wrist_1_joint' type='revolute'>
        <pose>0 1.1102230246251565e-16 -8.3266726846886741e-17 0 0 0</pose>
        <parent>sweepee_2/forearm_link</parent>
        <child>sweepee_2/wrist_1_link</child>
        <axis>
          <xyz>0 0 1</xyz>
          <limit>
            <lower>-6.2831853071795862</lower>
            <upper>6.2831853071795862</upper>
            <effort>56</effort>
            <velocity>3.1415926535897931</velocity>
            <stiffness>100000000</stiffness>
            <dissipation>1</dissipation>
          </limit>
          <dynamics>
            <spring_reference>0</spring_reference>
            <spring_stiffness>0</spring_stiffness>
            <damping>0</damping>
            <friction>0</friction>
          </dynamics>
        </axis>
      </joint>
      <link name='sweepee_2/wrist_1_link'>
        <pose>1.1844333761497561 0.1629736442038674 0.52674985630347848 1.5707963270000009 -0.0012420628439892237 3.1407758830695029</pose>
        <inertial>
          <pose>0 0 0 0 0 0</pose>
          <mass>1.96</mass>
          <inertia>
            <ixx>0.0051082479566999994</ixx>
            <ixy>0</ixy>
            <ixz>0</ixz>
            <iyy>0.0051082479566999994</iyy>
            <iyz>0</iyz>
            <izz>0.0055124999999999992</izz>
          </inertia>
        </inertial>
        <collision name='sweepee_2/wrist_1_link_collision'>
          <pose>0 0 -0.1149 1.5707963267948959 0 0</pose>
          <geometry>
            <mesh>
              <scale>1 1 1</scale>
              <uri>file:///home/stefanomutti/lampo_ws/install/ur_description/share/ur_description/meshes/ur10/collision/wrist1.stl</uri>
            </mesh>
          </geometry>
        </collision>
        <visual name='sweepee_2/wrist_1_link_visual'>
          <pose>0 0 -0.1149 1.5707963267948959 0 0</pose>
          <geometry>
            <mesh>
              <scale>1 1 1</scale>
              <uri>file:///home/stefanomutti/lampo_ws/install/ur_description/share/ur_description/meshes/ur10/visual/wrist1.dae</uri>
            </mesh>
          </geometry>
        </visual>
        <enable_wind>false</enable_wind>
      </link>
      <joint name='sweepee_2/wrist_2_joint' type='revolute'>
        <pose>0 2.7755575615628914e-17 0 0 0 -5.1517785475977202e-36</pose>
        <parent>sweepee_2/wrist_1_link</parent>
        <child>sweepee_2/wrist_2_link</child>
        <axis>
          <xyz>0 0 1</xyz>
          <limit>
            <lower>-6.2831853071795862</lower>
            <upper>6.2831853071795862</upper>
            <effort>56</effort>
            <velocity>3.1415926535897931</velocity>
            <stiffness>100000000</stiffness>
            <dissipation>1</dissipation>
          </limit>
          <dynamics>
            <spring_reference>0</spring_reference>
            <spring_stiffness>0</spring_stiffness>
            <damping>0</damping>
            <friction>0</friction>
          </dynamics>
        </axis>
      </joint>
      <link name='sweepee_2/wrist_2_link'>
        <pose>1.1842896695635523 0.16297376153173593 0.41104994554982538 3.1415915376110579 -0.001242062342642785 -3.1415106053544033</pose>
        <inertial>
          <pose>0 0 0 0 0 0</pose>
          <mass>1.96</mass>
          <inertia>
            <ixx>0.0040792483682999996</ixx>
            <ixy>0</ixy>
            <ixz>0</ixz>
            <iyy>0.0040792483682999996</iyy>
            <iyz>0</iyz>
            <izz>0.0055124999999999992</izz>
          </inertia>
        </inertial>
        <collision name='sweepee_2/wrist_2_link_collision'>
          <pose>0 0 -0.1158 0 0 0</pose>
          <geometry>
            <mesh>
              <scale>1 1 1</scale>
              <uri>file:///home/stefanomutti/lampo_ws/install/ur_description/share/ur_description/meshes/ur10/collision/wrist2.stl</uri>
            </mesh>
          </geometry>
        </collision>
        <visual name='sweepee_2/wrist_2_link_visual'>
          <pose>0 0 -0.1158 0 0 0</pose>
          <geometry>
            <mesh>
              <scale>1 1 1</scale>
              <uri>file:///home/stefanomutti/lampo_ws/install/ur_description/share/ur_description/meshes/ur10/visual/wrist2.dae</uri>
            </mesh>
          </geometry>
        </visual>
        <enable_wind>false</enable_wind>
      </link>
      <joint name='sweepee_2/wrist_3_joint' type='revolute'>
        <pose>0 0 -5.5511151231257827e-17 0 0 1.2325951644078309e-32</pose>
        <parent>sweepee_2/wrist_2_link</parent>
        <child>sweepee_2/wrist_3_link</child>
        <axis>
          <xyz>0 0 1</xyz>
          <limit>
            <lower>-6.2831853071795862</lower>
            <upper>6.2831853071795862</upper>
            <effort>56</effort>
            <velocity>3.1415926535897931</velocity>
            <stiffness>100000000</stiffness>
            <dissipation>1</dissipation>
          </limit>
          <dynamics>
            <spring_reference>0</spring_reference>
            <spring_stiffness>0</spring_stiffness>
            <damping>0</damping>
            <friction>0</friction>
          </dynamics>
        </axis>
      </joint>
      <link name='sweepee_2/wrist_3_link'>
        <pose>1.184282104844081 0.25517376122134738 0.41105004846189591 1.5707952106118124 -0.00043664619080915966 -3.1415106062533953</pose>
        <inertial>
          <pose>0 0 -0.01525 0 0 0</pose>
          <mass>0.20200000000000001</mass>
          <inertia>
            <ixx>0.00011792166116465</ixx>
            <ixy>0</ixy>
            <ixz>0</ixz>
            <iyy>0.00011792166116465</iyy>
            <iyz>0</iyz>
            <izz>0.000204525</izz>
          </inertia>
        </inertial>
        <collision name='sweepee_2/wrist_3_link_collision'>
          <pose>0 0 -0.092200000000000004 1.5707963267948959 0 0</pose>
          <geometry>
            <mesh>
              <scale>1 1 1</scale>
              <uri>file:///home/stefanomutti/lampo_ws/install/ur_description/share/ur_description/meshes/ur10/collision/wrist3.stl</uri>
            </mesh>
          </geometry>
        </collision>
        <visual name='sweepee_2/wrist_3_link_visual'>
          <pose>0 0 -0.092200000000000004 1.5707963267948959 0 0</pose>
          <geometry>
            <mesh>
              <scale>1 1 1</scale>
              <uri>file:///home/stefanomutti/lampo_ws/install/ur_description/share/ur_description/meshes/ur10/visual/wrist3.dae</uri>
            </mesh>
          </geometry>
        </visual>
        <enable_wind>false</enable_wind>
      </link>
      <plugin name='gz::sim::systems::MecanumDrive' filename='gz-sim-mecanum-drive-system'>
        <front_left_joint>sweepee_2/front_left_wheel_joint</front_left_joint>
        <front_right_joint>sweepee_2/front_right_wheel_joint</front_right_joint>
        <back_left_joint>sweepee_2/rear_left_wheel_joint</back_left_joint>
        <back_right_joint>sweepee_2/rear_right_wheel_joint</back_right_joint>
        <wheel_separation>0.5</wheel_separation>
        <wheelbase>0.7</wheelbase>
        <wheel_radius>0.1</wheel_radius>
        <min_acceleration>-5</min_acceleration>
        <max_acceleration>5</max_acceleration>
        <topic>sweepee_2/cmd_vel</topic>
        <frame_id>sweepee_2/base_link_sweepee</frame_id>
      </plugin>
      <plugin name='gz_ros2_control::GazeboSimROS2ControlPlugin' filename='libgz_ros2_control-system.so'>
        <robot_param>robot_description</robot_param>
        <robot_param_node>robot_state_publisher</robot_param_node>
        <controller_manager_prefix_node_name>sweepee_2</controller_manager_prefix_node_name>
        <parameters>/home/stefanomutti/lampo_ws/install/lampo_description/share/lampo_description/config/ur_controllers_2.yaml</parameters>
        <ros>
          <namespace>sweepee_2</namespace>
        </ros>
      </plugin>
      <frame name='sweepee_2/front_laser_joint' attached_to='sweepee_2/base_link_sweepee'>
        <pose>0.35999999999999999 0 0.26000000000000001 0 0 0</pose>
      </frame>
      <frame name='sweepee_2/front_laser' attached_to='sweepee_2/front_laser_joint'>
        <pose>0 0 0 0 0 0</pose>
      </frame>
      <frame name='sweepee_2/rear_laser_joint' attached_to='sweepee_2/base_link_sweepee'>
        <pose>-0.35999999999999999 0 0.26000000000000001 0 0 3.1415899999999999</pose>
      </frame>
      <frame name='sweepee_2/rear_laser' attached_to='sweepee_2/rear_laser_joint'>
        <pose>0 0 0 0 0 0</pose>
      </frame>
      <frame name='sweepee_2/base_footprint_joint' attached_to='sweepee_2/base_footprint'>
        <pose>0 0 0 0 0 0</pose>
      </frame>
      <frame name='sweepee_2/base_link_sweepee' attached_to='sweepee_2/base_footprint_joint'>
        <pose>0 0 0 0 0 0</pose>
      </frame>
      <frame name='sweepee_2/base_link-base_fixed_joint' attached_to='sweepee_2/base_link'>
        <pose>0 0 0 0 0 3.1415926535897931</pose>
      </frame>
      <frame name='sweepee_2/base' attached_to='sweepee_2/base_link-base_fixed_joint'>
        <pose>0 0 0 0 0 0</pose>
      </frame>
      <frame name='sweepee_2/base_link-base_link_inertia' attached_to='sweepee_2/base_link'>
        <pose>0 0 0 0 0 3.1415926535897931</pose>
      </frame>
      <frame name='sweepee_2/base_link_inertia' attached_to='sweepee_2/base_link-base_link_inertia'>
        <pose>0 0 0 0 0 0</pose>
      </frame>
      <frame name='sweepee_2/flange-tool0' attached_to='sweepee_2/flange'>
        <pose>0 0 0 1.5707963267948959 -5.5511151231257827e-17 1.5707963267948959</pose>
      </frame>
      <frame name='sweepee_2/tool0' attached_to='sweepee_2/flange-tool0'>
        <pose>0 0 0 0 0 0</pose>
      </frame>
      <frame name='sweepee_2/wrist_3-flange' attached_to='sweepee_2/wrist_3_link'>
        <pose>0 0 0 -1.5707963267948957 -1.5707963267948966 0</pose>
      </frame>
      <frame name='sweepee_2/flange' attached_to='sweepee_2/wrist_3-flange'>
        <pose>0 0 0 0 0 0</pose>
      </frame>
      <frame name='sweepee_2/wrist_3_link-ft_frame' attached_to='sweepee_2/wrist_3_link'>
        <pose>0 0 0 3.1415926535897931 0 0</pose>
      </frame>
      <frame name='sweepee_2/ft_frame' attached_to='sweepee_2/wrist_3_link-ft_frame'>
        <pose>0 0 0 0 0 0</pose>
      </frame>
      <frame name='sweepee_2/base_joint' attached_to='sweepee_2/base_footprint'>
        <pose>0 0 0.40000000000000002 0 0 0</pose>
      </frame>
      <frame name='sweepee_2/base_link' attached_to='sweepee_2/base_joint'>
        <pose>0 0 0 0 0 0</pose>
      </frame>
      <pose>-0.71226332349694155 1.98948459177051 -7.5037302232010457e-07 1.136839462468235e-07 4.9515905817926549e-07 2.6761841843343928</pose>
      <static>false</static>
      <self_collide>false</self_collide>
    </model>
</sdf>
