<sdf version='1.7'>
  <model name='eureca'>
    <link name='sweepee_1/base_footprint'>
      <inertial>
        <pose>0 0 0.00067 0 -0 0</pose>
        <mass>5012</mass>
        <inertia>
          <ixx>2.44241</ixx>
          <ixy>0.02</ixy>
          <ixz>0.02</ixz>
          <iyy>3.98648</iyy>
          <iyz>0.02</iyz>
          <izz>4.13653</izz>
        </inertia>
      </inertial>
      <collision name='sweepee_1/base_footprint_collision'>
        <pose>0 0 0.005 0 -0 0</pose>
        <geometry>
          <box>
            <size>1.02 0.55 0.01</size>
          </box>
        </geometry>
      </collision>
      <collision name='sweepee_1/base_footprint_fixed_joint_lump__sweepee_1/base_link_inertia_collision_1'>
        <pose>0 0 0.56 0 -0 3.14159</pose>
        <geometry>
          <mesh>
            <scale>1 1 1</scale>
            <uri>file:///home/kolmogorov/Documents/2ROS/lampo_ws_ros2/install/ur_description/share/ur_description/meshes/ur10/collision/base.stl</uri>
          </mesh>
        </geometry>
      </collision>
      <visual name='sweepee_1/base_footprint_fixed_joint_lump__sweepee_1/base_link_sweepee_visual'>
        <pose>0 0 0.032 0 0 -1.57079</pose>
        <geometry>
          <mesh>
            <scale>1 1 1</scale>
            <uri>file:///home/kolmogorov/Documents/2ROS/lampo_ws_ros2/install/lampo_description/share/lampo_description//meshes/sweepee/visual/sweepee.dae</uri>
          </mesh>
        </geometry>
      </visual>
      <visual name='sweepee_1/base_footprint_fixed_joint_lump__sweepee_1/base_link_inertia_visual_1'>
        <pose>0 0 0.56 0 -0 3.14159</pose>
        <geometry>
          <mesh>
            <scale>1 1 1</scale>
            <uri>file:///home/kolmogorov/Documents/2ROS/lampo_ws_ros2/install/ur_description/share/ur_description/meshes/ur10/visual/base.dae</uri>
          </mesh>
        </geometry>
      </visual>
      <sensor name='sweepee_1/front_laser' type='ray'>
        <update_rate>10</update_rate>
        <ray>
          <scan>
            <horizontal>
              <samples>750</samples>
              <resolution>1</resolution>
              <min_angle>-1.57079</min_angle>
              <max_angle>1.57079</max_angle>
            </horizontal>
          </scan>
          <range>
            <min>0.25</min>
            <max>59</max>
          </range>
        </ray>
        <plugin name='front_laser_plugin' filename='libgazebo_ros_ray_sensor.so'>
          <noise>
            <type>gaussian</type>
            <mean>0.0</mean>
            <stddev>0.01</stddev>
          </noise>
          <ros>
            <namespace>sweepee_1/</namespace>
            <argument>~out:=sweepee_1/rear_scan</argument>
          </ros>
          <alwaysOn>1</alwaysOn>
          <updateRate>15</updateRate>
          <frame_name>sweepee_1/front_laser</frame_name>
          <output_type>sensor_msgs/LaserScan</output_type>
        </plugin>
        <pose>0.36 0 0.26 0 -0 0</pose>
      </sensor>
      <sensor name='sweepee_1/rear_laser' type='ray'>
        <update_rate>10</update_rate>
        <ray>
          <scan>
            <horizontal>
              <samples>750</samples>
              <resolution>1</resolution>
              <min_angle>-1.57079</min_angle>
              <max_angle>1.57079</max_angle>
            </horizontal>
          </scan>
          <range>
            <min>0.25</min>
            <max>59</max>
          </range>
        </ray>
        <plugin name='rear_laser_plugin' filename='libgazebo_ros_ray_sensor.so'>
          <noise>
            <type>gaussian</type>
            <mean>0.0</mean>
            <stddev>0.01</stddev>
          </noise>
          <ros>
            <namespace>sweepee_1/</namespace>
            <argument>~out:=sweepee_1/rear_scan</argument>
          </ros>
          <alwaysOn>1</alwaysOn>
          <updateRate>15</updateRate>
          <frame_name>sweepee_1/rear_laser</frame_name>
          <output_type>sensor_msgs/LaserScan</output_type>
        </plugin>
        <pose>-0.36 0 0.26 0 -0 3.14159</pose>
      </sensor>
    </link>
    <joint name='sweepee_1/shoulder_pan_joint' type='revolute'>
      <pose relative_to='sweepee_1/base_footprint'>0 0 0.6873 0 0 -0</pose>
      <parent>sweepee_1/base_footprint</parent>
      <child>sweepee_1/shoulder_link</child>
      <axis>
        <xyz>0 0 1</xyz>
        <limit>
          <lower>-6.28319</lower>
          <upper>6.28319</upper>
          <effort>330</effort>
          <velocity>2.0944</velocity>
        </limit>
        <dynamics>
          <damping>0</damping>
          <friction>0</friction>
          <spring_reference>0</spring_reference>
          <spring_stiffness>0</spring_stiffness>
        </dynamics>
      </axis>
    </joint>
    <link name='sweepee_1/shoulder_link'>
      <pose relative_to='sweepee_1/shoulder_pan_joint'>0 0 0 0 -0 0</pose>
      <inertial>
        <pose>0 0 0 0 -0 0</pose>
        <mass>7.778</mass>
        <inertia>
          <ixx>0.0314743</ixx>
          <ixy>0</ixy>
          <ixz>0</ixz>
          <iyy>0.0314743</iyy>
          <iyz>0</iyz>
          <izz>0.0218756</izz>
        </inertia>
      </inertial>
      <collision name='sweepee_1/shoulder_link_collision'>
        <pose>0 0 0 0 -0 3.14159</pose>
        <geometry>
          <mesh>
            <scale>1 1 1</scale>
            <uri>file:///home/kolmogorov/Documents/2ROS/lampo_ws_ros2/install/ur_description/share/ur_description/meshes/ur10/collision/shoulder.stl</uri>
          </mesh>
        </geometry>
      </collision>
      <visual name='sweepee_1/shoulder_link_visual'>
        <pose>0 0 0 0 -0 3.14159</pose>
        <geometry>
          <mesh>
            <scale>1 1 1</scale>
            <uri>file:///home/kolmogorov/Documents/2ROS/lampo_ws_ros2/install/ur_description/share/ur_description/meshes/ur10/visual/shoulder.dae</uri>
          </mesh>
        </geometry>
      </visual>
    </link>
    <joint name='sweepee_1/shoulder_lift_joint' type='revolute'>
      <pose relative_to='sweepee_1/shoulder_link'>0 0 0 1.5708 -0 0</pose>
      <parent>sweepee_1/shoulder_link</parent>
      <child>sweepee_1/upper_arm_link</child>
      <axis>
        <xyz>0 0 1</xyz>
        <limit>
          <lower>-6.28319</lower>
          <upper>6.28319</upper>
          <effort>330</effort>
          <velocity>2.0944</velocity>
        </limit>
        <dynamics>
          <damping>0</damping>
          <friction>0</friction>
          <spring_reference>0</spring_reference>
          <spring_stiffness>0</spring_stiffness>
        </dynamics>
      </axis>
    </joint>
    <link name='sweepee_1/upper_arm_link'>
      <pose relative_to='sweepee_1/shoulder_lift_joint'>0 0 0 0 -0 0</pose>
      <inertial>
        <pose>-0.306 0 0.175 0 1.5708 0</pose>
        <mass>12.93</mass>
        <inertia>
          <ixx>0.421754</ixx>
          <ixy>0</ixy>
          <ixz>0</ixz>
          <iyy>0.421754</iyy>
          <iyz>0</iyz>
          <izz>0.0363656</izz>
        </inertia>
      </inertial>
      <collision name='sweepee_1/upper_arm_link_collision'>
        <pose>0 0 0.220941 1.5708 0 -1.5708</pose>
        <geometry>
          <mesh>
            <scale>1 1 1</scale>
            <uri>file:///home/kolmogorov/Documents/2ROS/lampo_ws_ros2/install/ur_description/share/ur_description/meshes/ur10/collision/upperarm.stl</uri>
          </mesh>
        </geometry>
      </collision>
      <visual name='sweepee_1/upper_arm_link_visual'>
        <pose>0 0 0.220941 1.5708 0 -1.5708</pose>
        <geometry>
          <mesh>
            <scale>1 1 1</scale>
            <uri>file:///home/kolmogorov/Documents/2ROS/lampo_ws_ros2/install/ur_description/share/ur_description/meshes/ur10/visual/upperarm.dae</uri>
          </mesh>
        </geometry>
      </visual>
    </link>
    <joint name='sweepee_1/elbow_joint' type='revolute'>
      <pose relative_to='sweepee_1/upper_arm_link'>-0.612 0 0 0 -0 0</pose>
      <parent>sweepee_1/upper_arm_link</parent>
      <child>sweepee_1/forearm_link</child>
      <axis>
        <xyz>0 0 1</xyz>
        <limit>
          <lower>-3.14159</lower>
          <upper>3.14159</upper>
          <effort>150</effort>
          <velocity>3.14159</velocity>
        </limit>
        <dynamics>
          <damping>0</damping>
          <friction>0</friction>
          <spring_reference>0</spring_reference>
          <spring_stiffness>0</spring_stiffness>
        </dynamics>
      </axis>
    </joint>
    <link name='sweepee_1/forearm_link'>
      <pose relative_to='sweepee_1/elbow_joint'>0 0 0 0 -0 0</pose>
      <inertial>
        <pose>-0.28615 0 0.049042 0 1.5708 0</pose>
        <mass>3.87</mass>
        <inertia>
          <ixx>0.11107</ixx>
          <ixy>0</ixy>
          <ixz>0</ixz>
          <iyy>0.11107</iyy>
          <iyz>0</iyz>
          <izz>0.0108844</izz>
        </inertia>
      </inertial>
      <collision name='sweepee_1/forearm_link_collision'>
        <pose>0 0 0.049042 1.5708 0 -1.5708</pose>
        <geometry>
          <mesh>
            <scale>1 1 1</scale>
            <uri>file:///home/kolmogorov/Documents/2ROS/lampo_ws_ros2/install/ur_description/share/ur_description/meshes/ur10/collision/forearm.stl</uri>
          </mesh>
        </geometry>
      </collision>
      <visual name='sweepee_1/forearm_link_visual'>
        <pose>0 0 0.049042 1.5708 0 -1.5708</pose>
        <geometry>
          <mesh>
            <scale>1 1 1</scale>
            <uri>file:///home/kolmogorov/Documents/2ROS/lampo_ws_ros2/install/ur_description/share/ur_description/meshes/ur10/visual/forearm.dae</uri>
          </mesh>
        </geometry>
      </visual>
    </link>
    <joint name='sweepee_1/wrist_1_joint' type='revolute'>
      <pose relative_to='sweepee_1/forearm_link'>-0.5723 0 0.163941 0 -0 0</pose>
      <parent>sweepee_1/forearm_link</parent>
      <child>sweepee_1/wrist_1_link</child>
      <axis>
        <xyz>0 0 1</xyz>
        <limit>
          <lower>-6.28319</lower>
          <upper>6.28319</upper>
          <effort>56</effort>
          <velocity>3.14159</velocity>
        </limit>
        <dynamics>
          <damping>0</damping>
          <friction>0</friction>
          <spring_reference>0</spring_reference>
          <spring_stiffness>0</spring_stiffness>
        </dynamics>
      </axis>
    </joint>
    <link name='sweepee_1/wrist_1_link'>
      <pose relative_to='sweepee_1/wrist_1_joint'>0 0 0 0 -0 0</pose>
      <inertial>
        <pose>0 0 0 0 -0 0</pose>
        <mass>1.96</mass>
        <inertia>
          <ixx>0.00510825</ixx>
          <ixy>0</ixy>
          <ixz>0</ixz>
          <iyy>0.00510825</iyy>
          <iyz>0</iyz>
          <izz>0.0055125</izz>
        </inertia>
      </inertial>
      <collision name='sweepee_1/wrist_1_link_collision'>
        <pose>0 0 -0.1149 1.5708 -0 0</pose>
        <geometry>
          <mesh>
            <scale>1 1 1</scale>
            <uri>file:///home/kolmogorov/Documents/2ROS/lampo_ws_ros2/install/ur_description/share/ur_description/meshes/ur10/collision/wrist1.stl</uri>
          </mesh>
        </geometry>
      </collision>
      <visual name='sweepee_1/wrist_1_link_visual'>
        <pose>0 0 -0.1149 1.5708 -0 0</pose>
        <geometry>
          <mesh>
            <scale>1 1 1</scale>
            <uri>file:///home/kolmogorov/Documents/2ROS/lampo_ws_ros2/install/ur_description/share/ur_description/meshes/ur10/visual/wrist1.dae</uri>
          </mesh>
        </geometry>
      </visual>
    </link>
    <joint name='sweepee_1/wrist_2_joint' type='revolute'>
      <pose relative_to='sweepee_1/wrist_1_link'>0 -0.1157 -0 1.5708 -0 0</pose>
      <parent>sweepee_1/wrist_1_link</parent>
      <child>sweepee_1/wrist_2_link</child>
      <axis>
        <xyz>0 0 1</xyz>
        <limit>
          <lower>-6.28319</lower>
          <upper>6.28319</upper>
          <effort>56</effort>
          <velocity>3.14159</velocity>
        </limit>
        <dynamics>
          <damping>0</damping>
          <friction>0</friction>
          <spring_reference>0</spring_reference>
          <spring_stiffness>0</spring_stiffness>
        </dynamics>
      </axis>
    </joint>
    <link name='sweepee_1/wrist_2_link'>
      <pose relative_to='sweepee_1/wrist_2_joint'>0 0 0 0 -0 0</pose>
      <inertial>
        <pose>0 0 0 0 -0 0</pose>
        <mass>1.96</mass>
        <inertia>
          <ixx>0.00407925</ixx>
          <ixy>0</ixy>
          <ixz>0</ixz>
          <iyy>0.00407925</iyy>
          <iyz>0</iyz>
          <izz>0.0055125</izz>
        </inertia>
      </inertial>
      <collision name='sweepee_1/wrist_2_link_collision'>
        <pose>0 0 -0.1158 0 -0 0</pose>
        <geometry>
          <mesh>
            <scale>1 1 1</scale>
            <uri>file:///home/kolmogorov/Documents/2ROS/lampo_ws_ros2/install/ur_description/share/ur_description/meshes/ur10/collision/wrist2.stl</uri>
          </mesh>
        </geometry>
      </collision>
      <visual name='sweepee_1/wrist_2_link_visual'>
        <pose>0 0 -0.1158 0 -0 0</pose>
        <geometry>
          <mesh>
            <scale>1 1 1</scale>
            <uri>file:///home/kolmogorov/Documents/2ROS/lampo_ws_ros2/install/ur_description/share/ur_description/meshes/ur10/visual/wrist2.dae</uri>
          </mesh>
        </geometry>
      </visual>
    </link>
    <joint name='sweepee_1/wrist_3_joint' type='revolute'>
      <pose relative_to='sweepee_1/wrist_2_link'>0 0.0922 -0 -1.5708 0 -0</pose>
      <parent>sweepee_1/wrist_2_link</parent>
      <child>sweepee_1/wrist_3_link</child>
      <axis>
        <xyz>0 0 1</xyz>
        <limit>
          <lower>-6.28319</lower>
          <upper>6.28319</upper>
          <effort>56</effort>
          <velocity>3.14159</velocity>
        </limit>
        <dynamics>
          <damping>0</damping>
          <friction>0</friction>
          <spring_reference>0</spring_reference>
          <spring_stiffness>0</spring_stiffness>
        </dynamics>
      </axis>
    </joint>
    <link name='sweepee_1/wrist_3_link'>
      <pose relative_to='sweepee_1/wrist_3_joint'>0 0 0 0 -0 0</pose>
      <inertial>
        <pose>0 0 -0.01525 0 -0 0</pose>
        <mass>0.202</mass>
        <inertia>
          <ixx>0.000117922</ixx>
          <ixy>0</ixy>
          <ixz>0</ixz>
          <iyy>0.000117922</iyy>
          <iyz>0</iyz>
          <izz>0.000204525</izz>
        </inertia>
      </inertial>
      <collision name='sweepee_1/wrist_3_link_collision'>
        <pose>0 0 -0.0922 1.5708 -0 0</pose>
        <geometry>
          <mesh>
            <scale>1 1 1</scale>
            <uri>file:///home/kolmogorov/Documents/2ROS/lampo_ws_ros2/install/ur_description/share/ur_description/meshes/ur10/collision/wrist3.stl</uri>
          </mesh>
        </geometry>
      </collision>
      <visual name='sweepee_1/wrist_3_link_visual'>
        <pose>0 0 -0.0922 1.5708 -0 0</pose>
        <geometry>
          <mesh>
            <scale>1 1 1</scale>
            <uri>file:///home/kolmogorov/Documents/2ROS/lampo_ws_ros2/install/ur_description/share/ur_description/meshes/ur10/visual/wrist3.dae</uri>
          </mesh>
        </geometry>
      </visual>
    </link>
    <plugin name='gazebo_ros2_control' filename='libgazebo_ros2_control.so'>
      <robot_param>robot_description</robot_param>
      <robot_namespace>sweepee_1/</robot_namespace>
      <parameters>/home/kolmogorov/Documents/2ROS/lampo_ws_ros2/install/lampo_description/share/lampo_description/config/ur_controllers_1.yaml</parameters>
      <robot_param_node>robot_state_publisher</robot_param_node>
    </plugin>
    <static>0</static>
    <plugin name='object_controller' filename='libgazebo_ros_planar_move.so'>
      <ros>
        <argument>~cmd_vel:=custom_cmd_vel</argument>
        <argument>~odom:=custom_odom</argument>
      </ros>
      <update_rate>100</update_rate>
      <publish_rate>10</publish_rate>
      <publish_odom>1</publish_odom>
      <publish_odom_tf>1</publish_odom_tf>
      <odometry_frame>sweepee_1/odom</odometry_frame>
      <robot_base_frame>sweepee_1/base_footprint</robot_base_frame>
      <covariance_x>0.0001</covariance_x>
      <covariance_y>0.0001</covariance_y>
      <covariance_yaw>0.01</covariance_yaw>
    </plugin>
  </model>
</sdf>
