<sdf version='1.10'>
    <model name='Depot'>
      <static>false</static>
      <link name='main'>
        <collision name='collision'>
          <pose>0 0 0 0 0 0</pose>
          <geometry>
            <plane>
              <normal>0 0 1</normal>
              <size>100 100</size>
            </plane>
          </geometry>
          <surface>
            <friction>
              <ode/>
            </friction>
            <bounce/>
            <contact/>
          </surface>
        </collision>
        <visual name='ROOF_visual'>
          <geometry>
            <mesh>
              <scale>0.59999999999999998 0.59999999999999998 0.59999999999999998</scale>
              <uri>file://home/gino/.gz/fuel/fuel.gazebosim.org/openrobotics/models/depot/5/meshes/Depot.dae</uri>
              <submesh>
                <name>ROOF</name>
                <center>false</center>
              </submesh>
            </mesh>
          </geometry>
          <material>
            <diffuse>1 1 1 1</diffuse>
            <specular>1 1 1 1</specular>
            <script>
              <uri>file://home/gino/.gz/fuel/fuel.gazebosim.org/openrobotics/models/depot/5/materials/scripts/</uri>
              <uri>materials/textures/</uri>
              <name>UrbanTile/ROOF_Diffuse</name>
            </script>
          </material>
        </visual>
        <visual name='WALLS_visual'>
          <geometry>
            <mesh>
              <scale>0.59999999999999998 0.59999999999999998 0.59999999999999998</scale>
              <uri>file://home/gino/.gz/fuel/fuel.gazebosim.org/openrobotics/models/depot/5/meshes/Depot.dae</uri>
              <submesh>
                <name>WALLS</name>
                <center>false</center>
              </submesh>
            </mesh>
          </geometry>
          <material>
            <diffuse>1 1 1 1</diffuse>
            <specular>1 1 1 1</specular>
            <script>
              <uri>file://home/gino/.gz/fuel/fuel.gazebosim.org/openrobotics/models/depot/5/materials/scripts/</uri>
              <uri>materials/textures/</uri>
              <name>UrbanTile/WALLS_Diffuse</name>
            </script>
          </material>
        </visual>
        <visual name='PILLERS_visual'>
          <geometry>
            <mesh>
              <scale>0.59999999999999998 0.59999999999999998 0.59999999999999998</scale>
              <uri>file://home/gino/.gz/fuel/fuel.gazebosim.org/openrobotics/models/depot/5/meshes/Depot.dae</uri>
              <submesh>
                <name>PILLERS</name>
                <center>false</center>
              </submesh>
            </mesh>
          </geometry>
          <material>
            <diffuse>1 1 1 1</diffuse>
            <specular>1 1 1 1</specular>
            <script>
              <uri>file://home/gino/.gz/fuel/fuel.gazebosim.org/openrobotics/models/depot/5/materials/scripts/</uri>
              <uri>materials/textures/</uri>
              <name>UrbanTile/PILLERS_Diffuse</name>
            </script>
          </material>
        </visual>
        <visual name='FANS_visual'>
          <geometry>
            <mesh>
              <scale>0.59999999999999998 0.59999999999999998 0.59999999999999998</scale>
              <uri>file://home/gino/.gz/fuel/fuel.gazebosim.org/openrobotics/models/depot/5/meshes/Depot.dae</uri>
              <submesh>
                <name>FANS</name>
                <center>false</center>
              </submesh>
            </mesh>
          </geometry>
          <material>
            <diffuse>1 1 1 1</diffuse>
            <specular>1 1 1 1</specular>
            <script>
              <uri>file://home/gino/.gz/fuel/fuel.gazebosim.org/openrobotics/models/depot/5/materials/scripts/</uri>
              <uri>materials/textures/</uri>
              <name>UrbanTile/FAN_Diffuse</name>
            </script>
          </material>
        </visual>
        <visual name='WINDOW_visual'>
          <geometry>
            <mesh>
              <scale>0.59999999999999998 0.59999999999999998 0.59999999999999998</scale>
              <uri>file://home/gino/.gz/fuel/fuel.gazebosim.org/openrobotics/models/depot/5/meshes/Depot.dae</uri>
              <submesh>
                <name>WINDOW</name>
                <center>false</center>
              </submesh>
            </mesh>
          </geometry>
          <material>
            <diffuse>1 1 1 1</diffuse>
            <specular>1 1 1 1</specular>
            <script>
              <uri>file://home/gino/.gz/fuel/fuel.gazebosim.org/openrobotics/models/depot/5/materials/scripts/</uri>
              <uri>materials/textures/</uri>
              <name>UrbanTile/WINDOW_Diffuse</name>
            </script>
          </material>
        </visual>
        <visual name='INTERCOM_visual'>
          <geometry>
            <mesh>
              <scale>0.59999999999999998 0.59999999999999998 0.59999999999999998</scale>
              <uri>file://home/gino/.gz/fuel/fuel.gazebosim.org/openrobotics/models/depot/5/meshes/Depot.dae</uri>
              <submesh>
                <name>INTERCOM</name>
                <center>false</center>
              </submesh>
            </mesh>
          </geometry>
          <material>
            <diffuse>1 1 1 1</diffuse>
            <specular>1 1 1 1</specular>
            <script>
              <uri>file://home/gino/.gz/fuel/fuel.gazebosim.org/openrobotics/models/depot/5/materials/scripts/</uri>
              <uri>materials/textures/</uri>
              <name>UrbanTile/INTERCOM_Diffuse</name>
            </script>
          </material>
        </visual>
        <visual name='FireAlarm_visual'>
          <geometry>
            <mesh>
              <scale>0.59999999999999998 0.59999999999999998 0.59999999999999998</scale>
              <uri>file://home/gino/.gz/fuel/fuel.gazebosim.org/openrobotics/models/depot/5/meshes/Depot.dae</uri>
              <submesh>
                <name>FireAlarm</name>
                <center>false</center>
              </submesh>
            </mesh>
          </geometry>
          <material>
            <diffuse>1 1 1 1</diffuse>
            <specular>1 1 1 1</specular>
            <script>
              <uri>file://home/gino/.gz/fuel/fuel.gazebosim.org/openrobotics/models/depot/5/materials/scripts/</uri>
              <uri>materials/textures/</uri>
              <name>UrbanTile/FireAlarm_Diffuse</name>
            </script>
          </material>
        </visual>
        <visual name='FireAlarmPole_visual'>
          <geometry>
            <mesh>
              <scale>0.59999999999999998 0.59999999999999998 0.59999999999999998</scale>
              <uri>file://home/gino/.gz/fuel/fuel.gazebosim.org/openrobotics/models/depot/5/meshes/Depot.dae</uri>
              <submesh>
                <name>FireAlarmPole</name>
                <center>false</center>
              </submesh>
            </mesh>
          </geometry>
          <material>
            <diffuse>1 1 1 1</diffuse>
            <specular>1 1 1 1</specular>
            <script>
              <uri>file://home/gino/.gz/fuel/fuel.gazebosim.org/openrobotics/models/depot/5/materials/scripts/</uri>
              <uri>materials/textures/</uri>
              <name>UrbanTile/FireAlarmPole</name>
            </script>
          </material>
        </visual>
        <visual name='Pipes_visual'>
          <geometry>
            <mesh>
              <scale>0.59999999999999998 0.59999999999999998 0.59999999999999998</scale>
              <uri>file://home/gino/.gz/fuel/fuel.gazebosim.org/openrobotics/models/depot/5/meshes/Depot.dae</uri>
              <submesh>
                <name>Pipes</name>
                <center>false</center>
              </submesh>
            </mesh>
          </geometry>
          <material>
            <diffuse>1 1 1 1</diffuse>
            <specular>1 1 1 1</specular>
            <script>
              <uri>file://home/gino/.gz/fuel/fuel.gazebosim.org/openrobotics/models/depot/5/materials/scripts/</uri>
              <uri>materials/textures/</uri>
              <name>UrbanTile/Pipes_Diffuse</name>
            </script>
          </material>
        </visual>
        <visual name='STAIRS_visual'>
          <geometry>
            <mesh>
              <scale>0.59999999999999998 0.59999999999999998 0.59999999999999998</scale>
              <uri>file://home/gino/.gz/fuel/fuel.gazebosim.org/openrobotics/models/depot/5/meshes/Depot.dae</uri>
              <submesh>
                <name>STAIRS</name>
                <center>false</center>
              </submesh>
            </mesh>
          </geometry>
          <material>
            <diffuse>1 1 1 1</diffuse>
            <specular>1 1 1 1</specular>
            <script>
              <uri>file://home/gino/.gz/fuel/fuel.gazebosim.org/openrobotics/models/depot/5/materials/scripts/</uri>
              <uri>materials/textures/</uri>
              <name>UrbanTile/STAIRS_Diffuse</name>
            </script>
          </material>
        </visual>
        <visual name='FLOOR_visual'>
          <geometry>
            <mesh>
              <scale>0.59999999999999998 0.59999999999999998 0.59999999999999998</scale>
              <uri>file://home/gino/.gz/fuel/fuel.gazebosim.org/openrobotics/models/depot/5/meshes/Depot.dae</uri>
              <submesh>
                <name>FLOOR</name>
                <center>false</center>
              </submesh>
            </mesh>
          </geometry>
          <material>
            <diffuse>1 1 1 1</diffuse>
            <specular>1 1 1 1</specular>
            <script>
              <uri>file://home/gino/.gz/fuel/fuel.gazebosim.org/openrobotics/models/depot/5/materials/scripts/</uri>
              <uri>materials/textures/</uri>
              <name>UrbanTile/FLOOR_Diffuse</name>
            </script>
          </material>
        </visual>
        <visual name='FanBack_visual'>
          <geometry>
            <mesh>
              <scale>0.59999999999999998 0.59999999999999998 0.59999999999999998</scale>
              <uri>file://home/gino/.gz/fuel/fuel.gazebosim.org/openrobotics/models/depot/5/meshes/Depot.dae</uri>
              <submesh>
                <name>FanBack</name>
                <center>false</center>
              </submesh>
            </mesh>
          </geometry>
          <material>
            <diffuse>1 1 1 1</diffuse>
            <specular>1 1 1 1</specular>
          </material>
        </visual>
        <visual name='crates'>
          <geometry>
            <mesh>
              <scale>0.59999999999999998 0.59999999999999998 0.59999999999999998</scale>
              <uri>file://home/gino/.gz/fuel/fuel.gazebosim.org/openrobotics/models/depot/5/meshes/Crates.dae</uri>
            </mesh>
          </geometry>
          <material>
            <diffuse>1 1 1 1</diffuse>
            <specular>1 1 1 1</specular>
          </material>
        </visual>
        <pose>0 0 0 0 0 0</pose>
        <inertial>
          <pose>0 0 0 0 0 0</pose>
          <mass>1</mass>
          <inertia>
            <ixx>1</ixx>
            <ixy>0</ixy>
            <ixz>0</ixz>
            <iyy>1</iyy>
            <iyz>0</iyz>
            <izz>1</izz>
          </inertia>
        </inertial>
        <enable_wind>false</enable_wind>
      </link>
      <link name='Fan1'>
        <pose>-5.0153999999999996 -0.29520000000000002 6.1200000000000001 0 0 3.1031085492408312</pose>
        <visual name='visual'>
          <pose>5.0153999999999996 0.29520000000000002 -6.1200000000000001 0 0 0</pose>
          <geometry>
            <mesh>
              <scale>0.59999999999999998 0.59999999999999998 0.59999999999999998</scale>
              <uri>file://home/gino/.gz/fuel/fuel.gazebosim.org/openrobotics/models/depot/5/meshes/Depot.dae</uri>
              <submesh>
                <name>FAN1</name>
                <center>false</center>
              </submesh>
            </mesh>
          </geometry>
          <material>
            <diffuse>1 1 1 1</diffuse>
            <specular>1 1 1 1</specular>
          </material>
        </visual>
        <inertial>
          <pose>0 0 0 0 0 0</pose>
          <mass>1</mass>
          <inertia>
            <ixx>1</ixx>
            <ixy>0</ixy>
            <ixz>0</ixz>
            <iyy>1</iyy>
            <iyz>0</iyz>
            <izz>1</izz>
          </inertia>
        </inertial>
        <enable_wind>false</enable_wind>
      </link>
      <link name='Fan2'>
        <pose>5.0153999999999996 -0.29520000000000002 6.1200000000000001 0 0 -0.076968208697923632</pose>
        <visual name='visual'>
          <pose>5.0153999999999996 0.29520000000000002 -6.1200000000000001 0 0 0</pose>
          <geometry>
            <mesh>
              <scale>0.59999999999999998 0.59999999999999998 0.59999999999999998</scale>
              <uri>file://home/gino/.gz/fuel/fuel.gazebosim.org/openrobotics/models/depot/5/meshes/Depot.dae</uri>
              <submesh>
                <name>FAN1</name>
                <center>false</center>
              </submesh>
            </mesh>
          </geometry>
          <material>
            <diffuse>1 1 1 1</diffuse>
            <specular>1 1 1 1</specular>
          </material>
        </visual>
        <inertial>
          <pose>0 0 0 0 0 0</pose>
          <mass>1</mass>
          <inertia>
            <ixx>1</ixx>
            <ixy>0</ixy>
            <ixz>0</ixz>
            <iyy>1</iyy>
            <iyz>0</iyz>
            <izz>1</izz>
          </inertia>
        </inertial>
        <enable_wind>false</enable_wind>
      </link>
      <joint name='world_joint' type='fixed'>
        <parent>world</parent>
        <child>main</child>
        <pose>0 0 0 0 0 0</pose>
      </joint>
      <joint name='fan1_joint' type='revolute'>
        <parent>main</parent>
        <child>Fan1</child>
        <axis>
          <xyz>0 0 1</xyz>
          <limit>
            <lower>-inf</lower>
            <upper>inf</upper>
            <effort>inf</effort>
            <velocity>inf</velocity>
            <stiffness>100000000</stiffness>
            <dissipation>1</dissipation>
          </limit>
          <dynamics>
            <spring_reference>0</spring_reference>
            <spring_stiffness>0</spring_stiffness>
            <damping>0</damping>
            <friction>0</friction>
          </dynamics>
        </axis>
        <pose>0 0 0 0 0 0</pose>
      </joint>
      <joint name='fan2_joint' type='revolute'>
        <parent>main</parent>
        <child>Fan2</child>
        <axis>
          <xyz>0 0 1</xyz>
          <limit>
            <lower>-inf</lower>
            <upper>inf</upper>
            <effort>inf</effort>
            <velocity>inf</velocity>
            <stiffness>100000000</stiffness>
            <dissipation>1</dissipation>
          </limit>
          <dynamics>
            <spring_reference>0</spring_reference>
            <spring_stiffness>0</spring_stiffness>
            <damping>0</damping>
            <friction>0</friction>
          </dynamics>
        </axis>
        <pose>0 0 0 0 0 0</pose>
      </joint>
      <pose>7.1900899999999996 1.09982 0 0 0 0</pose>
      <self_collide>false</self_collide>
    </model>
</sdf>