<sdf version='1.10'>
  <world name='Edifice'>
    <scene>
      <grid>false</grid>
      <ambient>0.400000006 0.400000006 0.400000006 1</ambient>
      <background>0.699999988 0.699999988 0.699999988 1</background>
      <shadows>true</shadows>
    </scene>
    <physics name='1ms' type='ignored'>
      <max_step_size>0.002</max_step_size>
      <real_time_factor>1</real_time_factor>
      <real_time_update_rate>1000</real_time_update_rate>
    </physics>
    <plugin name='ignition::gazebo::systems::Physics' filename='ignition-gazebo-physics-system'/>
    <plugin name='ignition::gazebo::systems::Sensors' filename='ignition-gazebo-sensors-system'>
      <render_engine>ogre2</render_engine>
    </plugin>
    <plugin name='ignition::gazebo::systems::UserCommands' filename='ignition-gazebo-user-commands-system'/>
    <plugin name='ignition::gazebo::systems::SceneBroadcaster' filename='ignition-gazebo-scene-broadcaster-system'/>
    <gui>
      <plugin name='3D View' filename='GzScene3D'>
        <ignition-gui>
          <title>3D View</title>
          <property type='bool' key='showTitleBar'>false</property>
          <property type='string' key='state'>docked</property>
        </ignition-gui>
        <engine>ogre2</engine>
        <scene>scene</scene>
        <ambient_light>0 0 0</ambient_light>
        <background_color>0.8 0.8 0.8</background_color>
        <sky/>
        <camera_pose>-14.14 0.06 1.34 0 0.1 0.06</camera_pose>
      </plugin>
      <plugin name='World control' filename='WorldControl'>
        <ignition-gui>
          <title>World control</title>
          <property type='bool' key='showTitleBar'>false</property>
          <property type='bool' key='resizable'>false</property>
          <property type='double' key='height'>72</property>
          <property type='double' key='width'>121</property>
          <property type='double' key='z'>1</property>
          <property type='string' key='state'>floating</property>
          <anchors target='3D View'>
            <line own='left' target='left'/>
            <line own='bottom' target='bottom'/>
          </anchors>
        </ignition-gui>
        <play_pause>true</play_pause>
        <step>true</step>
        <start_paused>true</start_paused>
      </plugin>
      <plugin name='World stats' filename='WorldStats'>
        <ignition-gui>
          <title>World stats</title>
          <property type='bool' key='showTitleBar'>false</property>
          <property type='bool' key='resizable'>false</property>
          <property type='double' key='height'>110</property>
          <property type='double' key='width'>290</property>
          <property type='double' key='z'>1</property>
          <property type='string' key='state'>floating</property>
          <anchors target='3D View'>
            <line own='right' target='right'/>
            <line own='bottom' target='bottom'/>
          </anchors>
        </ignition-gui>
        <sim_time>true</sim_time>
        <real_time>true</real_time>
        <real_time_factor>true</real_time_factor>
        <iterations>true</iterations>
      </plugin>
      <plugin name='Shapes' filename='Shapes'>
        <ignition-gui>
          <property key='resizable' type='bool'>false</property>
          <property key='x' type='double'>0</property>
          <property key='y' type='double'>0</property>
          <property key='width' type='double'>250</property>
          <property key='height' type='double'>50</property>
          <property key='state' type='string'>floating</property>
          <property key='showTitleBar' type='bool'>false</property>
          <property key='cardBackground' type='string'>#666666</property>
        </ignition-gui>
      </plugin>
      <plugin name='Lights' filename='Lights'>
        <ignition-gui>
          <property key='resizable' type='bool'>false</property>
          <property key='x' type='double'>250</property>
          <property key='y' type='double'>0</property>
          <property key='width' type='double'>150</property>
          <property key='height' type='double'>50</property>
          <property key='state' type='string'>floating</property>
          <property key='showTitleBar' type='bool'>false</property>
          <property key='cardBackground' type='string'>#666666</property>
        </ignition-gui>
      </plugin>
      <plugin name='Transform control' filename='TransformControl'>
        <ignition-gui>
          <property key='resizable' type='bool'>false</property>
          <property key='x' type='double'>0</property>
          <property key='y' type='double'>50</property>
          <property key='width' type='double'>250</property>
          <property key='height' type='double'>50</property>
          <property key='state' type='string'>floating</property>
          <property key='showTitleBar' type='bool'>false</property>
          <property key='cardBackground' type='string'>#777777</property>
        </ignition-gui>
      </plugin>
      <plugin name='Screenshot' filename='Screenshot'>
        <ignition-gui>
          <property key='resizable' type='bool'>false</property>
          <property key='x' type='double'>250</property>
          <property key='y' type='double'>50</property>
          <property key='width' type='double'>50</property>
          <property key='height' type='double'>50</property>
          <property key='state' type='string'>floating</property>
          <property key='showTitleBar' type='bool'>false</property>
          <property key='cardBackground' type='string'>#777777</property>
        </ignition-gui>
      </plugin>
      <plugin name='Entity tree' filename='EntityTree'>
        <ignition-gui>
          <property type='string' key='state'>docked_collapsed</property>
        </ignition-gui>
      </plugin>
      <plugin name='Component inspector' filename='ComponentInspector'>
        <ignition-gui>
          <property type='string' key='state'>docked_collapsed</property>
        </ignition-gui>
      </plugin>
      <plugin name='ImageDisplay' filename='ImageDisplay'>
        <ignition-gui>
          <property type='string' key='state'>docked_collapsed</property>
        </ignition-gui>
      </plugin>
      <plugin name='JointPositionController' filename='JointPositionController'>
        <ignition-gui>
          <property type='string' key='state'>docked_collapsed</property>
        </ignition-gui>
        <model_name>Panda</model_name>
      </plugin>
      <plugin name='Key publisher' filename='KeyPublisher'>
        <ignition-gui>
          <anchors target='3D View'>
            <line own='right' target='right'/>
            <line own='top' target='top'/>
          </anchors>
          <property key='resizable' type='bool'>false</property>
          <property key='width' type='double'>5</property>
          <property key='height' type='double'>5</property>
          <property key='state' type='string'>floating</property>
          <property key='showTitleBar' type='bool'>false</property>
        </ignition-gui>
      </plugin>
    </gui>
    <plugin name='ignition::gazebo::systems::TriggeredPublisher' filename='libignition-gazebo-triggered-publisher-system.so'>
      <input type='ignition.msgs.Int32' topic='/keyboard/keypress'>
        <match field='data'>87</match>
      </input>
      <output type='ignition.msgs.Twist' topic='/model/Mecanum_lift/cmd_vel'>linear: {x: 1.0, y: 0.0}, angular: {z: 0.0}</output>
    </plugin>
    <plugin name='ignition::gazebo::systems::TriggeredPublisher' filename='libignition-gazebo-triggered-publisher-system.so'>
      <input type='ignition.msgs.Int32' topic='/keyboard/keypress'>
        <match field='data'>88</match>
      </input>
      <output type='ignition.msgs.Twist' topic='/model/Mecanum_lift/cmd_vel'>linear: {x: -1.0, y: 0.0}, angular: {z: 0.0}</output>
    </plugin>
    <plugin name='ignition::gazebo::systems::TriggeredPublisher' filename='libignition-gazebo-triggered-publisher-system.so'>
      <input type='ignition.msgs.Int32' topic='/keyboard/keypress'>
        <match field='data'>68</match>
      </input>
      <output type='ignition.msgs.Twist' topic='/model/Mecanum_lift/cmd_vel'>linear: {x: 0.0, y: -1.0}, angular: {z: 0.0}</output>
    </plugin>
    <plugin name='ignition::gazebo::systems::TriggeredPublisher' filename='libignition-gazebo-triggered-publisher-system.so'>
      <input type='ignition.msgs.Int32' topic='/keyboard/keypress'>
        <match field='data'>65</match>
      </input>
      <output type='ignition.msgs.Twist' topic='/model/Mecanum_lift/cmd_vel'>linear: {x: 0.0, y: 1.0}, angular: {z: 0.0}</output>
    </plugin>
    <plugin name='ignition::gazebo::systems::TriggeredPublisher' filename='libignition-gazebo-triggered-publisher-system.so'>
      <input type='ignition.msgs.Int32' topic='/keyboard/keypress'>
        <match field='data'>69</match>
      </input>
      <output type='ignition.msgs.Twist' topic='/model/Mecanum_lift/cmd_vel'>linear: {x: 0.0, y: 0.0}, angular: {z: -1.0}</output>
    </plugin>
    <plugin name='ignition::gazebo::systems::TriggeredPublisher' filename='libignition-gazebo-triggered-publisher-system.so'>
      <input type='ignition.msgs.Int32' topic='/keyboard/keypress'>
        <match field='data'>81</match>
      </input>
      <output type='ignition.msgs.Twist' topic='/model/Mecanum_lift/cmd_vel'>linear: {x: 0.0, y: 0.0}, angular: {z: 1.0}</output>
    </plugin>
    <plugin name='ignition::gazebo::systems::TriggeredPublisher' filename='libignition-gazebo-triggered-publisher-system.so'>
      <input type='ignition.msgs.Int32' topic='/keyboard/keypress'>
        <match field='data'>83</match>
      </input>
      <output type='ignition.msgs.Twist' topic='/model/Mecanum_lift/cmd_vel'>linear: {x: 0.0, y: 0.0}, angular: {z: 0.0}</output>
    </plugin>
    <gravity>0 0 -9.8000000000000007</gravity>
    <magnetic_field>5.5644999999999998e-06 2.2875799999999999e-05 -4.2388400000000002e-05</magnetic_field>
    <atmosphere type='adiabatic'/>
    <model name='Depot'>
      <static>false</static>
      <link name='main'>
        <collision name='collision'>
          <pose>0 0 0 0 0 0</pose>
          <geometry>
            <plane>
              <normal>0 0 1</normal>
              <size>100 100</size>
            </plane>
          </geometry>
          <surface>
            <friction>
              <ode/>
            </friction>
            <bounce/>
            <contact/>
          </surface>
        </collision>
        <visual name='ROOF_visual'>
          <geometry>
            <mesh>
              <scale>0.59999999999999998 0.59999999999999998 0.59999999999999998</scale>
              <uri>file:///home/gino/.gz/fuel/fuel.ignitionrobotics.org/openrobotics/models/depot/5/meshes/Depot.dae</uri>
              <submesh>
                <name>ROOF</name>
                <center>false</center>
              </submesh>
            </mesh>
          </geometry>
          <material>
            <diffuse>1 1 1 1</diffuse>
            <specular>1 1 1 1</specular>
            <pbr>
              <metal>
                <albedo_map>materials/textures/ROOF_Albedo.png</albedo_map>
                <normal_map>materials/textures/ROOF_Normal.png</normal_map>
                <metalness_map>materials/textures/ROOF_Metalness.png</metalness_map>
                <roughness_map>materials/textures/ROOF_Roughness.png</roughness_map>
                <emissive_map>materials/textures/ROOF_Emissive.png</emissive_map>
                <light_map uv_set='1'>materials/textures/DepotLightmap.png</light_map>
              </metal>
            </pbr>
            <script>
              <uri>file:///home/gino/.gz/fuel/fuel.ignitionrobotics.org/openrobotics/models/depot/5/materials/scripts/</uri>
              <uri>materials/textures/</uri>
              <name>UrbanTile/ROOF_Diffuse</name>
            </script>
          </material>
        </visual>
        <visual name='WALLS_visual'>
          <geometry>
            <mesh>
              <scale>0.59999999999999998 0.59999999999999998 0.59999999999999998</scale>
              <uri>file:///home/gino/.gz/fuel/fuel.ignitionrobotics.org/openrobotics/models/depot/5/meshes/Depot.dae</uri>
              <submesh>
                <name>WALLS</name>
                <center>false</center>
              </submesh>
            </mesh>
          </geometry>
          <material>
            <diffuse>1 1 1 1</diffuse>
            <specular>1 1 1 1</specular>
            <pbr>
              <metal>
                <albedo_map>materials/textures/WALLS_Albedo.png</albedo_map>
                <normal_map>materials/textures/WALLS_Normal.png</normal_map>
                <metalness_map>materials/textures/WALLS_Metalness.png</metalness_map>
                <roughness_map>materials/textures/WALLS_Roughness.png</roughness_map>
                <light_map uv_set='1'>materials/textures/DepotLightmap.png</light_map>
              </metal>
            </pbr>
            <script>
              <uri>file:///home/gino/.gz/fuel/fuel.ignitionrobotics.org/openrobotics/models/depot/5/materials/scripts/</uri>
              <uri>materials/textures/</uri>
              <name>UrbanTile/WALLS_Diffuse</name>
            </script>
          </material>
        </visual>
        <visual name='PILLERS_visual'>
          <geometry>
            <mesh>
              <scale>0.59999999999999998 0.59999999999999998 0.59999999999999998</scale>
              <uri>file:///home/gino/.gz/fuel/fuel.ignitionrobotics.org/openrobotics/models/depot/5/meshes/Depot.dae</uri>
              <submesh>
                <name>PILLERS</name>
                <center>false</center>
              </submesh>
            </mesh>
          </geometry>
          <material>
            <diffuse>1 1 1 1</diffuse>
            <specular>1 1 1 1</specular>
            <pbr>
              <metal>
                <albedo_map>materials/textures/PILLERS_Albedo.png</albedo_map>
                <normal_map>materials/textures/PILLERS_Normal.png</normal_map>
                <metalness_map>materials/textures/PILLERS_Metalness.png</metalness_map>
                <roughness_map>materials/textures/PILLERS_Roughness.png</roughness_map>
                <light_map uv_set='1'>materials/textures/DepotLightmap.png</light_map>
              </metal>
            </pbr>
            <script>
              <uri>file:///home/gino/.gz/fuel/fuel.ignitionrobotics.org/openrobotics/models/depot/5/materials/scripts/</uri>
              <uri>materials/textures/</uri>
              <name>UrbanTile/PILLERS_Diffuse</name>
            </script>
          </material>
        </visual>
        <visual name='FANS_visual'>
          <geometry>
            <mesh>
              <scale>0.59999999999999998 0.59999999999999998 0.59999999999999998</scale>
              <uri>file:///home/gino/.gz/fuel/fuel.ignitionrobotics.org/openrobotics/models/depot/5/meshes/Depot.dae</uri>
              <submesh>
                <name>FANS</name>
                <center>false</center>
              </submesh>
            </mesh>
          </geometry>
          <material>
            <diffuse>1 1 1 1</diffuse>
            <specular>1 1 1 1</specular>
            <pbr>
              <metal>
                <albedo_map>materials/textures/FANS_Albedo.png</albedo_map>
                <normal_map>materials/textures/FANS_Normal.png</normal_map>
                <metalness_map>materials/textures/FANS_Metalness.png</metalness_map>
                <roughness_map>materials/textures/FANS_Roughness.png</roughness_map>
                <light_map uv_set='1'>materials/textures/DepotLightmap.png</light_map>
              </metal>
            </pbr>
            <script>
              <uri>file:///home/gino/.gz/fuel/fuel.ignitionrobotics.org/openrobotics/models/depot/5/materials/scripts/</uri>
              <uri>materials/textures/</uri>
              <name>UrbanTile/FAN_Diffuse</name>
            </script>
          </material>
        </visual>
        <visual name='WINDOW_visual'>
          <geometry>
            <mesh>
              <scale>0.59999999999999998 0.59999999999999998 0.59999999999999998</scale>
              <uri>file:///home/gino/.gz/fuel/fuel.ignitionrobotics.org/openrobotics/models/depot/5/meshes/Depot.dae</uri>
              <submesh>
                <name>WINDOW</name>
                <center>false</center>
              </submesh>
            </mesh>
          </geometry>
          <material>
            <diffuse>1 1 1 1</diffuse>
            <specular>1 1 1 1</specular>
            <pbr>
              <metal>
                <albedo_map>materials/textures/Window_WINDOW_BaseColor.png</albedo_map>
                <metalness_map>materials/textures/Window_WINDOW_Metallic.png</metalness_map>
                <roughness_map>materials/textures/Window_WINDOW_Roughness.png</roughness_map>
              </metal>
            </pbr>
            <script>
              <uri>file:///home/gino/.gz/fuel/fuel.ignitionrobotics.org/openrobotics/models/depot/5/materials/scripts/</uri>
              <uri>materials/textures/</uri>
              <name>UrbanTile/WINDOW_Diffuse</name>
            </script>
          </material>
        </visual>
        <visual name='INTERCOM_visual'>
          <geometry>
            <mesh>
              <scale>0.59999999999999998 0.59999999999999998 0.59999999999999998</scale>
              <uri>file:///home/gino/.gz/fuel/fuel.ignitionrobotics.org/openrobotics/models/depot/5/meshes/Depot.dae</uri>
              <submesh>
                <name>INTERCOM</name>
                <center>false</center>
              </submesh>
            </mesh>
          </geometry>
          <material>
            <diffuse>1 1 1 1</diffuse>
            <specular>1 1 1 1</specular>
            <pbr>
              <metal>
                <albedo_map>materials/textures/INTERCOM_Albedo.png</albedo_map>
                <normal_map>materials/textures/INTERCOM_Normal.png</normal_map>
                <metalness_map>materials/textures/INTERCOM_Metalness.png</metalness_map>
                <roughness_map>materials/textures/INTERCOM_Roughness.png</roughness_map>
                <emissive_map>materials/textures/INTERCOM_Emissive.png</emissive_map>
                <light_map uv_set='1'>materials/textures/DepotLightmap.png</light_map>
              </metal>
            </pbr>
            <script>
              <uri>file:///home/gino/.gz/fuel/fuel.ignitionrobotics.org/openrobotics/models/depot/5/materials/scripts/</uri>
              <uri>materials/textures/</uri>
              <name>UrbanTile/INTERCOM_Diffuse</name>
            </script>
          </material>
        </visual>
        <visual name='FireAlarm_visual'>
          <geometry>
            <mesh>
              <scale>0.59999999999999998 0.59999999999999998 0.59999999999999998</scale>
              <uri>file:///home/gino/.gz/fuel/fuel.ignitionrobotics.org/openrobotics/models/depot/5/meshes/Depot.dae</uri>
              <submesh>
                <name>FireAlarm</name>
                <center>false</center>
              </submesh>
            </mesh>
          </geometry>
          <material>
            <diffuse>1 1 1 1</diffuse>
            <specular>1 1 1 1</specular>
            <pbr>
              <metal>
                <albedo_map>materials/textures/FireAlarm_Albedo.png</albedo_map>
                <normal_map>materials/textures/FireAlarm_Normal.png</normal_map>
                <metalness_map>materials/textures/FireAlarm_Metalness.png</metalness_map>
                <roughness_map>materials/textures/FireAlarm_Roughness.png</roughness_map>
                <light_map uv_set='1'>materials/textures/DepotLightmap.png</light_map>
              </metal>
            </pbr>
            <script>
              <uri>file:///home/gino/.gz/fuel/fuel.ignitionrobotics.org/openrobotics/models/depot/5/materials/scripts/</uri>
              <uri>materials/textures/</uri>
              <name>UrbanTile/FireAlarm_Diffuse</name>
            </script>
          </material>
        </visual>
        <visual name='FireAlarmPole_visual'>
          <geometry>
            <mesh>
              <scale>0.59999999999999998 0.59999999999999998 0.59999999999999998</scale>
              <uri>file:///home/gino/.gz/fuel/fuel.ignitionrobotics.org/openrobotics/models/depot/5/meshes/Depot.dae</uri>
              <submesh>
                <name>FireAlarmPole</name>
                <center>false</center>
              </submesh>
            </mesh>
          </geometry>
          <material>
            <diffuse>1 1 1 1</diffuse>
            <specular>1 1 1 1</specular>
            <pbr>
              <metal>
                <albedo_map>materials/textures/FireAlarmPole_Albedo.png</albedo_map>
                <normal_map>materials/textures/FireAlarmPole_Normal.png</normal_map>
                <metalness_map>materials/textures/FireAlarmPole_Metalness.png</metalness_map>
                <roughness_map>materials/textures/FireAlarmPole_Roughness.png</roughness_map>
                <light_map uv_set='1'>materials/textures/DepotLightmap.png</light_map>
              </metal>
            </pbr>
            <script>
              <uri>file:///home/gino/.gz/fuel/fuel.ignitionrobotics.org/openrobotics/models/depot/5/materials/scripts/</uri>
              <uri>materials/textures/</uri>
              <name>UrbanTile/FireAlarmPole</name>
            </script>
          </material>
        </visual>
        <visual name='Pipes_visual'>
          <geometry>
            <mesh>
              <scale>0.59999999999999998 0.59999999999999998 0.59999999999999998</scale>
              <uri>file:///home/gino/.gz/fuel/fuel.ignitionrobotics.org/openrobotics/models/depot/5/meshes/Depot.dae</uri>
              <submesh>
                <name>Pipes</name>
                <center>false</center>
              </submesh>
            </mesh>
          </geometry>
          <material>
            <diffuse>1 1 1 1</diffuse>
            <specular>1 1 1 1</specular>
            <pbr>
              <metal>
                <albedo_map>materials/textures/Pipes_Albedo.png</albedo_map>
                <normal_map>materials/textures/Pipes_Normal.png</normal_map>
                <metalness_map>materials/textures/Pipes_Metalness.png</metalness_map>
                <roughness_map>materials/textures/Pipes_Roughness.png</roughness_map>
                <light_map uv_set='1'>materials/textures/DepotLightmap.png</light_map>
              </metal>
            </pbr>
            <script>
              <uri>file:///home/gino/.gz/fuel/fuel.ignitionrobotics.org/openrobotics/models/depot/5/materials/scripts/</uri>
              <uri>materials/textures/</uri>
              <name>UrbanTile/Pipes_Diffuse</name>
            </script>
          </material>
        </visual>
        <visual name='STAIRS_visual'>
          <geometry>
            <mesh>
              <scale>0.59999999999999998 0.59999999999999998 0.59999999999999998</scale>
              <uri>file:///home/gino/.gz/fuel/fuel.ignitionrobotics.org/openrobotics/models/depot/5/meshes/Depot.dae</uri>
              <submesh>
                <name>STAIRS</name>
                <center>false</center>
              </submesh>
            </mesh>
          </geometry>
          <material>
            <diffuse>1 1 1 1</diffuse>
            <specular>1 1 1 1</specular>
            <pbr>
              <metal>
                <albedo_map>materials/textures/STAIRS_Albedo.png</albedo_map>
                <normal_map>materials/textures/STAIRS_Normal.png</normal_map>
                <metalness_map>materials/textures/STAIRS_Metalness.png</metalness_map>
                <roughness_map>materials/textures/STAIRS_Roughness.png</roughness_map>
                <light_map uv_set='1'>materials/textures/DepotLightmap.png</light_map>
              </metal>
            </pbr>
            <script>
              <uri>file:///home/gino/.gz/fuel/fuel.ignitionrobotics.org/openrobotics/models/depot/5/materials/scripts/</uri>
              <uri>materials/textures/</uri>
              <name>UrbanTile/STAIRS_Diffuse</name>
            </script>
          </material>
        </visual>
        <visual name='BOXSET_visual'>
          <geometry>
            <mesh>
              <scale>0.59999999999999998 0.59999999999999998 0.59999999999999998</scale>
              <uri>file:///home/gino/.gz/fuel/fuel.ignitionrobotics.org/openrobotics/models/depot/5/meshes/Depot.dae</uri>
              <submesh>
                <name>BOXSET</name>
                <center>false</center>
              </submesh>
            </mesh>
          </geometry>
          <material>
            <diffuse>1 1 1 1</diffuse>
            <specular>1 1 1 1</specular>
            <pbr>
              <metal>
                <albedo_map>materials/textures/BOXSET_Albedo.png</albedo_map>
                <normal_map>materials/textures/BOXSET_Normal.png</normal_map>
                <metalness_map>materials/textures/BOXSET_Metalness.png</metalness_map>
                <roughness_map>materials/textures/BOXSET_Roughness.png</roughness_map>
                <emissive_map>materials/textures/BOXSET_Emissive.png</emissive_map>
                <light_map uv_set='1'>materials/textures/DepotLightmap.png</light_map>
              </metal>
            </pbr>
            <script>
              <uri>file:///home/gino/.gz/fuel/fuel.ignitionrobotics.org/openrobotics/models/depot/5/materials/scripts/</uri>
              <uri>materials/textures/</uri>
              <name>UrbanTile/BOXSET_Diffuse</name>
            </script>
          </material>
        </visual>
        <visual name='FLOOR_visual'>
          <geometry>
            <mesh>
              <scale>0.59999999999999998 0.59999999999999998 0.59999999999999998</scale>
              <uri>file:///home/gino/.gz/fuel/fuel.ignitionrobotics.org/openrobotics/models/depot/5/meshes/Depot.dae</uri>
              <submesh>
                <name>FLOOR</name>
                <center>false</center>
              </submesh>
            </mesh>
          </geometry>
          <material>
            <diffuse>1 1 1 1</diffuse>
            <specular>1 1 1 1</specular>
            <pbr>
              <metal>
                <albedo_map>materials/textures/FLOOR_Albedo.png</albedo_map>
                <normal_map>materials/textures/FLOOR_Normal.png</normal_map>
                <metalness_map>materials/textures/FLOOR_Metalness.png</metalness_map>
                <roughness_map>materials/textures/FLOOR_Roughness.png</roughness_map>
                <light_map uv_set='1'>materials/textures/DepotLightmap.png</light_map>
              </metal>
            </pbr>
            <script>
              <uri>file:///home/gino/.gz/fuel/fuel.ignitionrobotics.org/openrobotics/models/depot/5/materials/scripts/</uri>
              <uri>materials/textures/</uri>
              <name>UrbanTile/FLOOR_Diffuse</name>
            </script>
          </material>
        </visual>
        <visual name='FanBack_visual'>
          <geometry>
            <mesh>
              <scale>0.59999999999999998 0.59999999999999998 0.59999999999999998</scale>
              <uri>file:///home/gino/.gz/fuel/fuel.ignitionrobotics.org/openrobotics/models/depot/5/meshes/Depot.dae</uri>
              <submesh>
                <name>FanBack</name>
                <center>false</center>
              </submesh>
            </mesh>
          </geometry>
          <material>
            <diffuse>1 1 1 1</diffuse>
            <specular>1 1 1 1</specular>
            <pbr>
              <metal>
                <albedo_map>materials/textures/FanBack_FanBack_BaseColor.png</albedo_map>
              </metal>
            </pbr>
          </material>
        </visual>
        <visual name='crates'>
          <geometry>
            <mesh>
              <scale>0.59999999999999998 0.59999999999999998 0.59999999999999998</scale>
              <uri>file:///home/gino/.gz/fuel/fuel.ignitionrobotics.org/openrobotics/models/depot/5/meshes/Crates.dae</uri>
            </mesh>
          </geometry>
          <material>
            <diffuse>1 1 1 1</diffuse>
            <specular>1 1 1 1</specular>
            <pbr>
              <metal>
                <albedo_map>materials/textures/Crates_Crates_BaseColor.png</albedo_map>
                <normal_map>materials/textures/Crates_Crates_Normal.png</normal_map>
                <roughness_map>materials/textures/Crates_Crates_Roughness.png</roughness_map>
              </metal>
            </pbr>
          </material>
        </visual>
        <pose>0 0 0 0 0 0</pose>
        <inertial>
          <pose>0 0 0 0 0 0</pose>
          <mass>1</mass>
          <inertia>
            <ixx>1</ixx>
            <ixy>0</ixy>
            <ixz>0</ixz>
            <iyy>1</iyy>
            <iyz>0</iyz>
            <izz>1</izz>
          </inertia>
        </inertial>
        <enable_wind>false</enable_wind>
      </link>
      <link name='Fan1'>
        <pose>-5.0153999999999996 -0.29520000000000002 6.1200000000000001 0 0 3.0170350850646872</pose>
        <visual name='visual'>
          <pose>5.0153999999999996 0.29520000000000002 -6.1200000000000001 0 0 0</pose>
          <geometry>
            <mesh>
              <scale>0.59999999999999998 0.59999999999999998 0.59999999999999998</scale>
              <uri>file:///home/gino/.gz/fuel/fuel.ignitionrobotics.org/openrobotics/models/depot/5/meshes/Depot.dae</uri>
              <submesh>
                <name>FAN1</name>
                <center>false</center>
              </submesh>
            </mesh>
          </geometry>
          <material>
            <diffuse>1 1 1 1</diffuse>
            <specular>1 1 1 1</specular>
            <pbr>
              <metal>
                <albedo_map>materials/textures/FANS_Albedo.png</albedo_map>
                <normal_map>materials/textures/FANS_Normal.png</normal_map>
                <metalness_map>materials/textures/FANS_Metalness.png</metalness_map>
                <roughness_map>materials/textures/FANS_Roughness.png</roughness_map>
                <light_map uv_set='1'>materials/textures/DepotLightmap.png</light_map>
              </metal>
            </pbr>
          </material>
        </visual>
        <light name='fan_light' type='point'>
          <pose>0 0 0 0 0 0</pose>
          <cast_shadows>false</cast_shadows>
          <intensity>1</intensity>
          <direction>0 0 -1</direction>
          <diffuse>1 1 1 1</diffuse>
          <specular>0.300000012 0.300000012 0.300000012 1</specular>
          <attenuation>
            <range>50</range>
            <linear>0</linear>
            <constant>0</constant>
            <quadratic>0</quadratic>
          </attenuation>
          <spot>
            <inner_angle>0</inner_angle>
            <outer_angle>0</outer_angle>
            <falloff>0</falloff>
          </spot>
        </light>
        <inertial>
          <pose>0 0 0 0 0 0</pose>
          <mass>1</mass>
          <inertia>
            <ixx>1</ixx>
            <ixy>0</ixy>
            <ixz>0</ixz>
            <iyy>1</iyy>
            <iyz>0</iyz>
            <izz>1</izz>
          </inertia>
        </inertial>
        <enable_wind>false</enable_wind>
      </link>
      <link name='Fan2'>
        <pose>5.0153999999999996 -0.29520000000000002 6.1200000000000001 0 0 -0.2451151370502212</pose>
        <visual name='visual'>
          <pose>5.0153999999999996 0.29520000000000002 -6.1200000000000001 0 0 0</pose>
          <geometry>
            <mesh>
              <scale>0.59999999999999998 0.59999999999999998 0.59999999999999998</scale>
              <uri>file:///home/gino/.gz/fuel/fuel.ignitionrobotics.org/openrobotics/models/depot/5/meshes/Depot.dae</uri>
              <submesh>
                <name>FAN1</name>
                <center>false</center>
              </submesh>
            </mesh>
          </geometry>
          <material>
            <diffuse>1 1 1 1</diffuse>
            <specular>1 1 1 1</specular>
            <pbr>
              <metal>
                <albedo_map>materials/textures/FANS_Albedo.png</albedo_map>
                <normal_map>materials/textures/FANS_Normal.png</normal_map>
                <metalness_map>materials/textures/FANS_Metalness.png</metalness_map>
                <roughness_map>materials/textures/FANS_Roughness.png</roughness_map>
                <light_map uv_set='1'>materials/textures/DepotLightmap.png</light_map>
              </metal>
            </pbr>
          </material>
        </visual>
        <light name='fan_light' type='point'>
          <pose>0 0 0 0 0 0</pose>
          <cast_shadows>false</cast_shadows>
          <intensity>1</intensity>
          <direction>0 0 -1</direction>
          <diffuse>1 1 1 1</diffuse>
          <specular>0.300000012 0.300000012 0.300000012 1</specular>
          <attenuation>
            <range>50</range>
            <linear>0</linear>
            <constant>0</constant>
            <quadratic>0</quadratic>
          </attenuation>
          <spot>
            <inner_angle>0</inner_angle>
            <outer_angle>0</outer_angle>
            <falloff>0</falloff>
          </spot>
        </light>
        <inertial>
          <pose>0 0 0 0 0 0</pose>
          <mass>1</mass>
          <inertia>
            <ixx>1</ixx>
            <ixy>0</ixy>
            <ixz>0</ixz>
            <iyy>1</iyy>
            <iyz>0</iyz>
            <izz>1</izz>
          </inertia>
        </inertial>
        <enable_wind>false</enable_wind>
      </link>
      <joint name='world_joint' type='fixed'>
        <parent>world</parent>
        <child>main</child>
        <pose>0 0 0 0 0 0</pose>
      </joint>
      <joint name='fan1_joint' type='revolute'>
        <parent>main</parent>
        <child>Fan1</child>
        <axis>
          <xyz>0 0 1</xyz>
          <limit>
            <lower>-inf</lower>
            <upper>inf</upper>
            <effort>inf</effort>
            <velocity>inf</velocity>
            <stiffness>100000000</stiffness>
            <dissipation>1</dissipation>
          </limit>
          <dynamics>
            <spring_reference>0</spring_reference>
            <spring_stiffness>0</spring_stiffness>
            <damping>0</damping>
            <friction>0</friction>
          </dynamics>
        </axis>
        <pose>0 0 0 0 0 0</pose>
      </joint>
      <joint name='fan2_joint' type='revolute'>
        <parent>main</parent>
        <child>Fan2</child>
        <axis>
          <xyz>0 0 1</xyz>
          <limit>
            <lower>-inf</lower>
            <upper>inf</upper>
            <effort>inf</effort>
            <velocity>inf</velocity>
            <stiffness>100000000</stiffness>
            <dissipation>1</dissipation>
          </limit>
          <dynamics>
            <spring_reference>0</spring_reference>
            <spring_stiffness>0</spring_stiffness>
            <damping>0</damping>
            <friction>0</friction>
          </dynamics>
        </axis>
        <pose>0 0 0 0 0 0</pose>
      </joint>
      <plugin name='ignition::gazebo::systems::JointController' filename='ignition-gazebo-joint-controller-system'>
        <joint_name>fan1_joint</joint_name>
        <initial_velocity>1.0</initial_velocity>
      </plugin>
      <plugin name='ignition::gazebo::systems::JointController' filename='ignition-gazebo-joint-controller-system'>
        <joint_name>fan2_joint</joint_name>
        <initial_velocity>2.0</initial_velocity>
      </plugin>
      <pose>0 0 0 0 0 0</pose>
      <self_collide>false</self_collide>
    </model>
    <model name='Mecanum lift' xmlns:ignition='https://ignitionrobotics.org/schema'>
      <link name='chassis'>
        <inertial>
          <mass>1.14395</mass>
          <inertia>
            <ixx>0.126164</ixx>
            <ixy>0</ixy>
            <ixz>0</ixz>
            <iyy>0.41651899999999997</iyy>
            <iyz>0</iyz>
            <izz>0.481014</izz>
          </inertia>
          <pose>0 0 0 0 0 0</pose>
        </inertial>
        <collision name='scissor'>
          <pose>-0.029999999999999999 -0.13200000000000001 0.70799999999999996 0 0 0</pose>
          <geometry>
            <box>
              <size>2.04 0.93600000000000005 0.59999999999999998</size>
            </box>
          </geometry>
          <surface>
            <friction>
              <ode/>
            </friction>
            <bounce/>
            <contact/>
          </surface>
        </collision>
        <collision name='bar_1'>
          <pose>-0.042000000000000003 0.29399999999999998 1.98 0 1.5700000000001271 0</pose>
          <geometry>
            <cylinder>
              <radius>0.029999999999999999</radius>
              <length>1.8</length>
            </cylinder>
          </geometry>
          <surface>
            <friction>
              <ode/>
            </friction>
            <bounce/>
            <contact/>
          </surface>
        </collision>
        <collision name='bar_2'>
          <pose>-0.042000000000000003 0.29399999999999998 1.5780000000000001 0 1.5700000000001271 0</pose>
          <geometry>
            <cylinder>
              <radius>0.029999999999999999</radius>
              <length>1.8</length>
            </cylinder>
          </geometry>
          <surface>
            <friction>
              <ode/>
            </friction>
            <bounce/>
            <contact/>
          </surface>
        </collision>
        <collision name='bar_3'>
          <pose>-0.042000000000000003 -0.55800000000000005 1.5780000000000001 0 1.5700000000001271 0</pose>
          <geometry>
            <cylinder>
              <radius>0.029999999999999999</radius>
              <length>1.8</length>
            </cylinder>
          </geometry>
          <surface>
            <friction>
              <ode/>
            </friction>
            <bounce/>
            <contact/>
          </surface>
        </collision>
        <collision name='bar_4'>
          <pose>-0.042000000000000003 -0.55800000000000005 1.98 0 1.5700000000001271 0</pose>
          <geometry>
            <cylinder>
              <radius>0.029999999999999999</radius>
              <length>1.8</length>
            </cylinder>
          </geometry>
          <surface>
            <friction>
              <ode/>
            </friction>
            <bounce/>
            <contact/>
          </surface>
        </collision>
        <visual name='visual'>
          <pose>0 0 -0.084000000000000005 1.5700000000000001 0 0</pose>
          <geometry>
            <mesh>
              <scale>0.59999999999999998 0.59999999999999998 0.59999999999999998</scale>
              <uri>file:///home/gino/.gz/fuel/fuel.ignitionrobotics.org/openrobotics/models/mecanum lift/4/meshes/MecanumLift.dae</uri>
            </mesh>
          </geometry>
          <material>
            <diffuse>1 1 1 1</diffuse>
            <specular>1 1 1 1</specular>
            <pbr>
              <metal>
                <albedo_map>materials/textures/Forklift_Forklift_BaseColor.png</albedo_map>
                <normal_map>materials/textures/Forklift_Forklift_Normal.png</normal_map>
                <metalness_map>materials/textures/Forklift_Forklift_Metallic.png</metalness_map>
                <roughness_map>materials/textures/Forklift_Forklift_Roughness.png</roughness_map>
                <environment_map>https://fuel.ignitionrobotics.org/1.0/openrobotics/models/Reflective table/1/files/materials/textures/DepotEnvMap.dds</environment_map>
              </metal>
            </pbr>
            <script>
              <uri>file:///home/gino/.gz/fuel/fuel.ignitionrobotics.org/openrobotics/models/mecanum lift/4/materials/scripts/</uri>
              <uri>materials/textures/</uri>
              <name>UrbanTile/Forklift_Diffuse</name>
            </script>
          </material>
        </visual>
        <pose>0 0 0 0 0 0</pose>
        <enable_wind>false</enable_wind>
      </link>
      <link name='front_right_wheel'>
        <pose>0.85800000000000232 -0.55200000000000093 0.186 -2.8434333556510326e-25 1.4181641955885425e-18 -2.0162276887632384e-43</pose>
        <inertial>
          <mass>2</mass>
          <inertia>
            <ixx>0.14583299999999999</ixx>
            <ixy>0</ixy>
            <ixz>0</ixz>
            <iyy>0.14583299999999999</iyy>
            <iyz>0</iyz>
            <izz>0.125</izz>
          </inertia>
          <pose>0 0 0 0 0 0</pose>
        </inertial>
        <collision name='collision'>
          <geometry>
            <sphere>
              <radius>0.17999999999999999</radius>
            </sphere>
          </geometry>
          <surface>
            <friction>
              <ode>
                <mu>1</mu>
                <mu2>0</mu2>
                <fdir1 ignition:expressed_in='chassis'>1 1 0</fdir1>
              </ode>
            </friction>
            <bounce/>
            <contact/>
          </surface>
        </collision>
        <visual name='visual'>
          <geometry>
            <mesh>
              <uri>file:///home/gino/.gz/fuel/fuel.ignitionrobotics.org/openrobotics/models/mecanum lift/4/meshes/mecanum_wheel_right.STL</uri>
              <scale>0.0035999999999999999 0.0035999999999999999 0.0035999999999999999</scale>
            </mesh>
          </geometry>
          <material>
            <ambient>0 0 0 1</ambient>
            <diffuse>0 0 0 1</diffuse>
            <specular>1 1 1 1</specular>
          </material>
        </visual>
        <enable_wind>false</enable_wind>
      </link>
      <link name='rear_right_wheel'>
        <pose>-0.92999999999999972 -0.55200000000000093 0.18600000000000005 -1.4217166778255163e-25 1.1065675335865015e-18 -7.8661275882008817e-44</pose>
        <inertial>
          <mass>2</mass>
          <inertia>
            <ixx>0.14583299999999999</ixx>
            <ixy>0</ixy>
            <ixz>0</ixz>
            <iyy>0.14583299999999999</iyy>
            <iyz>0</iyz>
            <izz>0.125</izz>
          </inertia>
          <pose>0 0 0 0 0 0</pose>
        </inertial>
        <collision name='collision'>
          <geometry>
            <sphere>
              <radius>0.17999999999999999</radius>
            </sphere>
          </geometry>
          <surface>
            <friction>
              <ode>
                <mu>1</mu>
                <mu2>0</mu2>
                <fdir1 ignition:expressed_in='chassis'>1 -1 0</fdir1>
              </ode>
            </friction>
            <bounce/>
            <contact/>
          </surface>
        </collision>
        <visual name='visual'>
          <geometry>
            <mesh>
              <uri>file:///home/gino/.gz/fuel/fuel.ignitionrobotics.org/openrobotics/models/mecanum lift/4/meshes/mecanum_wheel_left.STL</uri>
              <scale>0.0035999999999999999 0.0035999999999999999 0.0035999999999999999</scale>
            </mesh>
          </geometry>
          <material>
            <ambient>0 0 0 1</ambient>
            <diffuse>0 0 0 1</diffuse>
            <specular>1 1 1 1</specular>
          </material>
        </visual>
        <enable_wind>false</enable_wind>
      </link>
      <link name='front_left_wheel'>
        <pose>0.85800000000000054 0.28199999999999914 0.18600000000000003 -7.7548182426846345e-26 1.2153069391539208e-18 -4.7122422111060251e-44</pose>
        <inertial>
          <mass>2</mass>
          <inertia>
            <ixx>0.14583299999999999</ixx>
            <ixy>0</ixy>
            <ixz>0</ixz>
            <iyy>0.14583299999999999</iyy>
            <iyz>0</iyz>
            <izz>0.125</izz>
          </inertia>
          <pose>0 0 0 0 0 0</pose>
        </inertial>
        <collision name='collision'>
          <geometry>
            <sphere>
              <radius>0.17999999999999999</radius>
            </sphere>
          </geometry>
          <surface>
            <friction>
              <ode>
                <mu>1</mu>
                <mu2>0</mu2>
                <fdir1 ignition:expressed_in='chassis'>1 -1 0</fdir1>
              </ode>
            </friction>
            <bounce/>
            <contact/>
          </surface>
        </collision>
        <visual name='visual'>
          <geometry>
            <mesh>
              <uri>file:///home/gino/.gz/fuel/fuel.ignitionrobotics.org/openrobotics/models/mecanum lift/4/meshes/mecanum_wheel_left.STL</uri>
              <scale>0.0035999999999999999 0.0035999999999999999 0.0035999999999999999</scale>
            </mesh>
          </geometry>
          <material>
            <ambient>0 0 0 1</ambient>
            <diffuse>0 0 0 1</diffuse>
            <specular>1 1 1 1</specular>
          </material>
        </visual>
        <enable_wind>false</enable_wind>
      </link>
      <link name='rear_left_wheel'>
        <pose>-0.92999999999999972 0.28200000000000003 0.186 0 1.482104067866761e-18 0</pose>
        <inertial>
          <mass>2</mass>
          <inertia>
            <ixx>0.14583299999999999</ixx>
            <ixy>0</ixy>
            <ixz>0</ixz>
            <iyy>0.14583299999999999</iyy>
            <iyz>0</iyz>
            <izz>0.125</izz>
          </inertia>
          <pose>0 0 0 0 0 0</pose>
        </inertial>
        <collision name='collision'>
          <geometry>
            <sphere>
              <radius>0.17999999999999999</radius>
            </sphere>
          </geometry>
          <surface>
            <friction>
              <ode>
                <mu>1</mu>
                <mu2>0</mu2>
                <fdir1 ignition:expressed_in='chassis'>1 1 0</fdir1>
              </ode>
            </friction>
            <bounce/>
            <contact/>
          </surface>
        </collision>
        <visual name='visual'>
          <geometry>
            <mesh>
              <uri>file:///home/gino/.gz/fuel/fuel.ignitionrobotics.org/openrobotics/models/mecanum lift/4/meshes/mecanum_wheel_right.STL</uri>
              <scale>0.0035999999999999999 0.0035999999999999999 0.0035999999999999999</scale>
            </mesh>
          </geometry>
          <material>
            <ambient>0 0 0 1</ambient>
            <diffuse>0 0 0 1</diffuse>
            <specular>1 1 1 1</specular>
          </material>
        </visual>
        <enable_wind>false</enable_wind>
      </link>
      <joint name='front_left_wheel_joint' type='revolute'>
        <parent>chassis</parent>
        <child>front_left_wheel</child>
        <axis>
          <xyz>0 1 0</xyz>
          <limit>
            <lower>-1.7976900000000001e+308</lower>
            <upper>1.7976900000000001e+308</upper>
            <effort>inf</effort>
            <velocity>inf</velocity>
            <stiffness>100000000</stiffness>
            <dissipation>1</dissipation>
          </limit>
          <dynamics>
            <spring_reference>0</spring_reference>
            <spring_stiffness>0</spring_stiffness>
            <damping>0</damping>
            <friction>0</friction>
          </dynamics>
        </axis>
        <pose>0 0 0 0 0 0</pose>
      </joint>
      <joint name='front_right_wheel_joint' type='revolute'>
        <parent>chassis</parent>
        <child>front_right_wheel</child>
        <axis>
          <xyz>0 1 0</xyz>
          <limit>
            <lower>-1.7976900000000001e+308</lower>
            <upper>1.7976900000000001e+308</upper>
            <effort>inf</effort>
            <velocity>inf</velocity>
            <stiffness>100000000</stiffness>
            <dissipation>1</dissipation>
          </limit>
          <dynamics>
            <spring_reference>0</spring_reference>
            <spring_stiffness>0</spring_stiffness>
            <damping>0</damping>
            <friction>0</friction>
          </dynamics>
        </axis>
        <pose>0 0 0 0 0 0</pose>
      </joint>
      <joint name='rear_left_wheel_joint' type='revolute'>
        <parent>chassis</parent>
        <child>rear_left_wheel</child>
        <axis>
          <xyz>0 1 0</xyz>
          <limit>
            <lower>-1.7976900000000001e+308</lower>
            <upper>1.7976900000000001e+308</upper>
            <effort>inf</effort>
            <velocity>inf</velocity>
            <stiffness>100000000</stiffness>
            <dissipation>1</dissipation>
          </limit>
          <dynamics>
            <spring_reference>0</spring_reference>
            <spring_stiffness>0</spring_stiffness>
            <damping>0</damping>
            <friction>0</friction>
          </dynamics>
        </axis>
        <pose>0 0 0 0 0 0</pose>
      </joint>
      <joint name='rear_right_wheel_joint' type='revolute'>
        <parent>chassis</parent>
        <child>rear_right_wheel</child>
        <axis>
          <xyz>0 1 0</xyz>
          <limit>
            <lower>-1.7976900000000001e+308</lower>
            <upper>1.7976900000000001e+308</upper>
            <effort>inf</effort>
            <velocity>inf</velocity>
            <stiffness>100000000</stiffness>
            <dissipation>1</dissipation>
          </limit>
          <dynamics>
            <spring_reference>0</spring_reference>
            <spring_stiffness>0</spring_stiffness>
            <damping>0</damping>
            <friction>0</friction>
          </dynamics>
        </axis>
        <pose>0 0 0 0 0 0</pose>
      </joint>
      <plugin name='ignition::gazebo::systems::MecanumDrive' filename='ignition-gazebo-mecanum-drive-system'>
        <front_left_joint>front_left_wheel_joint</front_left_joint>
        <back_left_joint>rear_left_wheel_joint</back_left_joint>
        <front_right_joint>front_right_wheel_joint</front_right_joint>
        <back_right_joint>rear_right_wheel_joint</back_right_joint>
        <wheel_separation>0.834</wheel_separation>
        <wheelbase>1.788</wheelbase>
        <wheel_radius>0.18</wheel_radius>
      </plugin>
      <pose>-9.4000000000046011 1.5999999999921966 -0.0060007961756720959 -1.2742879849276283e-09 3.6657476104848732e-11 -0.49999999999999972</pose>
      <static>false</static>
      <self_collide>false</self_collide>
    </model>
    <model name='fog_generator'>
      <pose>-13.199999999999999 -6 0.14999999999999999 0 0 0</pose>
      <static>true</static>
      <link name='link'>
        <pose>0 0 0 0 0 0</pose>
        <inertial>
          <pose>0 0 0 0 0 0</pose>
          <mass>1</mass>
          <inertia>
            <ixx>1</ixx>
            <ixy>0</ixy>
            <ixz>0</ixz>
            <iyy>1</iyy>
            <iyz>0</iyz>
            <izz>1</izz>
          </inertia>
        </inertial>
        <enable_wind>false</enable_wind>
      </link>
      <plugin name='ignition::gazebo::systems::ParticleEmitter' filename='ignition-gazebo-particle-emitter-system'>
        <emitter_name>fog_generator</emitter_name>
        <allow_renaming>true</allow_renaming>
        <emitting>false</emitting>
        <type>box</type>
        <size>10 10 0</size>
        <particle_size>1 1 1</particle_size>
        <lifetime>25</lifetime>
        <min_velocity>0.1</min_velocity>
        <max_velocity>0.2</max_velocity>
        <scale_rate>0.5</scale_rate>
        <rate>5</rate>
        <material>
          <diffuse>0.7 0.7 0.7</diffuse>
          <specular>1.0 1.0 1.0</specular>
          <pbr>
            <metal>
              <albedo_map>materials/textures/fog.png</albedo_map>
            </metal>
          </pbr>
        </material>
        <color_range_image>materials/textures/fogcolors.png</color_range_image>
      </plugin>
      <self_collide>false</self_collide>
    </model>
    <model name='Panda'>
      <joint name='panda_joint_world' type='fixed'>
        <parent>world</parent>
        <child>panda_link0</child>
        <pose>0 0 0 0 0 0</pose>
      </joint>
      <link name='panda_link0'>
        <visual name='panda_link0_visual'>
          <geometry>
            <mesh>
              <uri>file:///home/gino/.gz/fuel/fuel.ignitionrobotics.org/openrobotics/models/panda with ignition position controller model/4/meshes/visual/link0.dae</uri>
            </mesh>
          </geometry>
          <material>
            <diffuse>1 1 1 1</diffuse>
            <specular>1 1 1 1</specular>
            <pbr>
              <metal>
                <albedo_map>materials/textures/link0_link0_BaseColor.png</albedo_map>
                <normal_map>materials/textures/link0_link0_Normal.png</normal_map>
                <metalness_map>materials/textures/link0_link0_Metallic.png</metalness_map>
                <roughness_map>materials/textures/link0_link0_Roughness.png</roughness_map>
                <environment_map>https://fuel.ignitionrobotics.org/1.0/openrobotics/models/Reflective table/1/files/materials/textures/DepotEnvMap.dds</environment_map>
              </metal>
            </pbr>
          </material>
        </visual>
        <collision name='panda_link0_collision'>
          <geometry>
            <mesh>
              <uri>file:///home/gino/.gz/fuel/fuel.ignitionrobotics.org/openrobotics/models/panda with ignition position controller model/4/meshes/collision/link0.stl</uri>
            </mesh>
          </geometry>
          <surface>
            <friction>
              <ode>
                <mu>1.05</mu>
                <mu2>1.05</mu2>
              </ode>
            </friction>
          </surface>
        </collision>
        <inertial>
          <pose>-0.025565999999999998 -2.87883e-05 0.057332000000000001 0 0 0</pose>
          <mass>2.8142713001040618</mass>
          <inertia>
            <ixx>0.0075390636364814695</ixx>
            <iyy>0.010508017427382959</iyy>
            <izz>0.0098649336387082748</izz>
            <ixy>-1.5053124574783335e-05</ixy>
            <ixz>-0.0012144328835738973</ixz>
            <iyz>1.0434803501032979e-05</iyz>
          </inertia>
        </inertial>
        <pose>0 0 0 0 0 0</pose>
        <enable_wind>false</enable_wind>
      </link>
      <link name='panda_link1'>
        <pose>0 0 0.33299999999999996 0 0 -1.4953091933070372e-15</pose>
        <visual name='panda_link1_visual'>
          <geometry>
            <mesh>
              <uri>file:///home/gino/.gz/fuel/fuel.ignitionrobotics.org/openrobotics/models/panda with ignition position controller model/4/meshes/visual/link1.dae</uri>
            </mesh>
          </geometry>
          <material>
            <diffuse>1 1 1 1</diffuse>
            <specular>1 1 1 1</specular>
            <pbr>
              <metal>
                <albedo_map>materials/textures/link1_link1_BaseColor.png</albedo_map>
                <normal_map>materials/textures/link1_link1_Normal.png</normal_map>
                <roughness_map>materials/textures/link1_link1_Roughness.png</roughness_map>
                <environment_map>https://fuel.ignitionrobotics.org/1.0/openrobotics/models/Reflective table/1/files/materials/textures/DepotEnvMap.dds</environment_map>
                <metalness>0.1</metalness>
              </metal>
            </pbr>
          </material>
        </visual>
        <collision name='panda_link1_collision'>
          <geometry>
            <mesh>
              <uri>file:///home/gino/.gz/fuel/fuel.ignitionrobotics.org/openrobotics/models/panda with ignition position controller model/4/meshes/collision/link1.stl</uri>
            </mesh>
          </geometry>
          <surface>
            <friction>
              <ode>
                <mu>1.05</mu>
                <mu2>1.05</mu2>
              </ode>
            </friction>
          </surface>
        </collision>
        <inertial>
          <pose>-3.72212e-09 -0.032495799999999998 -0.067581799999999997 0 0 0</pose>
          <mass>2.6433170427227215</mass>
          <inertia>
            <ixx>0.017405076982879724</ixx>
            <iyy>0.015352077935781732</iyy>
            <izz>0.0059878916630738566</izz>
            <ixy>-8.6879863696210777e-09</ixy>
            <ixz>-1.6277819062920423e-08</ixz>
            <iyz>0.0045108559591022449</iyz>
          </inertia>
        </inertial>
        <enable_wind>false</enable_wind>
      </link>
      <link name='panda_link2'>
        <pose>0 0 0.33299999999999996 -1.570796326794897 0.00019243601709332555 -1.858873332762323e-13</pose>
        <visual name='panda_link2_visual'>
          <geometry>
            <mesh>
              <uri>file:///home/gino/.gz/fuel/fuel.ignitionrobotics.org/openrobotics/models/panda with ignition position controller model/4/meshes/visual/link2.dae</uri>
            </mesh>
          </geometry>
          <material>
            <diffuse>1 1 1 1</diffuse>
            <specular>1 1 1 1</specular>
            <pbr>
              <metal>
                <albedo_map>materials/textures/link2_link2_BaseColor.png</albedo_map>
                <normal_map>materials/textures/link2_link2_Normal.png</normal_map>
                <roughness_map>materials/textures/link2_link2_Roughness.png</roughness_map>
                <environment_map>https://fuel.ignitionrobotics.org/1.0/openrobotics/models/Reflective table/1/files/materials/textures/DepotEnvMap.dds</environment_map>
                <metalness>0.1</metalness>
              </metal>
            </pbr>
          </material>
        </visual>
        <collision name='panda_link2_collision'>
          <geometry>
            <mesh>
              <uri>file:///home/gino/.gz/fuel/fuel.ignitionrobotics.org/openrobotics/models/panda with ignition position controller model/4/meshes/collision/link2.stl</uri>
            </mesh>
          </geometry>
          <surface>
            <friction>
              <ode>
                <mu>1.05</mu>
                <mu2>1.05</mu2>
              </ode>
            </friction>
          </surface>
        </collision>
        <inertial>
          <pose>3.1783300000000001e-07 -0.068610000000000004 0.0322285 0 0 0</pose>
          <mass>2.6652755331661186</mass>
          <inertia>
            <ixx>0.017786940056353829</ixx>
            <iyy>0.0060441338679528443</iyy>
            <izz>0.015710955004556951</izz>
            <ixy>8.7063562587911901e-08</ixy>
            <ixz>3.7520720583940079e-08</ixz>
            <iyz>-0.0045994902954903756</iyz>
          </inertia>
        </inertial>
        <enable_wind>false</enable_wind>
      </link>
      <link name='panda_link3'>
        <pose>6.0809781025739085e-05 4.4408920985006262e-16 0.64899999414900389 5.2593902890463574e-17 0.00019243601709332557 8.7418658549982574e-14</pose>
        <visual name='panda_link3_visual'>
          <geometry>
            <mesh>
              <uri>file:///home/gino/.gz/fuel/fuel.ignitionrobotics.org/openrobotics/models/panda with ignition position controller model/4/meshes/visual/link3.dae</uri>
            </mesh>
          </geometry>
          <material>
            <diffuse>1 1 1 1</diffuse>
            <specular>1 1 1 1</specular>
            <pbr>
              <metal>
                <albedo_map>materials/textures/link3_link3_BaseColor.png</albedo_map>
                <normal_map>materials/textures/link3_link3_Normal.png</normal_map>
                <roughness_map>materials/textures/link3_link3_Roughness.png</roughness_map>
                <environment_map>https://fuel.ignitionrobotics.org/1.0/openrobotics/models/Reflective table/1/files/materials/textures/DepotEnvMap.dds</environment_map>
                <metalness>0.1</metalness>
              </metal>
            </pbr>
          </material>
        </visual>
        <collision name='panda_link3_collision'>
          <geometry>
            <mesh>
              <uri>file:///home/gino/.gz/fuel/fuel.ignitionrobotics.org/openrobotics/models/panda with ignition position controller model/4/meshes/collision/link3.stl</uri>
            </mesh>
          </geometry>
          <surface>
            <friction>
              <ode>
                <mu>1.05</mu>
                <mu2>1.05</mu2>
              </ode>
            </friction>
          </surface>
        </collision>
        <inertial>
          <pose>0.046989299999999998 0.031637400000000003 -0.031704000000000003 0 0 0</pose>
          <mass>2.3293714829045733</mass>
          <inertia>
            <ixx>0.0075496764161139766</ixx>
            <iyy>0.0096806760801913978</iyy>
            <izz>0.0079445574220080861</izz>
            <ixy>-0.0024320464513492225</ixy>
            <ixz>-0.003250815048103007</ixz>
            <iyz>-0.0021316282421730694</iyz>
          </inertia>
        </inertial>
        <enable_wind>false</enable_wind>
      </link>
      <link name='panda_link4'>
        <pose>0.082560808253470341 7.3274719625260332e-15 0.64898411817769164 1.5707963267948974 0.00024809045689480982 8.7418735966790996e-14</pose>
        <visual name='panda_link4_visual'>
          <geometry>
            <mesh>
              <uri>file:///home/gino/.gz/fuel/fuel.ignitionrobotics.org/openrobotics/models/panda with ignition position controller model/4/meshes/visual/link4.dae</uri>
            </mesh>
          </geometry>
          <material>
            <diffuse>1 1 1 1</diffuse>
            <specular>1 1 1 1</specular>
            <pbr>
              <metal>
                <albedo_map>materials/textures/link4_link4_BaseColor.png</albedo_map>
                <normal_map>materials/textures/link4_link4_Normal.png</normal_map>
                <roughness_map>materials/textures/link4_link4_Roughness.png</roughness_map>
                <environment_map>https://fuel.ignitionrobotics.org/1.0/openrobotics/models/Reflective table/1/files/materials/textures/DepotEnvMap.dds</environment_map>
                <metalness>0.1</metalness>
              </metal>
            </pbr>
          </material>
        </visual>
        <collision name='panda_link4_collision'>
          <geometry>
            <mesh>
              <uri>file:///home/gino/.gz/fuel/fuel.ignitionrobotics.org/openrobotics/models/panda with ignition position controller model/4/meshes/collision/link4.stl</uri>
            </mesh>
          </geometry>
          <surface>
            <friction>
              <ode>
                <mu>1.05</mu>
                <mu2>1.05</mu2>
              </ode>
            </friction>
          </surface>
        </collision>
        <inertial>
          <pose>-0.036050499999999999 0.033706899999999998 0.031901899999999997 0 0 0</pose>
          <mass>2.3104763646281508</mass>
          <inertia>
            <ixx>0.0077645688148648279</ixx>
            <iyy>0.0080157769299801489</iyy>
            <izz>0.0099558823080710662</izz>
            <ixy>0.0033714752040459352</ixy>
            <ixz>-0.0023436211131682479</ixz>
            <iyz>0.0022917526161470624</iyz>
          </inertia>
        </inertial>
        <enable_wind>false</enable_wind>
      </link>
      <link name='panda_link5'>
        <pose>0.00015732505320720236 -2.2204460492503131e-16 1.0330045735435218 8.5306391875076306e-17 0.00024987262577813905 2.009883720977066e-13</pose>
        <visual name='panda_link5_visual'>
          <geometry>
            <mesh>
              <uri>file:///home/gino/.gz/fuel/fuel.ignitionrobotics.org/openrobotics/models/panda with ignition position controller model/4/meshes/visual/link5.dae</uri>
            </mesh>
          </geometry>
          <material>
            <diffuse>1 1 1 1</diffuse>
            <specular>1 1 1 1</specular>
            <pbr>
              <metal>
                <albedo_map>materials/textures/link5_link5_BaseColor.png</albedo_map>
                <normal_map>materials/textures/link5_link5_Normal.png</normal_map>
                <roughness_map>materials/textures/link5_link5_Roughness.png</roughness_map>
                <environment_map>https://fuel.ignitionrobotics.org/1.0/openrobotics/models/Reflective table/1/files/materials/textures/DepotEnvMap.dds</environment_map>
                <metalness>0.1</metalness>
              </metal>
            </pbr>
          </material>
        </visual>
        <collision name='panda_link5_collision'>
          <geometry>
            <mesh>
              <uri>file:///home/gino/.gz/fuel/fuel.ignitionrobotics.org/openrobotics/models/panda with ignition position controller model/4/meshes/collision/link5.stl</uri>
            </mesh>
          </geometry>
          <surface>
            <friction>
              <ode>
                <mu>1.05</mu>
                <mu2>1.05</mu2>
              </ode>
            </friction>
          </surface>
        </collision>
        <inertial>
          <pose>-6.1252500000000004e-06 0.061042699999999998 -0.104176 0 0 0</pose>
          <mass>2.6226426154892004</mass>
          <inertia>
            <ixx>0.029070538014399377</ixx>
            <iyy>0.027638529986528795</iyy>
            <izz>0.0042511112344007368</izz>
            <ixy>6.2087382687255679e-07</ixy>
            <ixz>-1.0059151925023392e-05</ixz>
            <iyz>-0.0074243064778508139</iyz>
          </inertia>
        </inertial>
        <enable_wind>false</enable_wind>
      </link>
      <link name='panda_link6'>
        <pose>0.00015732505320720236 -2.2204460492503131e-16 1.0330045735435218 1.570796326794897 0.017703165146116064 2.0099574066159201e-13</pose>
        <visual name='panda_link6_visual'>
          <geometry>
            <mesh>
              <uri>file:///home/gino/.gz/fuel/fuel.ignitionrobotics.org/openrobotics/models/panda with ignition position controller model/4/meshes/visual/link6.dae</uri>
            </mesh>
          </geometry>
          <material>
            <diffuse>1 1 1 1</diffuse>
            <specular>1 1 1 1</specular>
            <pbr>
              <metal>
                <albedo_map>materials/textures/link6_link6_BaseColor.png</albedo_map>
                <normal_map>materials/textures/link6_link6_Normal.png</normal_map>
                <roughness_map>materials/textures/link6_link6_Roughness.png</roughness_map>
                <environment_map>https://fuel.ignitionrobotics.org/1.0/openrobotics/models/Reflective table/1/files/materials/textures/DepotEnvMap.dds</environment_map>
                <metalness>0.1</metalness>
              </metal>
            </pbr>
          </material>
        </visual>
        <collision name='panda_link6_collision'>
          <geometry>
            <mesh>
              <uri>file:///home/gino/.gz/fuel/fuel.ignitionrobotics.org/openrobotics/models/panda with ignition position controller model/4/meshes/collision/link6.stl</uri>
            </mesh>
          </geometry>
          <surface>
            <friction>
              <ode>
                <mu>1.05</mu>
                <mu2>1.05</mu2>
              </ode>
            </friction>
          </surface>
        </collision>
        <inertial>
          <pose>0.051050999999999999 0.00910797 0.010634299999999999 0 0 0</pose>
          <mass>1.5025804886626795</mass>
          <inertia>
            <ixx>0.002940555801469018</ixx>
            <iyy>0.0039210520124867698</iyy>
            <izz>0.0054115603870960195</izz>
            <ixy>-0.00042391108351381507</ixy>
            <ixz>0.00061000773533871698</ixz>
            <iyz>0.00012647545430836214</iyz>
          </inertia>
        </inertial>
        <enable_wind>false</enable_wind>
      </link>
      <link name='panda_link7'>
        <pose>0.088143535722872812 1.7541523789077473e-14 1.0314467763831112 -3.1415926535897931 0.017703165146116067 1.472269931661021e-13</pose>
        <visual name='panda_link7_visual'>
          <geometry>
            <mesh>
              <uri>file:///home/gino/.gz/fuel/fuel.ignitionrobotics.org/openrobotics/models/panda with ignition position controller model/4/meshes/visual/link7.dae</uri>
            </mesh>
          </geometry>
          <material>
            <diffuse>1 1 1 1</diffuse>
            <specular>1 1 1 1</specular>
            <pbr>
              <metal>
                <albedo_map>materials/textures/link7_link7_BaseColor.png</albedo_map>
                <normal_map>materials/textures/link7_link7_Normal.png</normal_map>
                <metalness_map>materials/textures/link7_link7_Metallic.png</metalness_map>
                <roughness_map>materials/textures/link7_link7_Roughness.png</roughness_map>
                <environment_map>https://fuel.ignitionrobotics.org/1.0/openrobotics/models/Reflective table/1/files/materials/textures/DepotEnvMap.dds</environment_map>
              </metal>
            </pbr>
          </material>
        </visual>
        <collision name='panda_link7_collision'>
          <geometry>
            <mesh>
              <uri>file:///home/gino/.gz/fuel/fuel.ignitionrobotics.org/openrobotics/models/panda with ignition position controller model/4/meshes/collision/link7.stl</uri>
            </mesh>
          </geometry>
          <surface>
            <friction>
              <ode>
                <mu>1.05</mu>
                <mu2>1.05</mu2>
              </ode>
            </friction>
          </surface>
        </collision>
        <inertial>
          <pose>0.0109695 0.010796500000000001 0.065041199999999993 0 0 0</pose>
          <mass>0.52376681347882559</mass>
          <inertia>
            <ixx>0.00086214679597265351</ixx>
            <iyy>0.00086131001848010482</iyy>
            <izz>0.00069611393966182193</izz>
            <ixy>-0.00011871071570425467</ixy>
            <ixz>3.8666026045093388e-05</ixz>
            <iyz>-9.0578416494227235e-05</iyz>
          </inertia>
        </inertial>
        <enable_wind>false</enable_wind>
      </link>
      <joint name='panda_joint1' type='revolute'>
        <pose>0 0 0 0 0 0</pose>
        <parent>panda_link0</parent>
        <child>panda_link1</child>
        <axis>
          <xyz>0 0 1</xyz>
          <limit>
            <lower>-2.8972465583105871</lower>
            <upper>2.8972465583105871</upper>
            <effort>87</effort>
            <velocity>2.617993877991494</velocity>
            <stiffness>100000000</stiffness>
            <dissipation>1</dissipation>
          </limit>
          <dynamics>
            <spring_reference>0</spring_reference>
            <spring_stiffness>0</spring_stiffness>
            <damping>21.75</damping>
            <friction>3.48</friction>
          </dynamics>
        </axis>
      </joint>
      <joint name='panda_joint2' type='revolute'>
        <pose>0 0 -2.7755575615628914e-17 0 0 0</pose>
        <parent>panda_link1</parent>
        <child>panda_link2</child>
        <axis>
          <xyz>0 0 1</xyz>
          <limit>
            <lower>-1.7627825445142731</lower>
            <upper>1.7627825445142731</upper>
            <effort>87</effort>
            <velocity>2.617993877991494</velocity>
            <stiffness>100000000</stiffness>
            <dissipation>1</dissipation>
          </limit>
          <dynamics>
            <spring_reference>0</spring_reference>
            <spring_stiffness>0</spring_stiffness>
            <damping>21.75</damping>
            <friction>3.48</friction>
          </dynamics>
        </axis>
      </joint>
      <joint name='panda_joint3' type='revolute'>
        <pose>0 0 0 0 0 0</pose>
        <parent>panda_link2</parent>
        <child>panda_link3</child>
        <axis>
          <xyz>0 0 1</xyz>
          <limit>
            <lower>-2.8972465583105871</lower>
            <upper>2.8972465583105871</upper>
            <effort>87</effort>
            <velocity>2.617993877991494</velocity>
            <stiffness>100000000</stiffness>
            <dissipation>1</dissipation>
          </limit>
          <dynamics>
            <spring_reference>0</spring_reference>
            <spring_stiffness>0</spring_stiffness>
            <damping>21.75</damping>
            <friction>3.48</friction>
          </dynamics>
        </axis>
      </joint>
      <joint name='panda_joint4' type='revolute'>
        <pose>0 0 0 0 0 0</pose>
        <parent>panda_link3</parent>
        <child>panda_link4</child>
        <axis>
          <xyz>0 0 1</xyz>
          <limit>
            <lower>-3.0717794835100198</lower>
            <upper>-0.069813170079773182</upper>
            <effort>87</effort>
            <velocity>2.617993877991494</velocity>
            <stiffness>100000000</stiffness>
            <dissipation>1</dissipation>
          </limit>
          <dynamics>
            <spring_reference>0</spring_reference>
            <spring_stiffness>0</spring_stiffness>
            <damping>21.75</damping>
            <friction>3.48</friction>
          </dynamics>
        </axis>
      </joint>
      <joint name='panda_joint5' type='revolute'>
        <pose>0 0 0 0 0 0</pose>
        <parent>panda_link4</parent>
        <child>panda_link5</child>
        <axis>
          <xyz>0 0 1</xyz>
          <limit>
            <lower>-2.8972465583105871</lower>
            <upper>2.8972465583105871</upper>
            <effort>12</effort>
            <velocity>3.1415926535897931</velocity>
            <stiffness>100000000</stiffness>
            <dissipation>1</dissipation>
          </limit>
          <dynamics>
            <spring_reference>0</spring_reference>
            <spring_stiffness>0</spring_stiffness>
            <damping>3</damping>
            <friction>0.47999999999999998</friction>
          </dynamics>
        </axis>
      </joint>
      <joint name='panda_joint6' type='revolute'>
        <pose>0 -2.2204460492503131e-16 1.1102230246251565e-16 0 0 0</pose>
        <parent>panda_link5</parent>
        <child>panda_link6</child>
        <axis>
          <xyz>0 0 1</xyz>
          <limit>
            <lower>-0.017453292519943299</lower>
            <upper>3.7524578917878091</upper>
            <effort>12</effort>
            <velocity>3.1415926535897931</velocity>
            <stiffness>100000000</stiffness>
            <dissipation>1</dissipation>
          </limit>
          <dynamics>
            <spring_reference>0</spring_reference>
            <spring_stiffness>0</spring_stiffness>
            <damping>3</damping>
            <friction>0.47999999999999998</friction>
          </dynamics>
        </axis>
      </joint>
      <joint name='panda_joint7' type='revolute'>
        <pose>0 0 0 0 0 0</pose>
        <parent>panda_link6</parent>
        <child>panda_link7</child>
        <axis>
          <xyz>0 0 1</xyz>
          <limit>
            <lower>-2.8972465583105871</lower>
            <upper>2.8972465583105871</upper>
            <effort>12</effort>
            <velocity>3.1415926535897931</velocity>
            <stiffness>100000000</stiffness>
            <dissipation>1</dissipation>
          </limit>
          <dynamics>
            <spring_reference>0</spring_reference>
            <spring_stiffness>0</spring_stiffness>
            <damping>3</damping>
            <friction>0.47999999999999998</friction>
          </dynamics>
        </axis>
      </joint>
      <joint name='panda_hand_joint' type='fixed'>
        <pose>0 0 0 0 0 1.6640034719505718e-31</pose>
        <parent>panda_link7</parent>
        <child>panda_hand</child>
      </joint>
      <link name='panda_hand'>
        <pose>0.086249395993737821 1.7763568394002505e-14 0.92446354295522104 -3.1290739715833924 0.012517701174040009 0.78547651800420037</pose>
        <visual name='panda_hand_visual'>
          <pose>0 0 0 0 0 0</pose>
          <geometry>
            <mesh>
              <uri>file:///home/gino/.gz/fuel/fuel.ignitionrobotics.org/openrobotics/models/panda with ignition position controller model/4/meshes/visual/hand.dae</uri>
            </mesh>
          </geometry>
          <material>
            <diffuse>1 1 1 1</diffuse>
            <specular>1 1 1 1</specular>
            <pbr>
              <metal>
                <albedo_map>materials/textures/hand_hand_BaseColor.png</albedo_map>
                <normal_map>materials/textures/hand_hand_Normal.png</normal_map>
                <roughness_map>materials/textures/hand_hand_Roughness.png</roughness_map>
                <environment_map>https://fuel.ignitionrobotics.org/1.0/openrobotics/models/Reflective table/1/files/materials/textures/DepotEnvMap.dds</environment_map>
                <metalness>0.1</metalness>
              </metal>
            </pbr>
          </material>
        </visual>
        <collision name='panda_hand_collision'>
          <pose>0 0 0 0 0 0</pose>
          <geometry>
            <mesh>
              <uri>file:///home/gino/.gz/fuel/fuel.ignitionrobotics.org/openrobotics/models/panda with ignition position controller model/4/meshes/collision/hand.stl</uri>
            </mesh>
          </geometry>
          <surface>
            <friction>
              <ode>
                <mu>1.05</mu>
                <mu2>1.05</mu2>
              </ode>
            </friction>
          </surface>
        </collision>
        <inertial>
          <pose>-6.7623999999999998e-06 0.0015243500000000001 0.0275912 0 0 0</pose>
          <mass>0.14060765127978503</mass>
          <inertia>
            <ixx>0.00053654504143520719</ixx>
            <iyy>7.7051195478372697e-05</iyy>
            <izz>0.00049381768826949144</izz>
            <ixy>1.7911952957732454e-08</ixy>
            <ixz>-2.320071910601251e-08</ixz>
            <iyz>4.6811499453159667e-08</iyz>
          </inertia>
        </inertial>
        <enable_wind>false</enable_wind>
      </link>
      <link name='panda_leftfinger'>
        <pose>0.085208278731252918 7.3725548987990663e-06 0.86607281418037108 -3.1290738853757101 0.012517787361460871 0.78547651908327021</pose>
        <visual name='panda_leftfinger_visual'>
          <geometry>
            <mesh>
              <uri>file:///home/gino/.gz/fuel/fuel.ignitionrobotics.org/openrobotics/models/panda with ignition position controller model/4/meshes/visual/finger.dae</uri>
            </mesh>
          </geometry>
          <material>
            <diffuse>1 1 1 1</diffuse>
            <specular>1 1 1 1</specular>
            <pbr>
              <metal>
                <albedo_map>materials/textures/finger_finger_BaseColor.png</albedo_map>
                <normal_map>materials/textures/finger_finger_Normal.png</normal_map>
                <metalness_map>materials/textures/finger_finger_Metallic.png</metalness_map>
                <roughness_map>materials/textures/finger_finger_Roughness.png</roughness_map>
                <environment_map>https://fuel.ignitionrobotics.org/1.0/openrobotics/models/Reflective table/1/files/materials/textures/DepotEnvMap.dds</environment_map>
              </metal>
            </pbr>
          </material>
        </visual>
        <collision name='panda_leftfinger_collision'>
          <geometry>
            <mesh>
              <uri>file:///home/gino/.gz/fuel/fuel.ignitionrobotics.org/openrobotics/models/panda with ignition position controller model/4/meshes/collision/finger.stl</uri>
            </mesh>
          </geometry>
          <surface>
            <friction>
              <ode>
                <mu>2.1499999999999999</mu>
                <mu2>2.1499999999999999</mu2>
              </ode>
            </friction>
          </surface>
        </collision>
        <inertial>
          <pose>-6.2561000000000001e-06 0.0022778099999999999 -0.027711599999999999 0 0 0</pose>
          <mass>0.2238453537819424</mass>
          <inertia>
            <ixx>6.7480416736369505e-05</ixx>
            <iyy>6.6271892216413953e-05</iyy>
            <izz>1.550396267804825e-05</izz>
            <ixy>-4.1027443646025676e-09</ixy>
            <ixz>1.8693673970152995e-08</ixz>
            <iyz>1.1967548474390802e-05</iyz>
          </inertia>
        </inertial>
        <enable_wind>false</enable_wind>
      </link>
      <link name='panda_rightfinger'>
        <pose>0.085208278731247589 7.3725549039060922e-06 0.86607281418037108 -3.1290738853757101 0.012517787361460871 0.78547651908327021</pose>
        <visual name='panda_rightfinger_visual'>
          <pose>0 0 0 0 0 3.1415926535897931</pose>
          <geometry>
            <mesh>
              <uri>file:///home/gino/.gz/fuel/fuel.ignitionrobotics.org/openrobotics/models/panda with ignition position controller model/4/meshes/visual/finger.dae</uri>
            </mesh>
          </geometry>
          <material>
            <diffuse>1 1 1 1</diffuse>
            <specular>1 1 1 1</specular>
            <pbr>
              <metal>
                <albedo_map>materials/textures/finger_finger_BaseColor.png</albedo_map>
                <normal_map>materials/textures/finger_finger_Normal.png</normal_map>
                <roughness_map>materials/textures/finger_finger_Roughness.png</roughness_map>
                <environment_map>https://fuel.ignitionrobotics.org/1.0/openrobotics/models/Reflective table/1/files/materials/textures/DepotEnvMap.dds</environment_map>
                <metalness>0.1</metalness>
              </metal>
            </pbr>
          </material>
        </visual>
        <collision name='panda_rightfinger_collision'>
          <pose>0 0 0 0 0 3.1415926535897931</pose>
          <geometry>
            <mesh>
              <uri>file:///home/gino/.gz/fuel/fuel.ignitionrobotics.org/openrobotics/models/panda with ignition position controller model/4/meshes/collision/finger.stl</uri>
            </mesh>
          </geometry>
          <surface>
            <friction>
              <ode>
                <mu>2.1499999999999999</mu>
                <mu2>2.1499999999999999</mu2>
              </ode>
            </friction>
          </surface>
        </collision>
        <inertial>
          <pose>-6.2561000000000001e-06 0.0022778099999999999 -0.027711599999999999 0 0 3.1415926535897931</pose>
          <mass>0.2238453537819424</mass>
          <inertia>
            <ixx>6.7480416736369505e-05</ixx>
            <iyy>6.6271892216413953e-05</iyy>
            <izz>1.550396267804825e-05</izz>
            <ixy>-4.1027443646025676e-09</ixy>
            <ixz>1.8693673970152995e-08</ixz>
            <iyz>1.1967548474390802e-05</iyz>
          </inertia>
        </inertial>
        <enable_wind>false</enable_wind>
      </link>
      <joint name='panda_finger_joint1' type='prismatic'>
        <pose>6.9388939039072284e-18 6.9388939039072284e-18 -2.2204460492503131e-16 0 0 1.6640034719505718e-31</pose>
        <parent>panda_hand</parent>
        <child>panda_leftfinger</child>
        <axis>
          <xyz>-1.6640034719505718e-31 1 0</xyz>
          <limit>
            <lower>0</lower>
            <upper>0.040000000000000001</upper>
            <effort>20</effort>
            <velocity>0.20000000000000001</velocity>
            <stiffness>100000000</stiffness>
            <dissipation>1</dissipation>
          </limit>
          <dynamics>
            <spring_reference>0</spring_reference>
            <spring_stiffness>0</spring_stiffness>
            <damping>10</damping>
            <friction>0.5</friction>
          </dynamics>
        </axis>
      </joint>
      <joint name='panda_finger_joint2' type='prismatic'>
        <pose>6.9388939039072284e-18 6.9388939039072284e-18 -2.2204460492503131e-16 0 0 1.6640034719505718e-31</pose>
        <parent>panda_hand</parent>
        <child>panda_rightfinger</child>
        <axis>
          <xyz>1.6640034719505718e-31 -1 0</xyz>
          <limit>
            <lower>0</lower>
            <upper>0.040000000000000001</upper>
            <effort>20</effort>
            <velocity>0.20000000000000001</velocity>
            <stiffness>100000000</stiffness>
            <dissipation>1</dissipation>
          </limit>
          <dynamics>
            <spring_reference>0</spring_reference>
            <spring_stiffness>0</spring_stiffness>
            <damping>10</damping>
            <friction>0.5</friction>
          </dynamics>
        </axis>
      </joint>
      <link name='panda_link8'>
        <pose>0.084425194673009685 1.9984014443252818e-14 0.82147983320032081 -3.1290752319645638 0.012516441089066334 0.78547650222836951</pose>
        <inertial>
          <pose>0 0 0 0 0 0</pose>
          <mass>1</mass>
          <inertia>
            <ixx>1</ixx>
            <ixy>0</ixy>
            <ixz>0</ixz>
            <iyy>1</iyy>
            <iyz>0</iyz>
            <izz>1</izz>
          </inertia>
        </inertial>
        <enable_wind>false</enable_wind>
      </link>
      <joint name='end_effector_frame_fixed_joint' type='fixed'>
        <pose>-6.9388939039072284e-18 6.9388939039072284e-18 0 0 0 1.6640034719505718e-31</pose>
        <parent>panda_hand</parent>
        <child>panda_link8</child>
      </joint>
      <plugin name='ignition::gazebo::systems::JointPositionController' filename='ignition-gazebo-joint-position-controller-system'>
        <joint_name>panda_joint1</joint_name>
        <p_gain>50</p_gain>
        <d_gain>20</d_gain>
        <i_gain>0</i_gain>
        <i_min>-1</i_min>
        <i_max>1</i_max>
        <cmd_min>-87</cmd_min>
        <cmd_max>87</cmd_max>
      </plugin>
      <plugin name='ignition::gazebo::systems::JointPositionController' filename='ignition-gazebo-joint-position-controller-system'>
        <joint_name>panda_joint2</joint_name>
        <p_gain>10000</p_gain>
        <d_gain>500</d_gain>
        <i_gain>0</i_gain>
        <i_min>-1</i_min>
        <i_max>1</i_max>
        <cmd_min>-87</cmd_min>
        <cmd_max>87</cmd_max>
      </plugin>
      <plugin name='ignition::gazebo::systems::JointPositionController' filename='ignition-gazebo-joint-position-controller-system'>
        <joint_name>panda_joint3</joint_name>
        <p_gain>100</p_gain>
        <d_gain>10</d_gain>
        <i_gain>0</i_gain>
        <i_min>-1</i_min>
        <i_max>1</i_max>
        <cmd_min>-87</cmd_min>
        <cmd_max>87</cmd_max>
      </plugin>
      <plugin name='ignition::gazebo::systems::JointPositionController' filename='ignition-gazebo-joint-position-controller-system'>
        <joint_name>panda_joint4</joint_name>
        <p_gain>1000</p_gain>
        <d_gain>50</d_gain>
        <i_gain>0</i_gain>
        <i_min>-1</i_min>
        <i_max>1</i_max>
        <cmd_min>-87</cmd_min>
        <cmd_max>87</cmd_max>
      </plugin>
      <plugin name='ignition::gazebo::systems::JointPositionController' filename='ignition-gazebo-joint-position-controller-system'>
        <joint_name>panda_joint5</joint_name>
        <p_gain>100</p_gain>
        <d_gain>50</d_gain>
        <i_gain>0</i_gain>
        <i_min>-1</i_min>
        <i_max>1</i_max>
        <cmd_min>-12</cmd_min>
        <cmd_max>12</cmd_max>
      </plugin>
      <plugin name='ignition::gazebo::systems::JointPositionController' filename='ignition-gazebo-joint-position-controller-system'>
        <joint_name>panda_joint6</joint_name>
        <p_gain>100</p_gain>
        <d_gain>10</d_gain>
        <i_gain>0</i_gain>
        <i_min>-1</i_min>
        <i_max>1</i_max>
        <cmd_min>-12</cmd_min>
        <cmd_max>12</cmd_max>
      </plugin>
      <plugin name='ignition::gazebo::systems::JointPositionController' filename='ignition-gazebo-joint-position-controller-system'>
        <joint_name>panda_joint7</joint_name>
        <p_gain>10</p_gain>
        <d_gain>0.1</d_gain>
        <i_gain>0.5</i_gain>
        <i_min>-1</i_min>
        <i_max>1</i_max>
        <cmd_min>-12</cmd_min>
        <cmd_max>12</cmd_max>
      </plugin>
      <plugin name='ignition::gazebo::systems::JointPositionController' filename='ignition-gazebo-joint-position-controller-system'>
        <joint_name>panda_finger_joint1</joint_name>
        <p_gain>100</p_gain>
        <d_gain>50</d_gain>
        <i_gain>0</i_gain>
        <i_min>-1</i_min>
        <i_max>1</i_max>
        <cmd_min>-20</cmd_min>
        <cmd_max>20</cmd_max>
      </plugin>
      <plugin name='ignition::gazebo::systems::JointPositionController' filename='ignition-gazebo-joint-position-controller-system'>
        <joint_name>panda_finger_joint2</joint_name>
        <p_gain>100</p_gain>
        <d_gain>50</d_gain>
        <i_gain>0</i_gain>
        <i_min>-1</i_min>
        <i_max>1</i_max>
        <cmd_min>-20</cmd_min>
        <cmd_max>20</cmd_max>
      </plugin>
      <pose>-9 -1.8 1.038 0 0 0</pose>
      <static>false</static>
      <self_collide>false</self_collide>
    </model>
    <model name='Reflective table'>
      <static>true</static>
      <link name='link'>
        <pose>0 0 0 3.1415926535897931 0.0015926535897931142 3.1415926535897931</pose>
        <collision name='collision'>
          <geometry>
            <mesh>
              <scale>0.59999999999999998 0.59999999999999998 0.59999999999999998</scale>
              <uri>file:///home/gino/.gz/fuel/fuel.ignitionrobotics.org/openrobotics/models/reflective table/2/meshes/Table.dae</uri>
            </mesh>
          </geometry>
        </collision>
        <visual name='visual'>
          <geometry>
            <mesh>
              <scale>0.59999999999999998 0.59999999999999998 0.59999999999999998</scale>
              <uri>file:///home/gino/.gz/fuel/fuel.ignitionrobotics.org/openrobotics/models/reflective table/2/meshes/Table.dae</uri>
            </mesh>
          </geometry>
          <material>
            <diffuse>1 1 1 1</diffuse>
            <specular>1 1 1 1</specular>
            <pbr>
              <metal>
                <albedo_map>materials/textures/Table_Table_BaseColor.png</albedo_map>
                <normal_map>materials/textures/Table_Table_Normal.png</normal_map>
                <roughness_map>materials/textures/Table_Roughness.png</roughness_map>
                <environment_map>materials/textures/DepotEnvMap.dds</environment_map>
                <metalness>0.1</metalness>
              </metal>
            </pbr>
          </material>
        </visual>
        <inertial>
          <pose>0 0 0 0 0 0</pose>
          <mass>1</mass>
          <inertia>
            <ixx>1</ixx>
            <ixy>0</ixy>
            <ixz>0</ixz>
            <iyy>1</iyy>
            <iyz>0</iyz>
            <izz>1</izz>
          </inertia>
        </inertial>
        <enable_wind>false</enable_wind>
      </link>
      <pose>-9 -2.3999999999999999 0 -1.3426289064045658e-16 -1.3467663122749495e-16 1.5700000000000001</pose>
      <self_collide>false</self_collide>
    </model>
    <model name='rescue_randy_sitting'>
      <static>true</static>
      <model name='artifact_proximity_detector'>
        <static>true</static>
        <pose>0 0 0 0 0 0</pose>
        <plugin name='ignition::gazebo::systems::PerformerDetector' filename='libignition-gazebo-performer-detector-system.so'>
          <topic>/subt_performer_detector</topic>
          <header_data>
            <key>type</key>
            <value>artifact_proximity</value>
          </header_data>
          <geometry>
            <box>
              <size>10 10 10</size>
            </box>
          </geometry>
        </plugin>
      </model>
      <link name='link'>
        <pose>0 0 -0.623996 0 0 0</pose>
        <collision name='collision'>
          <geometry>
            <mesh>
              <uri>file:///home/gino/.gz/fuel/fuel.ignitionrobotics.org/openrobotics/models/rescue randy sitting/7/meshes/rescue_randy.dae</uri>
            </mesh>
          </geometry>
        </collision>
        <visual name='visual'>
          <geometry>
            <mesh>
              <uri>file:///home/gino/.gz/fuel/fuel.ignitionrobotics.org/openrobotics/models/rescue randy sitting/7/meshes/rescue_randy.dae</uri>
            </mesh>
          </geometry>
          <plugin name='ignition::gazebo::systems::Thermal' filename='ignition-gazebo-thermal-system'>
            <heat_signature>materials/textures/RescueRandy_Thermal.png</heat_signature>
            <max_temp>305</max_temp>
          </plugin>
        </visual>
        <inertial>
          <pose>0 0 0 0 0 0</pose>
          <mass>1</mass>
          <inertia>
            <ixx>1</ixx>
            <ixy>0</ixy>
            <ixz>0</ixz>
            <iyy>1</iyy>
            <iyz>0</iyz>
            <izz>1</izz>
          </inertia>
        </inertial>
        <enable_wind>false</enable_wind>
      </link>
      <pose>-13.199999999999999 -6 0 0 0 1.5699999999999998</pose>
      <self_collide>false</self_collide>
    </model>
    <model name='thermal_camera_16_bit'>
      <pose>-9 -6.21 5 1.5174400962174918e-16 0.90000000000000058 -3.1399999999999997</pose>
      <link name='link'>
        <collision name='collision'>
          <geometry>
            <box>
              <size>0.10000000000000001 0.10000000000000001 0.10000000000000001</size>
            </box>
          </geometry>
          <surface>
            <friction>
              <ode/>
            </friction>
            <bounce/>
            <contact/>
          </surface>
        </collision>
        <visual name='visual'>
          <geometry>
            <box>
              <size>0.10000000000000001 0.10000000000000001 0.10000000000000001</size>
            </box>
          </geometry>
        </visual>
        <sensor name='thermal_camera' type='thermal_camera'>
          <pose>0 0 0 0 0 0</pose>
          <topic>thermal_camera_16_bit</topic>
          <update_rate>30</update_rate>
          <enable_metrics>false</enable_metrics>
          <camera name='__default__'>
            <pose>0 0 0 0 0 0</pose>
            <horizontal_fov>1.0469999999999999</horizontal_fov>
            <image>
              <width>320</width>
              <height>240</height>
              <format>L_INT16</format>
              <anti_aliasing>4</anti_aliasing>
            </image>
            <camera_info_topic>__default__</camera_info_topic>
            <trigger_topic></trigger_topic>
            <triggered>false</triggered>
            <clip>
              <near>0.10000000000000001</near>
              <far>100</far>
            </clip>
            <save enabled='false'>
              <path>__default__</path>
            </save>
            <visibility_mask>4294967295</visibility_mask>
            <noise>
              <type>none</type>
              <mean>0</mean>
              <stddev>0</stddev>
            </noise>
            <distortion>
              <k1>0</k1>
              <k2>0</k2>
              <k3>0</k3>
              <p1>0</p1>
              <p2>0</p2>
              <center>0.5 0.5</center>
            </distortion>
            <lens>
              <type>stereographic</type>
              <scale_to_hfov>true</scale_to_hfov>
              <cutoff_angle>1.5707963267948966</cutoff_angle>
              <env_texture_size>256</env_texture_size>
            </lens>
            <optical_frame_id></optical_frame_id>
          </camera>
        </sensor>
        <pose>0 0 0 0 0 0</pose>
        <inertial>
          <pose>0 0 0 0 0 0</pose>
          <mass>1</mass>
          <inertia>
            <ixx>1</ixx>
            <ixy>0</ixy>
            <ixz>0</ixz>
            <iyy>1</iyy>
            <iyz>0</iyz>
            <izz>1</izz>
          </inertia>
        </inertial>
        <enable_wind>false</enable_wind>
      </link>
      <static>true</static>
      <self_collide>false</self_collide>
    </model>
    <model name='thermal_camera_8_bit'>
      <pose>-9 -5.9500000000000002 5 1.5174400962174918e-16 0.90000000000000058 -3.1399999999999997</pose>
      <link name='link'>
        <collision name='collision'>
          <geometry>
            <box>
              <size>0.10000000000000001 0.10000000000000001 0.10000000000000001</size>
            </box>
          </geometry>
          <surface>
            <friction>
              <ode/>
            </friction>
            <bounce/>
            <contact/>
          </surface>
        </collision>
        <visual name='visual'>
          <geometry>
            <box>
              <size>0.10000000000000001 0.10000000000000001 0.10000000000000001</size>
            </box>
          </geometry>
        </visual>
        <sensor name='thermal_camera' type='thermal_camera'>
          <pose>0 0 0 0 0 0</pose>
          <topic>thermal_camera_8_bit</topic>
          <update_rate>30</update_rate>
          <enable_metrics>false</enable_metrics>
          <camera name='__default__'>
            <pose>0 0 0 0 0 0</pose>
            <horizontal_fov>1.0469999999999999</horizontal_fov>
            <image>
              <width>320</width>
              <height>240</height>
              <format>L_INT8</format>
              <anti_aliasing>4</anti_aliasing>
            </image>
            <camera_info_topic>__default__</camera_info_topic>
            <trigger_topic></trigger_topic>
            <triggered>false</triggered>
            <clip>
              <near>0.10000000000000001</near>
              <far>100</far>
            </clip>
            <save enabled='false'>
              <path>__default__</path>
            </save>
            <visibility_mask>4294967295</visibility_mask>
            <noise>
              <type>none</type>
              <mean>0</mean>
              <stddev>0</stddev>
            </noise>
            <distortion>
              <k1>0</k1>
              <k2>0</k2>
              <k3>0</k3>
              <p1>0</p1>
              <p2>0</p2>
              <center>0.5 0.5</center>
            </distortion>
            <lens>
              <type>stereographic</type>
              <scale_to_hfov>true</scale_to_hfov>
              <cutoff_angle>1.5707963267948966</cutoff_angle>
              <env_texture_size>256</env_texture_size>
            </lens>
            <optical_frame_id></optical_frame_id>
          </camera>
        </sensor>
        <pose>0 0 0 0 0 0</pose>
        <inertial>
          <pose>0 0 0 0 0 0</pose>
          <mass>1</mass>
          <inertia>
            <ixx>1</ixx>
            <ixy>0</ixy>
            <ixz>0</ixz>
            <iyy>1</iyy>
            <iyz>0</iyz>
            <izz>1</izz>
          </inertia>
        </inertial>
        <enable_wind>false</enable_wind>
      </link>
      <static>true</static>
      <self_collide>false</self_collide>
    </model>
    <model name='camera'>
      <pose>-9.0749999999999993 -6.1500000000000004 4.9950000000000001 1.5174400962174918e-16 0.90000000000000058 -3.1399999999999997</pose>
      <link name='link'>
        <inertial>
          <mass>0.10000000000000001</mass>
          <inertia>
            <ixx>0.00016666700000000001</ixx>
            <iyy>0.00016666700000000001</iyy>
            <izz>0.00016666700000000001</izz>
            <ixy>0</ixy>
            <ixz>0</ixz>
            <iyz>0</iyz>
          </inertia>
          <pose>0 0 0 0 0 0</pose>
        </inertial>
        <collision name='collision'>
          <geometry>
            <box>
              <size>0.10000000000000001 0.10000000000000001 0.10000000000000001</size>
            </box>
          </geometry>
          <surface>
            <friction>
              <ode/>
            </friction>
            <bounce/>
            <contact/>
          </surface>
        </collision>
        <visual name='visual'>
          <geometry>
            <box>
              <size>0.10000000000000001 0.10000000000000001 0.10000000000000001</size>
            </box>
          </geometry>
        </visual>
        <sensor name='camera' type='camera'>
          <pose>0 0 0 0 0 0</pose>
          <topic>__default__</topic>
          <update_rate>30</update_rate>
          <enable_metrics>false</enable_metrics>
          <camera name='__default__'>
            <pose>0 0 0 0 0 0</pose>
            <horizontal_fov>1.0469999999999999</horizontal_fov>
            <image>
              <width>320</width>
              <height>240</height>
              <format>RGB_INT8</format>
              <anti_aliasing>4</anti_aliasing>
            </image>
            <camera_info_topic>__default__</camera_info_topic>
            <trigger_topic></trigger_topic>
            <triggered>false</triggered>
            <clip>
              <near>0.10000000000000001</near>
              <far>100</far>
            </clip>
            <save enabled='false'>
              <path>__default__</path>
            </save>
            <visibility_mask>4294967295</visibility_mask>
            <noise>
              <type>none</type>
              <mean>0</mean>
              <stddev>0</stddev>
            </noise>
            <distortion>
              <k1>0</k1>
              <k2>0</k2>
              <k3>0</k3>
              <p1>0</p1>
              <p2>0</p2>
              <center>0.5 0.5</center>
            </distortion>
            <lens>
              <type>stereographic</type>
              <scale_to_hfov>true</scale_to_hfov>
              <cutoff_angle>1.5707963267948966</cutoff_angle>
              <env_texture_size>256</env_texture_size>
            </lens>
            <optical_frame_id></optical_frame_id>
          </camera>
        </sensor>
        <pose>0 0 0 0 0 0</pose>
        <enable_wind>false</enable_wind>
      </link>
      <static>true</static>
      <self_collide>false</self_collide>
    </model>
    <model name='depth_camera'>
      <link name='link'>
        <pose>0 0 0.050000000000000003 0 0 0</pose>
        <inertial>
          <mass>0.10000000000000001</mass>
          <inertia>
            <ixx>0.00016666700000000001</ixx>
            <iyy>0.00016666700000000001</iyy>
            <izz>0.00016666700000000001</izz>
            <ixy>0</ixy>
            <ixz>0</ixz>
            <iyz>0</iyz>
          </inertia>
          <pose>0 0 0 0 0 0</pose>
        </inertial>
        <collision name='collision'>
          <geometry>
            <box>
              <size>0.10000000000000001 0.10000000000000001 0.10000000000000001</size>
            </box>
          </geometry>
          <surface>
            <friction>
              <ode/>
            </friction>
            <bounce/>
            <contact/>
          </surface>
        </collision>
        <visual name='visual'>
          <geometry>
            <box>
              <size>0.10000000000000001 0.10000000000000001 0.10000000000000001</size>
            </box>
          </geometry>
        </visual>
        <sensor name='camera' type='depth_camera'>
          <pose>0 0 0 0 0 0</pose>
          <topic>__default__</topic>
          <update_rate>30</update_rate>
          <enable_metrics>false</enable_metrics>
          <camera name='__default__'>
            <pose>0 0 0 0 0 0</pose>
            <horizontal_fov>1.0469999999999999</horizontal_fov>
            <image>
              <width>320</width>
              <height>240</height>
              <format>RGB_INT8</format>
              <anti_aliasing>4</anti_aliasing>
            </image>
            <camera_info_topic>__default__</camera_info_topic>
            <trigger_topic></trigger_topic>
            <triggered>false</triggered>
            <clip>
              <near>0.10000000000000001</near>
              <far>100</far>
            </clip>
            <save enabled='false'>
              <path>__default__</path>
            </save>
            <visibility_mask>4294967295</visibility_mask>
            <noise>
              <type>none</type>
              <mean>0</mean>
              <stddev>0</stddev>
            </noise>
            <distortion>
              <k1>0</k1>
              <k2>0</k2>
              <k3>0</k3>
              <p1>0</p1>
              <p2>0</p2>
              <center>0.5 0.5</center>
            </distortion>
            <lens>
              <type>stereographic</type>
              <scale_to_hfov>true</scale_to_hfov>
              <cutoff_angle>1.5707963267948966</cutoff_angle>
              <env_texture_size>256</env_texture_size>
            </lens>
            <optical_frame_id></optical_frame_id>
          </camera>
        </sensor>
        <enable_wind>false</enable_wind>
      </link>
      <pose>-9.0399999999999991 -6.04 4.9699999999999998 1.5174400962174918e-16 0.90000000000000058 -3.1399999999999997</pose>
      <static>true</static>
      <self_collide>false</self_collide>
    </model>
    <model name='uniform_temp_box'>
      <pose>-13.199999999999999 -5.2999999999999998 0.19999989516484651 3.8274668033664375e-19 1.7182739846419778e-18 -8.6102966869277933e-21</pose>
      <link name='box_link'>
        <inertial>
          <inertia>
            <ixx>1</ixx>
            <ixy>0</ixy>
            <ixz>0</ixz>
            <iyy>1</iyy>
            <iyz>0</iyz>
            <izz>1</izz>
          </inertia>
          <mass>1</mass>
          <pose>0 0 0 0 0 0</pose>
        </inertial>
        <collision name='box_collision'>
          <geometry>
            <box>
              <size>0.40000000000000002 0.40000000000000002 0.40000000000000002</size>
            </box>
          </geometry>
          <surface>
            <friction>
              <ode/>
            </friction>
            <bounce/>
            <contact/>
          </surface>
        </collision>
        <visual name='box_visual'>
          <geometry>
            <box>
              <size>0.40000000000000002 0.40000000000000002 0.40000000000000002</size>
            </box>
          </geometry>
          <material>
            <ambient>1 0 0 1</ambient>
            <diffuse>1 0 0 1</diffuse>
            <specular>1 0 0 1</specular>
          </material>
          <plugin name='ignition::gazebo::systems::Thermal' filename='ignition-gazebo-thermal-system'>
            <temperature>295.0</temperature>
          </plugin>
        </visual>
        <pose>0 0 0 0 0 0</pose>
        <enable_wind>false</enable_wind>
      </link>
      <static>false</static>
      <self_collide>false</self_collide>
    </model>
    <model name='sweepee_1'>
      <link name='sweepee_1/base_footprint'>
        <inertial>
          <pose>0 0 0.20519480519480521 0 0 0</pose>
          <mass>154</mass>
          <inertia>
            <ixx>2.161950486734955</ixx>
            <ixy>0</ixy>
            <ixz>0</ixz>
            <iyy>3.861950486734957</iyy>
            <iyz>0</iyz>
            <izz>6.0112500000000004</izz>
          </inertia>
        </inertial>
        <collision name='sweepee_1/base_footprint_fixed_joint_lump__sweepee_1/base_link_sweepee_collision'>
          <pose>0 0 0.20000000000000001 0 0 0</pose>
          <geometry>
            <box>
              <size>0.29999999999999999 0.55000000000000004 0.050000000000000003</size>
            </box>
          </geometry>
          <surface>
            <friction>
              <ode/>
            </friction>
            <bounce/>
            <contact/>
          </surface>
        </collision>
        <collision name='sweepee_1/base_footprint_fixed_joint_lump__sweepee_1/base_link_inertia_collision_1'>
          <pose>0 0 0.40000000000000002 0 0 -2.4492935982947059e-16</pose>
          <geometry>
            <mesh>
              <scale>1 1 1</scale>
              <uri>file:///home/gino/ROS/lampo_ws_ros2_rolling/install/ur_description/share/ur_description/meshes/ur10/collision/base.stl</uri>
            </mesh>
          </geometry>
        </collision>
        <visual name='sweepee_1/base_footprint_fixed_joint_lump__sweepee_1/base_link_sweepee_visual'>
          <pose>0 0 0.032000000000000001 0 0 -1.5707949999999999</pose>
          <geometry>
            <mesh>
              <scale>1 1 1</scale>
              <uri>file:///home/gino/ROS/lampo_ws_ros2_rolling/install/lampo_description/share/lampo_description//meshes/sweepee/visual/sweepee.dae</uri>
            </mesh>
          </geometry>
          <material>
            <diffuse>0.625 0.625 0.625 1</diffuse>
            <ambient>0.625 0.625 0.625 1</ambient>
          </material>
        </visual>
        <visual name='sweepee_1/base_footprint_fixed_joint_lump__sweepee_1/base_link_inertia_visual_1'>
          <pose>0 0 0.40000000000000002 0 0 -2.4492935982947059e-16</pose>
          <geometry>
            <mesh>
              <scale>1 1 1</scale>
              <uri>file:///home/gino/ROS/lampo_ws_ros2_rolling/install/ur_description/share/ur_description/meshes/ur10/visual/base.dae</uri>
            </mesh>
          </geometry>
        </visual>
        <sensor name='gpu_lidar' type='gpu_lidar'>
          <pose>0.35999999999999999 0 0.26000000000000001 0 0 0</pose>
          <topic>sweepee_1/lidar</topic>
          <update_rate>10</update_rate>
          <enable_metrics>false</enable_metrics>
          <lidar>
            <scan>
              <horizontal>
                <samples>640</samples>
                <resolution>1</resolution>
                <min_angle>-1.396263</min_angle>
                <max_angle>1.396263</max_angle>
              </horizontal>
              <vertical>
                <samples>1</samples>
                <min_angle>0</min_angle>
                <max_angle>0</max_angle>
                <resolution>0.01</resolution>
              </vertical>
            </scan>
            <range>
              <min>0.080000000000000002</min>
              <max>10</max>
              <resolution>0.01</resolution>
            </range>
            <noise>
              <type>none</type>
              <mean>0</mean>
              <stddev>0</stddev>
            </noise>
            <visibility_mask>4294967295</visibility_mask>
          </lidar>
        </sensor>
        <pose>0 0 0 0 0 0</pose>
        <enable_wind>false</enable_wind>
      </link>
      <joint name='sweepee_1/front_left_wheel_joint' type='revolute'>
        <pose>-5.5511151231257827e-17 -2.7755575615628914e-17 0 0 0 0</pose>
        <parent>sweepee_1/base_footprint</parent>
        <child>sweepee_1/front_left_wheel</child>
        <axis>
          <xyz>0 0 1</xyz>
          <limit>
            <lower>-1.7976900000000001e+308</lower>
            <upper>1.7976900000000001e+308</upper>
            <effort>10000</effort>
            <velocity>5.0999999999999996</velocity>
            <stiffness>100000000</stiffness>
            <dissipation>1</dissipation>
          </limit>
          <dynamics>
            <spring_reference>0</spring_reference>
            <spring_stiffness>0</spring_stiffness>
            <damping>0</damping>
            <friction>0</friction>
          </dynamics>
        </axis>
      </joint>
      <link name='sweepee_1/front_left_wheel'>
        <pose>0.30000056366377126 0.2499999962368058 0.10000000010777142 -1.5706888222195621 -0.46005314013152865 -4.7742861416287156e-05</pose>
        <inertial>
          <pose>0 0 0 0 0 0</pose>
          <mass>1</mass>
          <inertia>
            <ixx>0.14499999999999999</ixx>
            <ixy>0</ixy>
            <ixz>0</ixz>
            <iyy>0.14499999999999999</iyy>
            <iyz>0</iyz>
            <izz>0.125</izz>
          </inertia>
        </inertial>
        <collision name='sweepee_1/front_left_wheel_fixed_joint_lump__collision_collision'>
          <pose>0 0 0 0 0 0</pose>
          <geometry>
            <sphere>
              <radius>0.10000000000000001</radius>
            </sphere>
          </geometry>
          <surface>
            <friction>
              <ode/>
            </friction>
            <bounce/>
            <contact/>
          </surface>
        </collision>
        <visual name='sweepee_1/front_left_wheel_fixed_joint_lump__visual_visual'>
          <pose>0 0 0 0 0 0</pose>
          <geometry>
            <sphere>
              <radius>0.10000000000000001</radius>
            </sphere>
          </geometry>
        </visual>
        <pose>0.85799999999999998 -0.55200000000000005 0.186 0 0 0</pose>
        <enable_wind>false</enable_wind>
      </link>
      <joint name='sweepee_1/front_right_wheel_joint' type='revolute'>
        <pose>-5.5511151231257827e-17 1.3877787807814457e-17 0 0 0 0</pose>
        <parent>sweepee_1/base_footprint</parent>
        <child>sweepee_1/front_right_wheel</child>
        <axis>
          <xyz>0 0 1</xyz>
          <limit>
            <lower>-1.7976900000000001e+308</lower>
            <upper>1.7976900000000001e+308</upper>
            <effort>10000</effort>
            <velocity>5.0999999999999996</velocity>
            <stiffness>100000000</stiffness>
            <dissipation>1</dissipation>
          </limit>
          <dynamics>
            <spring_reference>0</spring_reference>
            <spring_stiffness>0</spring_stiffness>
            <damping>0</damping>
            <friction>0</friction>
          </dynamics>
        </axis>
      </joint>
      <link name='sweepee_1/front_right_wheel'>
        <pose>0.30000055801895376 -0.25000000376319442 0.099999999901789247 -1.5706888222195765 0.46005313986222496 4.7720282081922271e-05</pose>
        <inertial>
          <pose>0 0 0 0 0 0</pose>
          <mass>1</mass>
          <inertia>
            <ixx>0.14499999999999999</ixx>
            <ixy>0</ixy>
            <ixz>0</ixz>
            <iyy>0.14499999999999999</iyy>
            <iyz>0</iyz>
            <izz>0.125</izz>
          </inertia>
        </inertial>
        <collision name='sweepee_1/front_right_wheel_fixed_joint_lump__collision_collision'>
          <pose>0 0 0 0 0 0</pose>
          <geometry>
            <sphere>
              <radius>0.10000000000000001</radius>
            </sphere>
          </geometry>
          <surface>
            <friction>
              <ode/>
            </friction>
            <bounce/>
            <contact/>
          </surface>
        </collision>
        <visual name='sweepee_1/front_right_wheel_fixed_joint_lump__visual_visual'>
          <pose>0 0 0 0 0 0</pose>
          <geometry>
            <sphere>
              <radius>0.10000000000000001</radius>
            </sphere>
          </geometry>
        </visual>
        <enable_wind>false</enable_wind>
      </link>
      <joint name='sweepee_1/rear_left_wheel_joint' type='revolute'>
        <pose>5.5511151231257827e-17 -2.7755575615628914e-17 0 0 0 0</pose>
        <parent>sweepee_1/base_footprint</parent>
        <child>sweepee_1/rear_left_wheel</child>
        <axis>
          <xyz>0 0 1</xyz>
          <limit>
            <lower>-1.7976900000000001e+308</lower>
            <upper>1.7976900000000001e+308</upper>
            <effort>10000</effort>
            <velocity>5.0999999999999996</velocity>
            <stiffness>100000000</stiffness>
            <dissipation>1</dissipation>
          </limit>
          <dynamics>
            <spring_reference>0</spring_reference>
            <spring_stiffness>0</spring_stiffness>
            <damping>0</damping>
            <friction>0</friction>
          </dynamics>
        </axis>
      </joint>
      <link name='sweepee_1/rear_left_wheel'>
        <pose>-0.29999943633622894 0.25000000301058667 0.10000000020709017 -1.570688822219438 -0.46005314245886847 -4.7742861695427595e-05</pose>
        <inertial>
          <pose>0 0 0 0 0 0</pose>
          <mass>1</mass>
          <inertia>
            <ixx>0.14499999999999999</ixx>
            <ixy>0</ixy>
            <ixz>0</ixz>
            <iyy>0.14499999999999999</iyy>
            <iyz>0</iyz>
            <izz>0.125</izz>
          </inertia>
        </inertial>
        <collision name='sweepee_1/rear_left_wheel_fixed_joint_lump__collision_collision'>
          <pose>0 0 0 0 0 0</pose>
          <geometry>
            <sphere>
              <radius>0.10000000000000001</radius>
            </sphere>
          </geometry>
          <surface>
            <friction>
              <ode/>
            </friction>
            <bounce/>
            <contact/>
          </surface>
        </collision>
        <visual name='sweepee_1/rear_left_wheel_fixed_joint_lump__visual_visual'>
          <pose>0 0 0 0 0 0</pose>
          <geometry>
            <sphere>
              <radius>0.10000000000000001</radius>
            </sphere>
          </geometry>
        </visual>
        <enable_wind>false</enable_wind>
      </link>
      <joint name='sweepee_1/rear_right_wheel_joint' type='revolute'>
        <pose>5.5511151231257827e-17 1.3877787807814457e-17 0 0 0 0</pose>
        <parent>sweepee_1/base_footprint</parent>
        <child>sweepee_1/rear_right_wheel</child>
        <axis>
          <xyz>0 0 1</xyz>
          <limit>
            <lower>-1.7976900000000001e+308</lower>
            <upper>1.7976900000000001e+308</upper>
            <effort>10000</effort>
            <velocity>5.0999999999999996</velocity>
            <stiffness>100000000</stiffness>
            <dissipation>1</dissipation>
          </limit>
          <dynamics>
            <spring_reference>0</spring_reference>
            <spring_stiffness>0</spring_stiffness>
            <damping>0</damping>
            <friction>0</friction>
          </dynamics>
        </axis>
      </joint>
      <link name='sweepee_1/rear_right_wheel'>
        <pose>-0.29999944198104656 -0.24999999698941316 0.10000000000110802 -1.5706888222195434 0.46005314048854712 4.7720282156919117e-05</pose>
        <inertial>
          <pose>0 0 0 0 0 0</pose>
          <mass>1</mass>
          <inertia>
            <ixx>0.14499999999999999</ixx>
            <ixy>0</ixy>
            <ixz>0</ixz>
            <iyy>0.14499999999999999</iyy>
            <iyz>0</iyz>
            <izz>0.125</izz>
          </inertia>
        </inertial>
        <collision name='sweepee_1/rear_right_wheel_fixed_joint_lump__collision_collision'>
          <pose>0 0 0 0 0 0</pose>
          <geometry>
            <sphere>
              <radius>0.10000000000000001</radius>
            </sphere>
          </geometry>
          <surface>
            <friction>
              <ode/>
            </friction>
            <bounce/>
            <contact/>
          </surface>
        </collision>
        <visual name='sweepee_1/rear_right_wheel_fixed_joint_lump__visual_visual'>
          <pose>0 0 0 0 0 0</pose>
          <geometry>
            <sphere>
              <radius>0.10000000000000001</radius>
            </sphere>
          </geometry>
        </visual>
        <enable_wind>false</enable_wind>
      </link>
      <joint name='sweepee_1/shoulder_pan_joint' type='revolute'>
        <pose>0 0 0 0 0 0</pose>
        <parent>sweepee_1/base_footprint</parent>
        <child>sweepee_1/shoulder_link</child>
        <axis>
          <xyz>0 0 1</xyz>
          <limit>
            <lower>-6.2831853071795862</lower>
            <upper>6.2831853071795862</upper>
            <effort>330</effort>
            <velocity>2.0943951023931948</velocity>
            <stiffness>100000000</stiffness>
            <dissipation>1</dissipation>
          </limit>
          <dynamics>
            <spring_reference>0</spring_reference>
            <spring_stiffness>0</spring_stiffness>
            <damping>0</damping>
            <friction>0</friction>
          </dynamics>
        </axis>
      </joint>
      <link name='sweepee_1/shoulder_link'>
        <pose>-2.2204460492503131e-16 2.2204460492503131e-16 0.52729999999999988 4.6641803992169994e-24 -9.3659950741464895e-24 -1.5675791983185283</pose>
        <inertial>
          <pose>0 0 0 0 0 0</pose>
          <mass>7.7779999999999996</mass>
          <inertia>
            <ixx>0.031474312576936593</ixx>
            <ixy>0</ixy>
            <ixz>0</ixz>
            <iyy>0.031474312576936593</iyy>
            <iyz>0</iyz>
            <izz>0.021875624999999999</izz>
          </inertia>
        </inertial>
        <collision name='sweepee_1/shoulder_link_collision'>
          <pose>0 0 0 0 0 3.1415926535897931</pose>
          <geometry>
            <mesh>
              <scale>1 1 1</scale>
              <uri>file:///home/gino/ROS/lampo_ws_ros2_rolling/install/ur_description/share/ur_description/meshes/ur10/collision/shoulder.stl</uri>
            </mesh>
          </geometry>
        </collision>
        <visual name='sweepee_1/shoulder_link_visual'>
          <pose>0 0 0 0 0 3.1415926535897931</pose>
          <geometry>
            <mesh>
              <scale>1 1 1</scale>
              <uri>file:///home/gino/ROS/lampo_ws_ros2_rolling/install/ur_description/share/ur_description/meshes/ur10/visual/shoulder.dae</uri>
            </mesh>
          </geometry>
        </visual>
        <enable_wind>false</enable_wind>
      </link>
      <joint name='sweepee_1/shoulder_lift_joint' type='revolute'>
        <pose>0 0 0 0 0 0</pose>
        <parent>sweepee_1/shoulder_link</parent>
        <child>sweepee_1/upper_arm_link</child>
        <axis>
          <xyz>0 0 1</xyz>
          <limit>
            <lower>-6.2831853071795862</lower>
            <upper>6.2831853071795862</upper>
            <effort>330</effort>
            <velocity>2.0943951023931948</velocity>
            <stiffness>100000000</stiffness>
            <dissipation>1</dissipation>
          </limit>
          <dynamics>
            <spring_reference>0</spring_reference>
            <spring_stiffness>0</spring_stiffness>
            <damping>0</damping>
            <friction>0</friction>
          </dynamics>
        </axis>
      </joint>
      <link name='sweepee_1/upper_arm_link'>
        <pose>5.6091209388320351e-07 -5.5233595475101538e-10 0.52730000005443967 1.5707963268579577 -0.86510387430512126 -1.5675778410351489</pose>
        <inertial>
          <pose>-0.30599999999999999 0 0.17499999999999999 0 1.5707963267948966 0</pose>
          <mass>12.93</mass>
          <inertia>
            <ixx>0.42175380379841088</ixx>
            <ixy>0</ixy>
            <ixz>0</ixz>
            <iyy>0.42175380379841088</iyy>
            <iyz>0</iyz>
            <izz>0.036365624999999992</izz>
          </inertia>
        </inertial>
        <collision name='sweepee_1/upper_arm_link_collision'>
          <pose>0 0 0.220941 1.5707963267948959 5.5511151231257827e-17 -1.5707963267948959</pose>
          <geometry>
            <mesh>
              <scale>1 1 1</scale>
              <uri>file:///home/gino/ROS/lampo_ws_ros2_rolling/install/ur_description/share/ur_description/meshes/ur10/collision/upperarm.stl</uri>
            </mesh>
          </geometry>
        </collision>
        <visual name='sweepee_1/upper_arm_link_visual'>
          <pose>0 0 0.220941 1.5707963267948959 5.5511151231257827e-17 -1.5707963267948959</pose>
          <geometry>
            <mesh>
              <scale>1 1 1</scale>
              <uri>file:///home/gino/ROS/lampo_ws_ros2_rolling/install/ur_description/share/ur_description/meshes/ur10/visual/upperarm.dae</uri>
            </mesh>
          </geometry>
        </visual>
        <enable_wind>false</enable_wind>
      </link>
      <joint name='sweepee_1/elbow_joint' type='revolute'>
        <pose>0 1.1102230246251565e-16 1.6653345369377348e-16 0 0 0</pose>
        <parent>sweepee_1/upper_arm_link</parent>
        <child>sweepee_1/forearm_link</child>
        <axis>
          <xyz>0 0 1</xyz>
          <limit>
            <lower>-3.1415926535897931</lower>
            <upper>3.1415926535897931</upper>
            <effort>150</effort>
            <velocity>3.1415926535897931</velocity>
            <stiffness>100000000</stiffness>
            <dissipation>1</dissipation>
          </limit>
          <dynamics>
            <spring_reference>0</spring_reference>
            <spring_stiffness>0</spring_stiffness>
            <damping>0</damping>
            <friction>0</friction>
          </dynamics>
        </axis>
      </joint>
      <link name='sweepee_1/forearm_link'>
        <pose>-0.0012769171923125988 0.39691631426153151 0.061467618943305588 1.5707963268536309 -0.0282464838948473 -1.5675779364150926</pose>
        <inertial>
          <pose>-0.28615000000000002 0 0.049042000000000002 0 1.5707963267948966 0</pose>
          <mass>3.8700000000000001</mass>
          <inertia>
            <ixx>0.1110696940971046</ixx>
            <ixy>0</ixy>
            <ixz>0</ixz>
            <iyy>0.1110696940971046</iyy>
            <iyz>0</iyz>
            <izz>0.010884375</izz>
          </inertia>
        </inertial>
        <collision name='sweepee_1/forearm_link_collision'>
          <pose>0 0 0.049042000000000002 1.5707963267948959 5.5511151231257827e-17 -1.5707963267948959</pose>
          <geometry>
            <mesh>
              <scale>1 1 1</scale>
              <uri>file:///home/gino/ROS/lampo_ws_ros2_rolling/install/ur_description/share/ur_description/meshes/ur10/collision/forearm.stl</uri>
            </mesh>
          </geometry>
        </collision>
        <visual name='sweepee_1/forearm_link_visual'>
          <pose>0 0 0.049042000000000002 1.5707963267948959 5.5511151231257827e-17 -1.5707963267948959</pose>
          <geometry>
            <mesh>
              <scale>1 1 1</scale>
              <uri>file:///home/gino/ROS/lampo_ws_ros2_rolling/install/ur_description/share/ur_description/meshes/ur10/visual/forearm.dae</uri>
            </mesh>
          </geometry>
        </visual>
        <enable_wind>false</enable_wind>
      </link>
      <joint name='sweepee_1/wrist_1_joint' type='revolute'>
        <pose>0 1.1102230246251565e-16 -8.3266726846886741e-17 0 0 0</pose>
        <parent>sweepee_1/forearm_link</parent>
        <child>sweepee_1/wrist_1_link</child>
        <axis>
          <xyz>0 0 1</xyz>
          <limit>
            <lower>-6.2831853071795862</lower>
            <upper>6.2831853071795862</upper>
            <effort>56</effort>
            <velocity>3.1415926535897931</velocity>
            <stiffness>100000000</stiffness>
            <dissipation>1</dissipation>
          </limit>
          <dynamics>
            <spring_reference>0</spring_reference>
            <spring_stiffness>0</spring_stiffness>
            <damping>0</damping>
            <friction>0</friction>
          </dynamics>
        </axis>
      </joint>
      <link name='sweepee_1/wrist_1_link'>
        <pose>-0.16705826865260764 0.9684584300783412 0.045305817436793135 -1.5707963393965731 1.5675507868256227 1.5740148000010279</pose>
        <inertial>
          <pose>0 0 0 0 0 0</pose>
          <mass>1.96</mass>
          <inertia>
            <ixx>0.0051082479566999994</ixx>
            <ixy>0</ixy>
            <ixz>0</ixz>
            <iyy>0.0051082479566999994</iyy>
            <iyz>0</iyz>
            <izz>0.0055124999999999992</izz>
          </inertia>
        </inertial>
        <collision name='sweepee_1/wrist_1_link_collision'>
          <pose>0 0 -0.1149 1.5707963267948959 0 0</pose>
          <geometry>
            <mesh>
              <scale>1 1 1</scale>
              <uri>file:///home/gino/ROS/lampo_ws_ros2_rolling/install/ur_description/share/ur_description/meshes/ur10/collision/wrist1.stl</uri>
            </mesh>
          </geometry>
        </collision>
        <visual name='sweepee_1/wrist_1_link_visual'>
          <pose>0 0 -0.1149 1.5707963267948959 0 0</pose>
          <geometry>
            <mesh>
              <scale>1 1 1</scale>
              <uri>file:///home/gino/ROS/lampo_ws_ros2_rolling/install/ur_description/share/ur_description/meshes/ur10/visual/wrist1.dae</uri>
            </mesh>
          </geometry>
        </visual>
        <enable_wind>false</enable_wind>
      </link>
      <joint name='sweepee_1/wrist_2_joint' type='revolute'>
        <pose>0 2.7755575615628914e-17 0 0 0 -5.1517785475977202e-36</pose>
        <parent>sweepee_1/wrist_1_link</parent>
        <child>sweepee_1/wrist_2_link</child>
        <axis>
          <xyz>0 0 1</xyz>
          <limit>
            <lower>-6.2831853071795862</lower>
            <upper>6.2831853071795862</upper>
            <effort>56</effort>
            <velocity>3.1415926535897931</velocity>
            <stiffness>100000000</stiffness>
            <dissipation>1</dissipation>
          </limit>
          <dynamics>
            <spring_reference>0</spring_reference>
            <spring_stiffness>0</spring_stiffness>
            <damping>0</damping>
            <friction>0</friction>
          </dynamics>
        </axis>
      </joint>
      <link name='sweepee_1/wrist_2_link'>
        <pose>-0.16743064483273229 1.0841572214699788 0.045681325752011233 0.23398895274073558 1.5674598654598122 1.8080050205036673</pose>
        <inertial>
          <pose>0 0 0 0 0 0</pose>
          <mass>1.96</mass>
          <inertia>
            <ixx>0.0040792483682999996</ixx>
            <ixy>0</ixy>
            <ixz>0</ixz>
            <iyy>0.0040792483682999996</iyy>
            <iyz>0</iyz>
            <izz>0.0055124999999999992</izz>
          </inertia>
        </inertial>
        <collision name='sweepee_1/wrist_2_link_collision'>
          <pose>0 0 -0.1158 0 0 0</pose>
          <geometry>
            <mesh>
              <scale>1 1 1</scale>
              <uri>file:///home/gino/ROS/lampo_ws_ros2_rolling/install/ur_description/share/ur_description/meshes/ur10/collision/wrist2.stl</uri>
            </mesh>
          </geometry>
        </collision>
        <visual name='sweepee_1/wrist_2_link_visual'>
          <pose>0 0 -0.1158 0 0 0</pose>
          <geometry>
            <mesh>
              <scale>1 1 1</scale>
              <uri>file:///home/gino/ROS/lampo_ws_ros2_rolling/install/ur_description/share/ur_description/meshes/ur10/visual/wrist2.dae</uri>
            </mesh>
          </geometry>
        </visual>
        <enable_wind>false</enable_wind>
      </link>
      <joint name='sweepee_1/wrist_3_joint' type='revolute'>
        <pose>0 0 -5.5511151231257827e-17 0 0 1.2325951644078309e-32</pose>
        <parent>sweepee_1/wrist_2_link</parent>
        <child>sweepee_1/wrist_3_link</child>
        <axis>
          <xyz>0 0 1</xyz>
          <limit>
            <lower>-6.2831853071795862</lower>
            <upper>6.2831853071795862</upper>
            <effort>56</effort>
            <velocity>3.1415926535897931</velocity>
            <stiffness>100000000</stiffness>
            <dissipation>1</dissipation>
          </limit>
          <dynamics>
            <spring_reference>0</spring_reference>
            <spring_stiffness>0</spring_stiffness>
            <damping>0</damping>
            <friction>0</friction>
          </dynamics>
        </axis>
      </joint>
      <link name='sweepee_1/wrist_3_link'>
        <pose>-0.25963013896605036 1.083860246192095 0.045752650674750206 1.5697322775359408 0.75681873283646428 -1.568305919468485</pose>
        <inertial>
          <pose>0 0 -0.01525 0 0 0</pose>
          <mass>0.20200000000000001</mass>
          <inertia>
            <ixx>0.00011792166116465</ixx>
            <ixy>0</ixy>
            <ixz>0</ixz>
            <iyy>0.00011792166116465</iyy>
            <iyz>0</iyz>
            <izz>0.000204525</izz>
          </inertia>
        </inertial>
        <collision name='sweepee_1/wrist_3_link_collision'>
          <pose>0 0 -0.092200000000000004 1.5707963267948959 0 0</pose>
          <geometry>
            <mesh>
              <scale>1 1 1</scale>
              <uri>file:///home/gino/ROS/lampo_ws_ros2_rolling/install/ur_description/share/ur_description/meshes/ur10/collision/wrist3.stl</uri>
            </mesh>
          </geometry>
        </collision>
        <visual name='sweepee_1/wrist_3_link_visual'>
          <pose>0 0 -0.092200000000000004 1.5707963267948959 0 0</pose>
          <geometry>
            <mesh>
              <scale>1 1 1</scale>
              <uri>file:///home/gino/ROS/lampo_ws_ros2_rolling/install/ur_description/share/ur_description/meshes/ur10/visual/wrist3.dae</uri>
            </mesh>
          </geometry>
        </visual>
        <enable_wind>false</enable_wind>
      </link>
      <plugin name='gz::sim::systems::MecanumDrive' filename='gz-sim-mecanum-drive-system'>
        <front_left_joint>sweepee_1/front_left_wheel_joint</front_left_joint>
        <front_right_joint>sweepee_1/front_right_wheel_joint</front_right_joint>
        <back_left_joint>sweepee_1/rear_left_wheel_joint</back_left_joint>
        <back_right_joint>sweepee_1/rear_right_wheel_joint</back_right_joint>
        <wheel_separation>0.5</wheel_separation>
        <wheelbase>0.7</wheelbase>
        <wheel_radius>0.1</wheel_radius>
        <min_acceleration>-5</min_acceleration>
        <max_acceleration>5</max_acceleration>
        <topic>sweepee_1/cmd_vel</topic>
        <frame_id>sweepee_1/base_link_sweepee</frame_id>
      </plugin>
      <plugin name='gz_ros2_control::GazeboSimROS2ControlPlugin' filename='libgz_ros2_control-system.so'>
        <robot_param>robot_description</robot_param>
        <robot_param_node>robot_state_publisher</robot_param_node>
        <parameters>/home/gino/ROS/lampo_ws_ros2_rolling/install/lampo_description/share/lampo_description/config/ur_controllers_1.yaml</parameters>
        <ros>
          <namespace>sweepee_1</namespace>
        </ros>
      </plugin>
      <frame name='sweepee_1/front_laser_joint' attached_to='sweepee_1/base_link_sweepee'>
        <pose>0.35999999999999999 0 0.26000000000000001 0 0 0</pose>
      </frame>
      <frame name='sweepee_1/front_laser' attached_to='sweepee_1/front_laser_joint'>
        <pose>0 0 0 0 0 0</pose>
      </frame>
      <frame name='sweepee_1/rear_laser_joint' attached_to='sweepee_1/base_link_sweepee'>
        <pose>-0.35999999999999999 0 0.26000000000000001 0 0 3.1415899999999999</pose>
      </frame>
      <frame name='sweepee_1/rear_laser' attached_to='sweepee_1/rear_laser_joint'>
        <pose>0 0 0 0 0 0</pose>
      </frame>
      <frame name='sweepee_1/base_footprint_joint' attached_to='sweepee_1/base_footprint'>
        <pose>0 0 0 0 0 0</pose>
      </frame>
      <frame name='sweepee_1/base_link_sweepee' attached_to='sweepee_1/base_footprint_joint'>
        <pose>0 0 0 0 0 0</pose>
      </frame>
      <frame name='sweepee_1/base_link-base_fixed_joint' attached_to='sweepee_1/base_link'>
        <pose>0 0 0 0 0 3.1415926535897931</pose>
      </frame>
      <frame name='sweepee_1/base' attached_to='sweepee_1/base_link-base_fixed_joint'>
        <pose>0 0 0 0 0 0</pose>
      </frame>
      <frame name='sweepee_1/base_link-base_link_inertia' attached_to='sweepee_1/base_link'>
        <pose>0 0 0 0 0 3.1415926535897931</pose>
      </frame>
      <frame name='sweepee_1/base_link_inertia' attached_to='sweepee_1/base_link-base_link_inertia'>
        <pose>0 0 0 0 0 0</pose>
      </frame>
      <frame name='sweepee_1/flange-tool0' attached_to='sweepee_1/flange'>
        <pose>0 0 0 1.5707963267948959 -5.5511151231257827e-17 1.5707963267948959</pose>
      </frame>
      <frame name='sweepee_1/tool0' attached_to='sweepee_1/flange-tool0'>
        <pose>0 0 0 0 0 0</pose>
      </frame>
      <frame name='sweepee_1/wrist_3-flange' attached_to='sweepee_1/wrist_3_link'>
        <pose>0 0 0 -1.5707963267948957 -1.5707963267948966 0</pose>
      </frame>
      <frame name='sweepee_1/flange' attached_to='sweepee_1/wrist_3-flange'>
        <pose>0 0 0 0 0 0</pose>
      </frame>
      <frame name='sweepee_1/wrist_3_link-ft_frame' attached_to='sweepee_1/wrist_3_link'>
        <pose>0 0 0 3.1415926535897931 0 0</pose>
      </frame>
      <frame name='sweepee_1/ft_frame' attached_to='sweepee_1/wrist_3_link-ft_frame'>
        <pose>0 0 0 0 0 0</pose>
      </frame>
      <frame name='sweepee_1/base_joint' attached_to='sweepee_1/base_footprint'>
        <pose>0 0 0.40000000000000002 0 0 0</pose>
      </frame>
      <frame name='sweepee_1/base_link' attached_to='sweepee_1/base_joint'>
        <pose>0 0 0 0 0 0</pose>
      </frame>
      <pose>0.51469970980297752 -1.2068984196457748 -5.4373666431106306e-08 4.0598055997206441e-08 1.357869438123826e-08 -1.5707961460883118</pose>
      <static>false</static>
      <self_collide>false</self_collide>
    </model>
  </world>
</sdf>
